Workbook
Name Table1: 'Bureau 1'!$D$49:$M$59
Name Table1: 'Bureau 10'!$D$49:$M$59
Name Table1: 'Bureau 11'!$D$49:$M$59
Name Table1: 'Bureau 12'!$D$49:$M$59
Name Table1: 'Bureau 2'!$D$49:$M$59
Name Table1: 'Bureau 3'!$D$49:$M$59
Name Table1: 'Bureau 4'!$D$49:$M$59
Name Table1: 'Bureau 5'!$D$49:$M$59
Name Table1: 'Bureau 6'!$D$49:$M$59
Name Table1: 'Bureau 7'!$D$49:$M$59
Name Table1: 'Bureau 8'!$D$49:$M$59
Name Table1: 'Bureau 9'!$D$49:$M$59
Name Table1: 'Feuille décompte'!$B$3:$K$12
Name Table1: #REF!
Name Table2: 'Bureau 1'!$D$67:$M$72
Name Table2: 'Bureau 10'!$D$67:$M$72
Name Table2: 'Bureau 11'!$D$67:$M$72
Name Table2: 'Bureau 12'!$D$67:$M$72
Name Table2: 'Bureau 2'!$D$67:$M$72
Name Table2: 'Bureau 3'!$D$67:$M$72
Name Table2: 'Bureau 4'!$D$67:$M$72
Name Table2: 'Bureau 5'!$D$67:$M$72
Name Table2: 'Bureau 6'!$D$67:$M$72
Name Table2: 'Bureau 7'!$D$67:$M$72
Name Table2: 'Bureau 8'!$D$67:$M$72
Name Table2: 'Bureau 9'!$D$67:$M$72
Name Table2: 'Feuille décompte'!$D$61:$M$66
Name Table2: #REF!
Name Table3: 'Bureau 1'!$D$78:$M$80
Name Table3: 'Bureau 10'!$D$78:$M$80
Name Table3: 'Bureau 11'!$D$78:$M$80
Name Table3: 'Bureau 12'!$D$78:$M$80
Name Table3: 'Bureau 2'!$D$78:$M$80
Name Table3: 'Bureau 3'!$D$78:$M$80
Name Table3: 'Bureau 4'!$D$78:$M$80
Name Table3: 'Bureau 5'!$D$78:$M$80
Name Table3: 'Bureau 6'!$D$78:$M$80
Name Table3: 'Bureau 7'!$D$78:$M$80
Name Table3: 'Bureau 8'!$D$78:$M$80
Name Table3: 'Bureau 9'!$D$78:$M$80
Name Table3: 'Feuille décompte'!$D$72:$M$74
Name Table3: #REF!

Sheet Synthèse
L1: 1 | M1: 2 | N1: 3 | O1: 4 | P1: 5 | Q1: 6 | R1: 7 | S1: Vérification
A2: N° | B2: Nom | C2: Inscrits | D2: Emargements | E2: Votants | F2: Abstention | G2: Blancs | H2: Nuls | I2: Exprimés | J2: Participation | K2: Abstention (%) | L2: Mme Christiane LARDAT | M2: M. Francis LAPRADE | N2: M. Pierre-Yves TIERCE | O2: M. Philippe VALLET | P2: Mme Isabelle FARNET RISSO | Q2: Mme Véronique LANSADE | R2: M. Pascal CORDÉ | S2: Total exprimé
A3: 1 | B3: Ecole Chabaud | C3: 553 | D3: {=INDIRECT("'Bureau " & ROW()-2 & "'!$B$8")} -> 323 | E3: {=INDIRECT("'Bureau " & ROW()-2 & "'!$B$7")} -> 323 | F3: =C3-E3 -> 230 | G3: =INDEX(INDIRECT("'Bureau "&(ROW()-2)&"'!13:13"),1,MATCH("Blancs",INDIRECT("'Bureau "&(ROW()-2)&"'!2:2"),0)) -> 8 | H3: =INDEX(INDIRECT("'Bureau "&(ROW()-2)&"'!13:13"),1,MATCH("Nuls",INDIRECT("'Bureau "&(ROW()-2)&"'!2:2"),0)) -> 4 | I3: =E3-G3-H3 -> 311 | J3: =E3/C3 -> 0.5840868 | K3: =F3/C3 -> 0.4159132 | L3: =INDEX(INDIRECT("'Bureau " & ROW()-2 & "'!E:E"), MATCH("TOTAL", INDIRECT("'Bureau " & ROW() -2& "'!D:D"), 0)) -> 31 | M3: =INDEX(INDIRECT("'Bureau " & ROW()-2 & "'!F:F"), MATCH("TOTAL", INDIRECT("'Bureau " & ROW() -2& "'!D:D"), 0)) -> 6 | N3: =INDEX(INDIRECT("'Bureau " & ROW()-2 & "'!G:G"), MATCH("TOTAL", INDIRECT("'Bureau " & ROW() -2& "'!D:D"), 0)) -> 112 | O3: =INDEX(INDIRECT("'Bureau " & ROW()-2 & "'!H:H"), MATCH("TOTAL", INDIRECT("'Bureau " & ROW() -2& "'!D:D"), 0)) -> 36 | P3: =INDEX(INDIRECT("'Bureau " & ROW()-2 & "'!I:I"), MATCH("TOTAL", INDIRECT("'Bureau " & ROW() -2& "'!D:D"), 0)) -> 94 | Q3: =INDEX(INDIRECT("'Bureau " & ROW()-2 & "'!J:J"), MATCH("TOTAL", INDIRECT("'Bureau " & ROW() -2& "'!D:D"), 0)) -> 10 | R3: =INDEX(INDIRECT("'Bureau " & ROW()-2 & "'!K:K"), MATCH("TOTAL", INDIRECT("'Bureau " & ROW() -2& "'!D:D"), 0)) -> 22 | S3: {=SUM(IFERROR(L3:R3,0))} -> 311
A4: 2 | B4: Gymnase B | C4: 740 | D4: {=INDIRECT("'Bureau " & ROW()-2 & "'!$B$8")} -> 443 | E4: {=INDIRECT("'Bureau " & ROW()-2 & "'!$B$7")} -> 443 | F4: =C4-E4 -> 297 | G4: =INDEX(INDIRECT("'Bureau "&(ROW()-2)&"'!13:13"),1,MATCH("Blancs",INDIRECT("'Bureau "&(ROW()-2)&"'!2:2"),0)) -> 9 | H4: =INDEX(INDIRECT("'Bureau "&(ROW()-2)&"'!13:13"),1,MATCH("Nuls",INDIRECT("'Bureau "&(ROW()-2)&"'!2:2"),0)) -> 12 | I4: =E4-G4-H4 -> 422 | J4: =E4/C4 -> 0.59864865 | K4: =F4/C4 -> 0.40135135 | L4: =INDEX(INDIRECT("'Bureau " & ROW()-2 & "'!E:E"), MATCH("TOTAL", INDIRECT("'Bureau " & ROW() -2& "'!D:D"), 0)) -> 29 | M4: =INDEX(INDIRECT("'Bureau " & ROW()-2 & "'!F:F"), MATCH("TOTAL", INDIRECT("'Bureau " & ROW() -2& "'!D:D"), 0)) -> 19 | N4: =INDEX(INDIRECT("'Bureau " & ROW()-2 & "'!G:G"), MATCH("TOTAL", INDIRECT("'Bureau " & ROW() -2& "'!D:D"), 0)) -> 129 | O4: =INDEX(INDIRECT("'Bureau " & ROW()-2 & "'!H:H"), MATCH("TOTAL", INDIRECT("'Bureau " & ROW() -2& "'!D:D"), 0)) -> 78 | P4: =INDEX(INDIRECT("'Bureau " & ROW()-2 & "'!I:I"), MATCH("TOTAL", INDIRECT("'Bureau " & ROW() -2& "'!D:D"), 0)) -> 137 | Q4: =INDEX(INDIRECT("'Bureau " & ROW()-2 & "'!J:J"), MATCH("TOTAL", INDIRECT("'Bureau " & ROW() -2& "'!D:D"), 0)) -> 20 | R4: =INDEX(INDIRECT("'Bureau " & ROW()-2 & "'!K:K"), MATCH("TOTAL", INDIRECT("'Bureau " & ROW() -2& "'!D:D"), 0)) -> 10 | S4: {=SUM(IFERROR(L4:R4,0))} -> 422
A5: 3 | B5: Gymnase B | C5: 713 | D5: {=INDIRECT("'Bureau " & ROW()-2 & "'!$B$8")} -> 484 | E5: {=INDIRECT("'Bureau " & ROW()-2 & "'!$B$7")} -> 484 | F5: =C5-E5 -> 229 | G5: =INDEX(INDIRECT("'Bureau "&(ROW()-2)&"'!13:13"),1,MATCH("Blancs",INDIRECT("'Bureau "&(ROW()-2)&"'!2:2"),0)) -> 11 | H5: =INDEX(INDIRECT("'Bureau "&(ROW()-2)&"'!13:13"),1,MATCH("Nuls",INDIRECT("'Bureau "&(ROW()-2)&"'!2:2"),0)) -> 8 | I5: =E5-G5-H5 -> 465 | J5: =E5/C5 -> 0.67882188 | K5: =F5/C5 -> 0.32117812 | L5: =INDEX(INDIRECT("'Bureau " & ROW()-2 & "'!E:E"), MATCH("TOTAL", INDIRECT("'Bureau " & ROW() -2& "'!D:D"), 0)) -> 37 | M5: =INDEX(INDIRECT("'Bureau " & ROW()-2 & "'!F:F"), MATCH("TOTAL", INDIRECT("'Bureau " & ROW() -2& "'!D:D"), 0)) -> 9 | N5: =INDEX(INDIRECT("'Bureau " & ROW()-2 & "'!G:G"), MATCH("TOTAL", INDIRECT("'Bureau " & ROW() -2& "'!D:D"), 0)) -> 137 | O5: =INDEX(INDIRECT("'Bureau " & ROW()-2 & "'!H:H"), MATCH("TOTAL", INDIRECT("'Bureau " & ROW() -2& "'!D:D"), 0)) -> 76 | P5: =INDEX(INDIRECT("'Bureau " & ROW()-2 & "'!I:I"), MATCH("TOTAL", INDIRECT("'Bureau " & ROW() -2& "'!D:D"), 0)) -> 188 | Q5: =INDEX(INDIRECT("'Bureau " & ROW()-2 & "'!J:J"), MATCH("TOTAL", INDIRECT("'Bureau " & ROW() -2& "'!D:D"), 0)) -> 10 | R5: =INDEX(INDIRECT("'Bureau " & ROW()-2 & "'!K:K"), MATCH("TOTAL", INDIRECT("'Bureau " & ROW() -2& "'!D:D"), 0)) -> 8 | S5: {=SUM(IFERROR(L5:R5,0))} -> 465
A6: 4 | B6: Gymnase B | C6: 679 | D6: {=INDIRECT("'Bureau " & ROW()-2 & "'!$B$8")} -> 363 | E6: {=INDIRECT("'Bureau " & ROW()-2 & "'!$B$7")} -> 363 | F6: =C6-E6 -> 316 | G6: =INDEX(INDIRECT("'Bureau "&(ROW()-2)&"'!13:13"),1,MATCH("Blancs",INDIRECT("'Bureau "&(ROW()-2)&"'!2:2"),0)) -> 4 | H6: =INDEX(INDIRECT("'Bureau "&(ROW()-2)&"'!13:13"),1,MATCH("Nuls",INDIRECT("'Bureau "&(ROW()-2)&"'!2:2"),0)) -> 10 | I6: =E6-G6-H6 -> 349 | J6: =E6/C6 -> 0.53460972 | K6: =F6/C6 -> 0.46539028 | L6: =INDEX(INDIRECT("'Bureau " & ROW()-2 & "'!E:E"), MATCH("TOTAL", INDIRECT("'Bureau " & ROW() -2& "'!D:D"), 0)) -> 28 | M6: =INDEX(INDIRECT("'Bureau " & ROW()-2 & "'!F:F"), MATCH("TOTAL", INDIRECT("'Bureau " & ROW() -2& "'!D:D"), 0)) -> 15 | N6: =INDEX(INDIRECT("'Bureau " & ROW()-2 & "'!G:G"), MATCH("TOTAL", INDIRECT("'Bureau " & ROW() -2& "'!D:D"), 0)) -> 81 | O6: =INDEX(INDIRECT("'Bureau " & ROW()-2 & "'!H:H"), MATCH("TOTAL", INDIRECT("'Bureau " & ROW() -2& "'!D:D"), 0)) -> 61 | P6: =INDEX(INDIRECT("'Bureau " & ROW()-2 & "'!I:I"), MATCH("TOTAL", INDIRECT("'Bureau " & ROW() -2& "'!D:D"), 0)) -> 135 | Q6: =INDEX(INDIRECT("'Bureau " & ROW()-2 & "'!J:J"), MATCH("TOTAL", INDIRECT("'Bureau " & ROW() -2& "'!D:D"), 0)) -> 15 | R6: =INDEX(INDIRECT("'Bureau " & ROW()-2 & "'!K:K"), MATCH("TOTAL", INDIRECT("'Bureau " & ROW() -2& "'!D:D"), 0)) -> 14 | S6: {=SUM(IFERROR(L6:R6,0))} -> 349
A7: 5 | B7: COSEC | C7: 701 | D7: {=INDIRECT("'Bureau " & ROW()-2 & "'!$B$8")} -> 452 | E7: {=INDIRECT("'Bureau " & ROW()-2 & "'!$B$7")} -> 452 | F7: =C7-E7 -> 249 | G7: =INDEX(INDIRECT("'Bureau "&(ROW()-2)&"'!13:13"),1,MATCH("Blancs",INDIRECT("'Bureau "&(ROW()-2)&"'!2:2"),0)) -> 9 | H7: =INDEX(INDIRECT("'Bureau "&(ROW()-2)&"'!13:13"),1,MATCH("Nuls",INDIRECT("'Bureau "&(ROW()-2)&"'!2:2"),0)) -> 7 | I7: =E7-G7-H7 -> 436 | J7: =E7/C7 -> 0.64479315 | K7: =F7/C7 -> 0.35520685 | L7: =INDEX(INDIRECT("'Bureau " & ROW()-2 & "'!E:E"), MATCH("TOTAL", INDIRECT("'Bureau " & ROW() -2& "'!D:D"), 0)) -> 27 | M7: =INDEX(INDIRECT("'Bureau " & ROW()-2 & "'!F:F"), MATCH("TOTAL", INDIRECT("'Bureau " & ROW() -2& "'!D:D"), 0)) -> 21 | N7: =INDEX(INDIRECT("'Bureau " & ROW()-2 & "'!G:G"), MATCH("TOTAL", INDIRECT("'Bureau " & ROW() -2& "'!D:D"), 0)) -> 125 | O7: =INDEX(INDIRECT("'Bureau " & ROW()-2 & "'!H:H"), MATCH("TOTAL", INDIRECT("'Bureau " & ROW() -2& "'!D:D"), 0)) -> 83 | P7: =INDEX(INDIRECT("'Bureau " & ROW()-2 & "'!I:I"), MATCH("TOTAL", INDIRECT("'Bureau " & ROW() -2& "'!D:D"), 0)) -> 158 | Q7: =INDEX(INDIRECT("'Bureau " & ROW()-2 & "'!J:J"), MATCH("TOTAL", INDIRECT("'Bureau " & ROW() -2& "'!D:D"), 0)) -> 11 | R7: =INDEX(INDIRECT("'Bureau " & ROW()-2 & "'!K:K"), MATCH("TOTAL", INDIRECT("'Bureau " & ROW() -2& "'!D:D"), 0)) -> 11 | S7: {=SUM(IFERROR(L7:R7,0))} -> 436
A8: 6 | B8: COSEC | C8: 710 | D8: {=INDIRECT("'Bureau " & ROW()-2 & "'!$B$8")} -> 367 | E8: {=INDIRECT("'Bureau " & ROW()-2 & "'!$B$7")} -> 367 | F8: =C8-E8 -> 343 | G8: =INDEX(INDIRECT("'Bureau "&(ROW()-2)&"'!13:13"),1,MATCH("Blancs",INDIRECT("'Bureau "&(ROW()-2)&"'!2:2"),0)) -> 9 | H8: =INDEX(INDIRECT("'Bureau "&(ROW()-2)&"'!13:13"),1,MATCH("Nuls",INDIRECT("'Bureau "&(ROW()-2)&"'!2:2"),0)) -> 1 | I8: =E8-G8-H8 -> 357 | J8: =E8/C8 -> 0.51690141 | K8: =F8/C8 -> 0.48309859 | L8: =INDEX(INDIRECT("'Bureau " & ROW()-2 & "'!E:E"), MATCH("TOTAL", INDIRECT("'Bureau " & ROW() -2& "'!D:D"), 0)) -> 15 | M8: =INDEX(INDIRECT("'Bureau " & ROW()-2 & "'!F:F"), MATCH("TOTAL", INDIRECT("'Bureau " & ROW() -2& "'!D:D"), 0)) -> 12 | N8: =INDEX(INDIRECT("'Bureau " & ROW()-2 & "'!G:G"), MATCH("TOTAL", INDIRECT("'Bureau " & ROW() -2& "'!D:D"), 0)) -> 126 | O8: =INDEX(INDIRECT("'Bureau " & ROW()-2 & "'!H:H"), MATCH("TOTAL", INDIRECT("'Bureau " & ROW() -2& "'!D:D"), 0)) -> 61 | P8: =INDEX(INDIRECT("'Bureau " & ROW()-2 & "'!I:I"), MATCH("TOTAL", INDIRECT("'Bureau " & ROW() -2& "'!D:D"), 0)) -> 120 | Q8: =INDEX(INDIRECT("'Bureau " & ROW()-2 & "'!J:J"), MATCH("TOTAL", INDIRECT("'Bureau " & ROW() -2& "'!D:D"), 0)) -> 9 | R8: =INDEX(INDIRECT("'Bureau " & ROW()-2 & "'!K:K"), MATCH("TOTAL", INDIRECT("'Bureau " & ROW() -2& "'!D:D"), 0)) -> 14 | S8: {=SUM(IFERROR(L8:R8,0))} -> 357
A9: 7 | B9: COSEC | C9: 731 | D9: {=INDIRECT("'Bureau " & ROW()-2 & "'!$B$8")} -> 439 | E9: {=INDIRECT("'Bureau " & ROW()-2 & "'!$B$7")} -> 439 | F9: =C9-E9 -> 292 | G9: =INDEX(INDIRECT("'Bureau "&(ROW()-2)&"'!13:13"),1,MATCH("Blancs",INDIRECT("'Bureau "&(ROW()-2)&"'!2:2"),0)) -> 12 | H9: =INDEX(INDIRECT("'Bureau "&(ROW()-2)&"'!13:13"),1,MATCH("Nuls",INDIRECT("'Bureau "&(ROW()-2)&"'!2:2"),0)) -> 2 | I9: =E9-G9-H9 -> 425 | J9: =E9/C9 -> 0.6005472 | K9: =F9/C9 -> 0.3994528 | L9: =INDEX(INDIRECT("'Bureau " & ROW()-2 & "'!E:E"), MATCH("TOTAL", INDIRECT("'Bureau " & ROW() -2& "'!D:D"), 0)) -> 20 | M9: =INDEX(INDIRECT("'Bureau " & ROW()-2 & "'!F:F"), MATCH("TOTAL", INDIRECT("'Bureau " & ROW() -2& "'!D:D"), 0)) -> 12 | N9: =INDEX(INDIRECT("'Bureau " & ROW()-2 & "'!G:G"), MATCH("TOTAL", INDIRECT("'Bureau " & ROW() -2& "'!D:D"), 0)) -> 121 | O9: =INDEX(INDIRECT("'Bureau " & ROW()-2 & "'!H:H"), MATCH("TOTAL", INDIRECT("'Bureau " & ROW() -2& "'!D:D"), 0)) -> 69 | P9: =INDEX(INDIRECT("'Bureau " & ROW()-2 & "'!I:I"), MATCH("TOTAL", INDIRECT("'Bureau " & ROW() -2& "'!D:D"), 0)) -> 168 | Q9: =INDEX(INDIRECT("'Bureau " & ROW()-2 & "'!J:J"), MATCH("TOTAL", INDIRECT("'Bureau " & ROW() -2& "'!D:D"), 0)) -> 22 | R9: =INDEX(INDIRECT("'Bureau " & ROW()-2 & "'!K:K"), MATCH("TOTAL", INDIRECT("'Bureau " & ROW() -2& "'!D:D"), 0)) -> 13 | S9: {=SUM(IFERROR(L9:R9,0))} -> 425
A10: 8 | B10: COSEC | C10: 646 | D10: {=INDIRECT("'Bureau " & ROW()-2 & "'!$B$8")} -> 379 | E10: {=INDIRECT("'Bureau " & ROW()-2 & "'!$B$7")} -> 379 | F10: =C10-E10 -> 267 | G10: =INDEX(INDIRECT("'Bureau "&(ROW()-2)&"'!13:13"),1,MATCH("Blancs",INDIRECT("'Bureau "&(ROW()-2)&"'!2:2"),0)) -> 6 | H10: =INDEX(INDIRECT("'Bureau "&(ROW()-2)&"'!13:13"),1,MATCH("Nuls",INDIRECT("'Bureau "&(ROW()-2)&"'!2:2"),0)) -> 8 | I10: =E10-G10-H10 -> 365 | J10: =E10/C10 -> 0.58668731 | K10: =F10/C10 -> 0.41331269 | L10: =INDEX(INDIRECT("'Bureau " & ROW()-2 & "'!E:E"), MATCH("TOTAL", INDIRECT("'Bureau " & ROW() -2& "'!D:D"), 0)) -> 34 | M10: =INDEX(INDIRECT("'Bureau " & ROW()-2 & "'!F:F"), MATCH("TOTAL", INDIRECT("'Bureau " & ROW() -2& "'!D:D"), 0)) -> 16 | N10: =INDEX(INDIRECT("'Bureau " & ROW()-2 & "'!G:G"), MATCH("TOTAL", INDIRECT("'Bureau " & ROW() -2& "'!D:D"), 0)) -> 100 | O10: =INDEX(INDIRECT("'Bureau " & ROW()-2 & "'!H:H"), MATCH("TOTAL", INDIRECT("'Bureau " & ROW() -2& "'!D:D"), 0)) -> 67 | P10: =INDEX(INDIRECT("'Bureau " & ROW()-2 & "'!I:I"), MATCH("TOTAL", INDIRECT("'Bureau " & ROW() -2& "'!D:D"), 0)) -> 123 | Q10: =INDEX(INDIRECT("'Bureau " & ROW()-2 & "'!J:J"), MATCH("TOTAL", INDIRECT("'Bureau " & ROW() -2& "'!D:D"), 0)) -> 17 | R10: =INDEX(INDIRECT("'Bureau " & ROW()-2 & "'!K:K"), MATCH("TOTAL", INDIRECT("'Bureau " & ROW() -2& "'!D:D"), 0)) -> 8 | S10: {=SUM(IFERROR(L10:R10,0))} -> 365
A11: 9 | B11: CMM | C11: 709 | D11: {=INDIRECT("'Bureau " & ROW()-2 & "'!$B$8")} -> 333 | E11: {=INDIRECT("'Bureau " & ROW()-2 & "'!$B$7")} -> 333 | F11: =C11-E11 -> 376 | G11: =INDEX(INDIRECT("'Bureau "&(ROW()-2)&"'!13:13"),1,MATCH("Blancs",INDIRECT("'Bureau "&(ROW()-2)&"'!2:2"),0)) -> 7 | H11: =INDEX(INDIRECT("'Bureau "&(ROW()-2)&"'!13:13"),1,MATCH("Nuls",INDIRECT("'Bureau "&(ROW()-2)&"'!2:2"),0)) -> 8 | I11: =E11-G11-H11 -> 318 | J11: =E11/C11 -> 0.4696756 | K11: =F11/C11 -> 0.5303244 | L11: =INDEX(INDIRECT("'Bureau " & ROW()-2 & "'!E:E"), MATCH("TOTAL", INDIRECT("'Bureau " & ROW() -2& "'!D:D"), 0)) -> 23 | M11: =INDEX(INDIRECT("'Bureau " & ROW()-2 & "'!F:F"), MATCH("TOTAL", INDIRECT("'Bureau " & ROW() -2& "'!D:D"), 0)) -> 12 | N11: =INDEX(INDIRECT("'Bureau " & ROW()-2 & "'!G:G"), MATCH("TOTAL", INDIRECT("'Bureau " & ROW() -2& "'!D:D"), 0)) -> 86 | O11: =INDEX(INDIRECT("'Bureau " & ROW()-2 & "'!H:H"), MATCH("TOTAL", INDIRECT("'Bureau " & ROW() -2& "'!D:D"), 0)) -> 60 | P11: =INDEX(INDIRECT("'Bureau " & ROW()-2 & "'!I:I"), MATCH("TOTAL", INDIRECT("'Bureau " & ROW() -2& "'!D:D"), 0)) -> 104 | Q11: =INDEX(INDIRECT("'Bureau " & ROW()-2 & "'!J:J"), MATCH("TOTAL", INDIRECT("'Bureau " & ROW() -2& "'!D:D"), 0)) -> 22 | R11: =INDEX(INDIRECT("'Bureau " & ROW()-2 & "'!K:K"), MATCH("TOTAL", INDIRECT("'Bureau " & ROW() -2& "'!D:D"), 0)) -> 11 | S11: {=SUM(IFERROR(L11:R11,0))} -> 318
A12: 10 | B12: CMM | C12: 609 | D12: {=INDIRECT("'Bureau " & ROW()-2 & "'!$B$8")} -> 357 | E12: {=INDIRECT("'Bureau " & ROW()-2 & "'!$B$7")} -> 357 | F12: =C12-E12 -> 252 | G12: =INDEX(INDIRECT("'Bureau "&(ROW()-2)&"'!13:13"),1,MATCH("Blancs",INDIRECT("'Bureau "&(ROW()-2)&"'!2:2"),0)) -> 10 | H12: =INDEX(INDIRECT("'Bureau "&(ROW()-2)&"'!13:13"),1,MATCH("Nuls",INDIRECT("'Bureau "&(ROW()-2)&"'!2:2"),0)) -> 9 | I12: =E12-G12-H12 -> 338 | J12: =E12/C12 -> 0.5862069 | K12: =F12/C12 -> 0.4137931 | L12: =INDEX(INDIRECT("'Bureau " & ROW()-2 & "'!E:E"), MATCH("TOTAL", INDIRECT("'Bureau " & ROW() -2& "'!D:D"), 0)) -> 22 | M12: =INDEX(INDIRECT("'Bureau " & ROW()-2 & "'!F:F"), MATCH("TOTAL", INDIRECT("'Bureau " & ROW() -2& "'!D:D"), 0)) -> 7 | N12: =INDEX(INDIRECT("'Bureau " & ROW()-2 & "'!G:G"), MATCH("TOTAL", INDIRECT("'Bureau " & ROW() -2& "'!D:D"), 0)) -> 99 | O12: =INDEX(INDIRECT("'Bureau " & ROW()-2 & "'!H:H"), MATCH("TOTAL", INDIRECT("'Bureau " & ROW() -2& "'!D:D"), 0)) -> 80 | P12: =INDEX(INDIRECT("'Bureau " & ROW()-2 & "'!I:I"), MATCH("TOTAL", INDIRECT("'Bureau " & ROW() -2& "'!D:D"), 0)) -> 110 | Q12: =INDEX(INDIRECT("'Bureau " & ROW()-2 & "'!J:J"), MATCH("TOTAL", INDIRECT("'Bureau " & ROW() -2& "'!D:D"), 0)) -> 9 | R12: =INDEX(INDIRECT("'Bureau " & ROW()-2 & "'!K:K"), MATCH("TOTAL", INDIRECT("'Bureau " & ROW() -2& "'!D:D"), 0)) -> 11 | S12: {=SUM(IFERROR(L12:R12,0))} -> 338
A13: 11 | B13: CMM | C13: 691 | D13: {=INDIRECT("'Bureau " & ROW()-2 & "'!$B$8")} -> 416 | E13: {=INDIRECT("'Bureau " & ROW()-2 & "'!$B$7")} -> 416 | F13: =C13-E13 -> 275 | G13: =INDEX(INDIRECT("'Bureau "&(ROW()-2)&"'!13:13"),1,MATCH("Blancs",INDIRECT("'Bureau "&(ROW()-2)&"'!2:2"),0)) -> 3 | H13: =INDEX(INDIRECT("'Bureau "&(ROW()-2)&"'!13:13"),1,MATCH("Nuls",INDIRECT("'Bureau "&(ROW()-2)&"'!2:2"),0)) -> 10 | I13: =E13-G13-H13 -> 403 | J13: =E13/C13 -> 0.60202605 | K13: =F13/C13 -> 0.39797395 | L13: =INDEX(INDIRECT("'Bureau " & ROW()-2 & "'!E:E"), MATCH("TOTAL", INDIRECT("'Bureau " & ROW() -2& "'!D:D"), 0)) -> 28 | M13: =INDEX(INDIRECT("'Bureau " & ROW()-2 & "'!F:F"), MATCH("TOTAL", INDIRECT("'Bureau " & ROW() -2& "'!D:D"), 0)) -> 15 | N13: =INDEX(INDIRECT("'Bureau " & ROW()-2 & "'!G:G"), MATCH("TOTAL", INDIRECT("'Bureau " & ROW() -2& "'!D:D"), 0)) -> 137 | O13: =INDEX(INDIRECT("'Bureau " & ROW()-2 & "'!H:H"), MATCH("TOTAL", INDIRECT("'Bureau " & ROW() -2& "'!D:D"), 0)) -> 89 | P13: =INDEX(INDIRECT("'Bureau " & ROW()-2 & "'!I:I"), MATCH("TOTAL", INDIRECT("'Bureau " & ROW() -2& "'!D:D"), 0)) -> 110 | Q13: =INDEX(INDIRECT("'Bureau " & ROW()-2 & "'!J:J"), MATCH("TOTAL", INDIRECT("'Bureau " & ROW() -2& "'!D:D"), 0)) -> 14 | R13: =INDEX(INDIRECT("'Bureau " & ROW()-2 & "'!K:K"), MATCH("TOTAL", INDIRECT("'Bureau " & ROW() -2& "'!D:D"), 0)) -> 10 | S13: {=SUM(IFERROR(L13:R13,0))} -> 403
A14: 12 | B14: Base nautique | C14: 680 | D14: {=INDIRECT("'Bureau " & ROW()-2 & "'!$B$8")} -> 325 | E14: {=INDIRECT("'Bureau " & ROW()-2 & "'!$B$7")} -> 326 | F14: =C14-E14 -> 354 | G14: =INDEX(INDIRECT("'Bureau "&(ROW()-2)&"'!13:13"),1,MATCH("Blancs",INDIRECT("'Bureau "&(ROW()-2)&"'!2:2"),0)) -> 9 | H14: =INDEX(INDIRECT("'Bureau "&(ROW()-2)&"'!13:13"),1,MATCH("Nuls",INDIRECT("'Bureau "&(ROW()-2)&"'!2:2"),0)) -> 2 | I14: =E14-G14-H14 -> 315 | J14: =E14/C14 -> 0.47941176 | K14: =F14/C14 -> 0.52058824 | L14: =INDEX(INDIRECT("'Bureau " & ROW()-2 & "'!E:E"), MATCH("TOTAL", INDIRECT("'Bureau " & ROW() -2& "'!D:D"), 0)) -> 15 | M14: =INDEX(INDIRECT("'Bureau " & ROW()-2 & "'!F:F"), MATCH("TOTAL", INDIRECT("'Bureau " & ROW() -2& "'!D:D"), 0)) -> 12 | N14: =INDEX(INDIRECT("'Bureau " & ROW()-2 & "'!G:G"), MATCH("TOTAL", INDIRECT("'Bureau " & ROW() -2& "'!D:D"), 0)) -> 62 | O14: =INDEX(INDIRECT("'Bureau " & ROW()-2 & "'!H:H"), MATCH("TOTAL", INDIRECT("'Bureau " & ROW() -2& "'!D:D"), 0)) -> 85 | P14: =INDEX(INDIRECT("'Bureau " & ROW()-2 & "'!I:I"), MATCH("TOTAL", INDIRECT("'Bureau " & ROW() -2& "'!D:D"), 0)) -> 79 | Q14: =INDEX(INDIRECT("'Bureau " & ROW()-2 & "'!J:J"), MATCH("TOTAL", INDIRECT("'Bureau " & ROW() -2& "'!D:D"), 0)) -> 51 | R14: =INDEX(INDIRECT("'Bureau " & ROW()-2 & "'!K:K"), MATCH("TOTAL", INDIRECT("'Bureau " & ROW() -2& "'!D:D"), 0)) -> 11 | S14: {=SUM(IFERROR(L14:R14,0))} -> 315
A15: TOTAL | C15: {=SUM(IFERROR(C3:C14,0))} -> 8162 | D15: {=SUM(IFERROR(D3:D14,0))} -> 4681 | E15: {=SUM(IFERROR(E3:E14,0))} -> 4682 | F15: {=SUM(IFERROR(F3:F14,0))} -> 3480 | G15: {=SUM(IFERROR(G3:G14,0))} -> 97 | H15: {=SUM(IFERROR(H3:H14,0))} -> 81 | I15: {=SUM(IFERROR(I3:I14,0))} -> 4504 | J15: =E15 -> 4682 | K15: {=SUM(IFERROR(F3:F14,0))} -> 3480 | L15: {=SUM(IFERROR(L3:L14,0))} -> 309 | M15: {=SUM(IFERROR(M3:M14,0))} -> 156 | N15: {=SUM(IFERROR(N3:N14,0))} -> 1315 | O15: {=SUM(IFERROR(O3:O14,0))} -> 845 | P15: {=SUM(IFERROR(P3:P14,0))} -> 1526 | Q15: {=SUM(IFERROR(Q3:Q14,0))} -> 210 | R15: {=SUM(IFERROR(R3:R14,0))} -> 143 | S15: {=SUM(IFERROR(S3:S14,0))} -> 4504
A16: % | D16: =D15/$C15 -> 0.57351139 | E16: =E15/$C15 -> 0.57363391 | F16: =F15/$C15 -> 0.42636609 | G16: =G15/$C15 -> 0.011884342 | H16: =H15/$C15 -> 0.0099240382 | I16: =I15/$C15 -> 0.55182553 | J16: =J15/$C15 -> 0.57363391 | K16: =K15/$C15 -> 0.42636609 | L16: =IFERROR(L15/$I15,0) -> 0.068605684 | M16: =IFERROR(M15/$I15,0) -> 0.034635879 | N16: =IFERROR(N15/$I15,0) -> 0.2919627 | O16: =IFERROR(O15/$I15,0) -> 0.18761101 | P16: =IFERROR(P15/$I15,0) -> 0.33880995 | Q16: =IFERROR(Q15/$I15,0) -> 0.046625222 | R16: =IFERROR(R15/$I15,0) -> 0.031749556 | S16: =IFERROR(S15/$I15,0) -> 1
A17: Date | B17: 46096
A18: Election | B18: Municipales 1er tour
A19: Ville | B19: Cogolin
A24: Seules les cases bleu clair
A25: sont à remplir
A30: Les cases grisées sont
A31: calculées automatiquement
A32: Ne pas éditer
F40: Nb Candidats | G40: =MATCH("Total exprimé",2:2,0)-12 -> 7
F41: Nb Bureaux | G41: =MATCH("TOTAL",B:B,0)-3 -> #N/A

Sheet Participation horaire
A1: Bureaux | C1: Votants | F1: Inscrits | G1: 09h00 | I1: 10h00 | K1: 11h00 | M1: 12h00 | O1: 13h00 | Q1: 14h00 | S1: 15h00 | U1: 16h00 | W1: 17h00 | Y1: 18h00 | AA1: 19h00 | AC1: 20h00 | AE1: Bureaux | AF1: 09h00 | AG1: 10h00 | AH1: 11h00 | AI1: 12h00 | AJ1: 13h00 | AK1: 14h00 | AL1: 15h00 | AM1: 16h00 | AN1: 17h00 | AO1: 18h00 | AP1: 19h00 | AQ1: 20h00
A2: 1 | B2: =Synthèse!B3 -> Ecole Chabaud | C2: =MAX(G2,I2,K2,M2,O2,Q2,S2,U2,W2,Y2,AA2,AC2) -> 323 | D2: =C2/$F2 -> 0.5840868 | E2: =D2 -> 0.5840868 | F2: =Synthèse!C3 -> 553 | G2: {=INDIRECT("'Bureau " & ROW()-1 & "'!$Q4")} -> 33 | H2: =G2/$F2 -> 0.059674503 | I2: {=INDIRECT("'Bureau " & ROW()-1 & "'!$Q5")} -> 78 | J2: =I2/$F2 -> 0.14104882 | K2: {=INDIRECT("'Bureau " & ROW()-1 & "'!$Q6")} -> 130 | L2: =K2/$F2 -> 0.23508137 | M2: {=INDIRECT("'Bureau " & ROW()-1 & "'!$Q7")} -> 186 | N2: =M2/$F2 -> 0.3363472 | O2: {=INDIRECT("'Bureau " & ROW()-1 & "'!$Q8")} -> 209 | P2: =O2/$F2 -> 0.37793852 | Q2: {=INDIRECT("'Bureau " & ROW()-1 & "'!$Q9")} -> 235 | R2: =Q2/$F2 -> 0.42495479 | S2: {=INDIRECT("'Bureau " & ROW()-1 & "'!$Q10")} -> 256 | T2: =S2/$F2 -> 0.46292948 | U2: {=INDIRECT("'Bureau " & ROW()-1 & "'!$Q11")} -> 282 | V2: =U2/$F2 -> 0.50994575 | W2: {=INDIRECT("'Bureau " & ROW()-1 & "'!$Q12")} -> 303 | X2: =W2/$F2 -> 0.54792043 | Y2: {=INDIRECT("'Bureau " & ROW()-1 & "'!$Q13")} -> 323 | Z2: =Y2/$F2 -> 0.5840868 | AA2: {=INDIRECT("'Bureau " & ROW()-1 & "'!$Q14")} -> 0 | AB2: =AA2/$F2 -> 0 | AC2: {=INDIRECT("'Bureau " & ROW()-1 & "'!$Q15")} -> 0 | AD2: =AC2/$F2 -> 0 | AE2: 1
A3: 2 | B3: =Synthèse!B4 -> Gymnase B | C3: =MAX(G3,I3,K3,M3,O3,Q3,S3,U3,W3,Y3,AA3,AC3) -> 443 | D3: =C3/$F3 -> 0.59864865 | E3: =D3 -> 0.59864865 | F3: =Synthèse!C4 -> 740 | G3: {=INDIRECT("'Bureau " & ROW()-1 & "'!$Q4")} -> 45 | H3: =G3/$F3 -> 0.060810811 | I3: {=INDIRECT("'Bureau " & ROW()-1 & "'!$Q5")} -> 80 | J3: =I3/$F3 -> 0.10810811 | K3: {=INDIRECT("'Bureau " & ROW()-1 & "'!$Q6")} -> 140 | L3: =K3/$F3 -> 0.18918919 | M3: {=INDIRECT("'Bureau " & ROW()-1 & "'!$Q7")} -> 230 | N3: =M3/$F3 -> 0.31081081 | O3: {=INDIRECT("'Bureau " & ROW()-1 & "'!$Q8")} -> 268 | P3: =O3/$F3 -> 0.36216216 | Q3: {=INDIRECT("'Bureau " & ROW()-1 & "'!$Q9")} -> 310 | R3: =Q3/$F3 -> 0.41891892 | S3: {=INDIRECT("'Bureau " & ROW()-1 & "'!$Q10")} -> 360 | T3: =S3/$F3 -> 0.48648649 | U3: {=INDIRECT("'Bureau " & ROW()-1 & "'!$Q11")} -> 390 | V3: =U3/$F3 -> 0.52702703 | W3: {=INDIRECT("'Bureau " & ROW()-1 & "'!$Q12")} -> 415 | X3: =W3/$F3 -> 0.56081081 | Y3: {=INDIRECT("'Bureau " & ROW()-1 & "'!$Q13")} -> 443 | Z3: =Y3/$F3 -> 0.59864865 | AA3: {=INDIRECT("'Bureau " & ROW()-1 & "'!$Q14")} -> 0 | AB3: =AA3/$F3 -> 0 | AC3: {=INDIRECT("'Bureau " & ROW()-1 & "'!$Q15")} -> 0 | AD3: =AC3/$F3 -> 0 | AE3: 2
A4: 3 | B4: =Synthèse!B5 -> Gymnase B | C4: =MAX(G4,I4,K4,M4,O4,Q4,S4,U4,W4,Y4,AA4,AC4) -> 484 | D4: =C4/$F4 -> 0.67882188 | E4: =D4 -> 0.67882188 | F4: =Synthèse!C5 -> 713 | G4: {=INDIRECT("'Bureau " & ROW()-1 & "'!$Q4")} -> 40 | H4: =G4/$F4 -> 0.056100982 | I4: {=INDIRECT("'Bureau " & ROW()-1 & "'!$Q5")} -> 110 | J4: =I4/$F4 -> 0.1542777 | K4: {=INDIRECT("'Bureau " & ROW()-1 & "'!$Q6")} -> 190 | L4: =K4/$F4 -> 0.26647966 | M4: {=INDIRECT("'Bureau " & ROW()-1 & "'!$Q7")} -> 270 | N4: =M4/$F4 -> 0.37868163 | O4: {=INDIRECT("'Bureau " & ROW()-1 & "'!$Q8")} -> 310 | P4: =O4/$F4 -> 0.43478261 | Q4: {=INDIRECT("'Bureau " & ROW()-1 & "'!$Q9")} -> 360 | R4: =Q4/$F4 -> 0.50490884 | S4: {=INDIRECT("'Bureau " & ROW()-1 & "'!$Q10")} -> 410 | T4: =S4/$F4 -> 0.57503506 | U4: {=INDIRECT("'Bureau " & ROW()-1 & "'!$Q11")} -> 440 | V4: =U4/$F4 -> 0.6171108 | W4: {=INDIRECT("'Bureau " & ROW()-1 & "'!$Q12")} -> 470 | X4: =W4/$F4 -> 0.65918654 | Y4: {=INDIRECT("'Bureau " & ROW()-1 & "'!$Q13")} -> 484 | Z4: =Y4/$F4 -> 0.67882188 | AA4: {=INDIRECT("'Bureau " & ROW()-1 & "'!$Q14")} -> 0 | AB4: =AA4/$F4 -> 0 | AC4: {=INDIRECT("'Bureau " & ROW()-1 & "'!$Q15")} -> 0 | AD4: =AC4/$F4 -> 0 | AE4: 3
A5: 4 | B5: =Synthèse!B6 -> Gymnase B | C5: =MAX(G5,I5,K5,M5,O5,Q5,S5,U5,W5,Y5,AA5,AC5) -> 363 | D5: =C5/$F5 -> 0.53460972 | E5: =D5 -> 0.53460972 | F5: =Synthèse!C6 -> 679 | G5: {=INDIRECT("'Bureau " & ROW()-1 & "'!$Q4")} -> 33 | H5: =G5/$F5 -> 0.048600884 | I5: {=INDIRECT("'Bureau " & ROW()-1 & "'!$Q5")} -> 68 | J5: =I5/$F5 -> 0.10014728 | K5: {=INDIRECT("'Bureau " & ROW()-1 & "'!$Q6")} -> 138 | L5: =K5/$F5 -> 0.20324006 | M5: {=INDIRECT("'Bureau " & ROW()-1 & "'!$Q7")} -> 188 | N5: =M5/$F5 -> 0.27687776 | O5: {=INDIRECT("'Bureau " & ROW()-1 & "'!$Q8")} -> 226 | P5: =O5/$F5 -> 0.33284242 | Q5: {=INDIRECT("'Bureau " & ROW()-1 & "'!$Q9")} -> 266 | R5: =Q5/$F5 -> 0.39175258 | S5: {=INDIRECT("'Bureau " & ROW()-1 & "'!$Q10")} -> 306 | T5: =S5/$F5 -> 0.45066274 | U5: {=INDIRECT("'Bureau " & ROW()-1 & "'!$Q11")} -> 336 | V5: =U5/$F5 -> 0.49484536 | W5: {=INDIRECT("'Bureau " & ROW()-1 & "'!$Q12")} -> 351 | X5: =W5/$F5 -> 0.51693667 | Y5: {=INDIRECT("'Bureau " & ROW()-1 & "'!$Q13")} -> 363 | Z5: =Y5/$F5 -> 0.53460972 | AA5: {=INDIRECT("'Bureau " & ROW()-1 & "'!$Q14")} -> 0 | AB5: =AA5/$F5 -> 0 | AC5: {=INDIRECT("'Bureau " & ROW()-1 & "'!$Q15")} -> 0 | AD5: =AC5/$F5 -> 0 | AE5: 4
A6: 5 | B6: =Synthèse!B7 -> COSEC | C6: =MAX(G6,I6,K6,M6,O6,Q6,S6,U6,W6,Y6,AA6,AC6) -> 452 | D6: =C6/$F6 -> 0.64479315 | E6: =D6 -> 0.64479315 | F6: =Synthèse!C7 -> 701 | G6: {=INDIRECT("'Bureau " & ROW()-1 & "'!$Q4")} -> 37 | H6: =G6/$F6 -> 0.05278174 | I6: {=INDIRECT("'Bureau " & ROW()-1 & "'!$Q5")} -> 93 | J6: =I6/$F6 -> 0.13266762 | K6: {=INDIRECT("'Bureau " & ROW()-1 & "'!$Q6")} -> 160 | L6: =K6/$F6 -> 0.22824536 | M6: {=INDIRECT("'Bureau " & ROW()-1 & "'!$Q7")} -> 240 | N6: =M6/$F6 -> 0.34236805 | O6: {=INDIRECT("'Bureau " & ROW()-1 & "'!$Q8")} -> 290 | P6: =O6/$F6 -> 0.41369472 | Q6: {=INDIRECT("'Bureau " & ROW()-1 & "'!$Q9")} -> 325 | R6: =Q6/$F6 -> 0.4636234 | S6: {=INDIRECT("'Bureau " & ROW()-1 & "'!$Q10")} -> 375 | T6: =S6/$F6 -> 0.53495007 | U6: {=INDIRECT("'Bureau " & ROW()-1 & "'!$Q11")} -> 420 | V6: =U6/$F6 -> 0.59914408 | W6: {=INDIRECT("'Bureau " & ROW()-1 & "'!$Q12")} -> 435 | X6: =W6/$F6 -> 0.62054208 | Y6: {=INDIRECT("'Bureau " & ROW()-1 & "'!$Q13")} -> 452 | Z6: =Y6/$F6 -> 0.64479315 | AA6: {=INDIRECT("'Bureau " & ROW()-1 & "'!$Q14")} -> 0 | AB6: =AA6/$F6 -> 0 | AC6: {=INDIRECT("'Bureau " & ROW()-1 & "'!$Q15")} -> 0 | AD6: =AC6/$F6 -> 0 | AE6: 5
A7: 6 | B7: =Synthèse!B8 -> COSEC | C7: =MAX(G7,I7,K7,M7,O7,Q7,S7,U7,W7,Y7,AA7,AC7) -> 367 | D7: =C7/$F7 -> 0.51690141 | E7: =D7 -> 0.51690141 | F7: =Synthèse!C8 -> 710 | G7: {=INDIRECT("'Bureau " & ROW()-1 & "'!$Q4")} -> 30 | H7: =G7/$F7 -> 0.042253521 | I7: {=INDIRECT("'Bureau " & ROW()-1 & "'!$Q5")} -> 89 | J7: =I7/$F7 -> 0.12535211 | K7: {=INDIRECT("'Bureau " & ROW()-1 & "'!$Q6")} -> 140 | L7: =K7/$F7 -> 0.1971831 | M7: {=INDIRECT("'Bureau " & ROW()-1 & "'!$Q7")} -> 190 | N7: =M7/$F7 -> 0.26760563 | O7: {=INDIRECT("'Bureau " & ROW()-1 & "'!$Q8")} -> 237 | P7: =O7/$F7 -> 0.33380282 | Q7: {=INDIRECT("'Bureau " & ROW()-1 & "'!$Q9")} -> 275 | R7: =Q7/$F7 -> 0.38732394 | S7: {=INDIRECT("'Bureau " & ROW()-1 & "'!$Q10")} -> 305 | T7: =S7/$F7 -> 0.42957746 | U7: {=INDIRECT("'Bureau " & ROW()-1 & "'!$Q11")} -> 336 | V7: =U7/$F7 -> 0.47323944 | W7: {=INDIRECT("'Bureau " & ROW()-1 & "'!$Q12")} -> 355 | X7: =W7/$F7 -> 0.5 | Y7: {=INDIRECT("'Bureau " & ROW()-1 & "'!$Q13")} -> 367 | Z7: =Y7/$F7 -> 0.51690141 | AA7: {=INDIRECT("'Bureau " & ROW()-1 & "'!$Q14")} -> 0 | AB7: =AA7/$F7 -> 0 | AC7: {=INDIRECT("'Bureau " & ROW()-1 & "'!$Q15")} -> 0 | AD7: =AC7/$F7 -> 0 | AE7: 6
A8: 7 | B8: =Synthèse!B9 -> COSEC | C8: =MAX(G8,I8,K8,M8,O8,Q8,S8,U8,W8,Y8,AA8,AC8) -> 439 | D8: =C8/$F8 -> 0.6005472 | E8: =D8 -> 0.6005472 | F8: =Synthèse!C9 -> 731 | G8: {=INDIRECT("'Bureau " & ROW()-1 & "'!$Q4")} -> 20 | H8: =G8/$F8 -> 0.027359781 | I8: {=INDIRECT("'Bureau " & ROW()-1 & "'!$Q5")} -> 75 | J8: =I8/$F8 -> 0.10259918 | K8: {=INDIRECT("'Bureau " & ROW()-1 & "'!$Q6")} -> 150 | L8: =K8/$F8 -> 0.20519836 | M8: {=INDIRECT("'Bureau " & ROW()-1 & "'!$Q7")} -> 242 | N8: =M8/$F8 -> 0.33105335 | O8: {=INDIRECT("'Bureau " & ROW()-1 & "'!$Q8")} -> 284 | P8: =O8/$F8 -> 0.38850889 | Q8: {=INDIRECT("'Bureau " & ROW()-1 & "'!$Q9")} -> 310 | R8: =Q8/$F8 -> 0.42407661 | S8: {=INDIRECT("'Bureau " & ROW()-1 & "'!$Q10")} -> 354 | T8: =S8/$F8 -> 0.48426813 | U8: {=INDIRECT("'Bureau " & ROW()-1 & "'!$Q11")} -> 402 | V8: =U8/$F8 -> 0.5499316 | W8: {=INDIRECT("'Bureau " & ROW()-1 & "'!$Q12")} -> 420 | X8: =W8/$F8 -> 0.5745554 | Y8: {=INDIRECT("'Bureau " & ROW()-1 & "'!$Q13")} -> 439 | Z8: =Y8/$F8 -> 0.6005472 | AA8: {=INDIRECT("'Bureau " & ROW()-1 & "'!$Q14")} -> 0 | AB8: =AA8/$F8 -> 0 | AC8: {=INDIRECT("'Bureau " & ROW()-1 & "'!$Q15")} -> 0 | AD8: =AC8/$F8 -> 0 | AE8: 7
A9: 8 | B9: =Synthèse!B10 -> COSEC | C9: =MAX(G9,I9,K9,M9,O9,Q9,S9,U9,W9,Y9,AA9,AC9) -> 379 | D9: =C9/$F9 -> 0.58668731 | E9: =D9 -> 0.58668731 | F9: =Synthèse!C10 -> 646 | G9: {=INDIRECT("'Bureau " & ROW()-1 & "'!$Q4")} -> 36 | H9: =G9/$F9 -> 0.055727554 | I9: {=INDIRECT("'Bureau " & ROW()-1 & "'!$Q5")} -> 72 | J9: =I9/$F9 -> 0.11145511 | K9: {=INDIRECT("'Bureau " & ROW()-1 & "'!$Q6")} -> 149 | L9: =K9/$F9 -> 0.23065015 | M9: {=INDIRECT("'Bureau " & ROW()-1 & "'!$Q7")} -> 213 | N9: =M9/$F9 -> 0.32972136 | O9: {=INDIRECT("'Bureau " & ROW()-1 & "'!$Q8")} -> 260 | P9: =O9/$F9 -> 0.40247678 | Q9: {=INDIRECT("'Bureau " & ROW()-1 & "'!$Q9")} -> 300 | R9: =Q9/$F9 -> 0.46439628 | S9: {=INDIRECT("'Bureau " & ROW()-1 & "'!$Q10")} -> 325 | T9: =S9/$F9 -> 0.50309598 | U9: {=INDIRECT("'Bureau " & ROW()-1 & "'!$Q11")} -> 350 | V9: =U9/$F9 -> 0.54179567 | W9: {=INDIRECT("'Bureau " & ROW()-1 & "'!$Q12")} -> 361 | X9: =W9/$F9 -> 0.55882353 | Y9: {=INDIRECT("'Bureau " & ROW()-1 & "'!$Q13")} -> 379 | Z9: =Y9/$F9 -> 0.58668731 | AA9: {=INDIRECT("'Bureau " & ROW()-1 & "'!$Q14")} -> 0 | AB9: =AA9/$F9 -> 0 | AC9: {=INDIRECT("'Bureau " & ROW()-1 & "'!$Q15")} -> 0 | AD9: =AC9/$F9 -> 0 | AE9: 8
A10: 9 | B10: =Synthèse!B11 -> CMM | C10: =MAX(G10,I10,K10,M10,O10,Q10,S10,U10,W10,Y10,AA10,AC10) -> 333 | D10: =C10/$F10 -> 0.4696756 | E10: =D10 -> 0.4696756 | F10: =Synthèse!C11 -> 709 | G10: {=INDIRECT("'Bureau " & ROW()-1 & "'!$Q4")} -> 22 | H10: =G10/$F10 -> 0.031029619 | I10: {=INDIRECT("'Bureau " & ROW()-1 & "'!$Q5")} -> 59 | J10: =I10/$F10 -> 0.083215797 | K10: {=INDIRECT("'Bureau " & ROW()-1 & "'!$Q6")} -> 105 | L10: =K10/$F10 -> 0.14809591 | M10: {=INDIRECT("'Bureau " & ROW()-1 & "'!$Q7")} -> 165 | N10: =M10/$F10 -> 0.23272214 | O10: {=INDIRECT("'Bureau " & ROW()-1 & "'!$Q8")} -> 192 | P10: =O10/$F10 -> 0.27080395 | Q10: {=INDIRECT("'Bureau " & ROW()-1 & "'!$Q9")} -> 230 | R10: =Q10/$F10 -> 0.32440056 | S10: {=INDIRECT("'Bureau " & ROW()-1 & "'!$Q10")} -> 270 | T10: =S10/$F10 -> 0.38081805 | U10: {=INDIRECT("'Bureau " & ROW()-1 & "'!$Q11")} -> 293 | V10: =U10/$F10 -> 0.41325811 | W10: {=INDIRECT("'Bureau " & ROW()-1 & "'!$Q12")} -> 312 | X10: =W10/$F10 -> 0.44005642 | Y10: {=INDIRECT("'Bureau " & ROW()-1 & "'!$Q13")} -> 333 | Z10: =Y10/$F10 -> 0.4696756 | AA10: {=INDIRECT("'Bureau " & ROW()-1 & "'!$Q14")} -> 0 | AB10: =AA10/$F10 -> 0 | AC10: {=INDIRECT("'Bureau " & ROW()-1 & "'!$Q15")} -> 0 | AD10: =AC10/$F10 -> 0 | AE10: 9
A11: 10 | B11: =Synthèse!B12 -> CMM | C11: =MAX(G11,I11,K11,M11,O11,Q11,S11,U11,W11,Y11,AA11,AC11) -> 357 | D11: =C11/$F11 -> 0.5862069 | E11: =D11 -> 0.5862069 | F11: =Synthèse!C12 -> 609 | G11: {=INDIRECT("'Bureau " & ROW()-1 & "'!$Q4")} -> 27 | H11: =G11/$F11 -> 0.044334975 | I11: {=INDIRECT("'Bureau " & ROW()-1 & "'!$Q5")} -> 70 | J11: =I11/$F11 -> 0.11494253 | K11: {=INDIRECT("'Bureau " & ROW()-1 & "'!$Q6")} -> 140 | L11: =K11/$F11 -> 0.22988506 | M11: {=INDIRECT("'Bureau " & ROW()-1 & "'!$Q7")} -> 210 | N11: =M11/$F11 -> 0.34482759 | O11: {=INDIRECT("'Bureau " & ROW()-1 & "'!$Q8")} -> 240 | P11: =O11/$F11 -> 0.39408867 | Q11: {=INDIRECT("'Bureau " & ROW()-1 & "'!$Q9")} -> 272 | R11: =Q11/$F11 -> 0.44663383 | S11: {=INDIRECT("'Bureau " & ROW()-1 & "'!$Q10")} -> 300 | T11: =S11/$F11 -> 0.49261084 | U11: {=INDIRECT("'Bureau " & ROW()-1 & "'!$Q11")} -> 330 | V11: =U11/$F11 -> 0.54187192 | W11: {=INDIRECT("'Bureau " & ROW()-1 & "'!$Q12")} -> 344 | X11: =W11/$F11 -> 0.56486043 | Y11: {=INDIRECT("'Bureau " & ROW()-1 & "'!$Q13")} -> 357 | Z11: =Y11/$F11 -> 0.5862069 | AA11: {=INDIRECT("'Bureau " & ROW()-1 & "'!$Q14")} -> 0 | AB11: =AA11/$F11 -> 0 | AC11: {=INDIRECT("'Bureau " & ROW()-1 & "'!$Q15")} -> 0 | AD11: =AC11/$F11 -> 0 | AE11: 10
A12: 11 | B12: =Synthèse!B13 -> CMM | C12: =MAX(G12,I12,K12,M12,O12,Q12,S12,U12,W12,Y12,AA12,AC12) -> 416 | D12: =C12/$F12 -> 0.60202605 | E12: =D12 -> 0.60202605 | F12: =Synthèse!C13 -> 691 | G12: {=INDIRECT("'Bureau " & ROW()-1 & "'!$Q4")} -> 47 | H12: =G12/$F12 -> 0.068017366 | I12: {=INDIRECT("'Bureau " & ROW()-1 & "'!$Q5")} -> 96 | J12: =I12/$F12 -> 0.13892909 | K12: {=INDIRECT("'Bureau " & ROW()-1 & "'!$Q6")} -> 158 | L12: =K12/$F12 -> 0.22865412 | M12: {=INDIRECT("'Bureau " & ROW()-1 & "'!$Q7")} -> 215 | N12: =M12/$F12 -> 0.31114327 | O12: {=INDIRECT("'Bureau " & ROW()-1 & "'!$Q8")} -> 264 | P12: =O12/$F12 -> 0.38205499 | Q12: {=INDIRECT("'Bureau " & ROW()-1 & "'!$Q9")} -> 299 | R12: =Q12/$F12 -> 0.43270622 | S12: {=INDIRECT("'Bureau " & ROW()-1 & "'!$Q10")} -> 332 | T12: =S12/$F12 -> 0.4804631 | U12: {=INDIRECT("'Bureau " & ROW()-1 & "'!$Q11")} -> 382 | V12: =U12/$F12 -> 0.552822 | W12: {=INDIRECT("'Bureau " & ROW()-1 & "'!$Q12")} -> 398 | X12: =W12/$F12 -> 0.57597685 | Y12: {=INDIRECT("'Bureau " & ROW()-1 & "'!$Q13")} -> 416 | Z12: =Y12/$F12 -> 0.60202605 | AA12: {=INDIRECT("'Bureau " & ROW()-1 & "'!$Q14")} -> 0 | AB12: =AA12/$F12 -> 0 | AC12: {=INDIRECT("'Bureau " & ROW()-1 & "'!$Q15")} -> 0 | AD12: =AC12/$F12 -> 0 | AE12: 11
A13: 12 | B13: =Synthèse!B14 -> Base nautique | C13: =MAX(G13,I13,K13,M13,O13,Q13,S13,U13,W13,Y13,AA13,AC13) -> 326 | D13: =C13/$F13 -> 0.47941176 | E13: =D13 -> 0.47941176 | F13: =Synthèse!C14 -> 680 | G13: {=INDIRECT("'Bureau " & ROW()-1 & "'!$Q4")} -> 24 | H13: =G13/$F13 -> 0.035294118 | I13: {=INDIRECT("'Bureau " & ROW()-1 & "'!$Q5")} -> 49 | J13: =I13/$F13 -> 0.072058824 | K13: {=INDIRECT("'Bureau " & ROW()-1 & "'!$Q6")} -> 96 | L13: =K13/$F13 -> 0.14117647 | M13: {=INDIRECT("'Bureau " & ROW()-1 & "'!$Q7")} -> 143 | N13: =M13/$F13 -> 0.21029412 | O13: {=INDIRECT("'Bureau " & ROW()-1 & "'!$Q8")} -> 182 | P13: =O13/$F13 -> 0.26764706 | Q13: {=INDIRECT("'Bureau " & ROW()-1 & "'!$Q9")} -> 217 | R13: =Q13/$F13 -> 0.31911765 | S13: {=INDIRECT("'Bureau " & ROW()-1 & "'!$Q10")} -> 251 | T13: =S13/$F13 -> 0.36911765 | U13: {=INDIRECT("'Bureau " & ROW()-1 & "'!$Q11")} -> 287 | V13: =U13/$F13 -> 0.42205882 | W13: {=INDIRECT("'Bureau " & ROW()-1 & "'!$Q12")} -> 321 | X13: =W13/$F13 -> 0.47205882 | Y13: {=INDIRECT("'Bureau " & ROW()-1 & "'!$Q13")} -> 326 | Z13: =Y13/$F13 -> 0.47941176 | AA13: {=INDIRECT("'Bureau " & ROW()-1 & "'!$Q14")} -> 0 | AB13: =AA13/$F13 -> 0 | AC13: {=INDIRECT("'Bureau " & ROW()-1 & "'!$Q15")} -> 0 | AD13: =AC13/$F13 -> 0 | AE13: 12
A14: TOTAL | C14: =SUM(C2:C13) -> 4682 | D14: =C14/$F14 -> 0.57363391 | E14: =D14 -> 0.57363391 | F14: =SUM(F2:F13) -> 8162 | G14: =SUM(G2:G13) -> 394 | H14: =G14/$F14 -> 0.048272482 | I14: =SUM(I2:I13) -> 939 | J14: =I14/$F14 -> 0.11504533 | K14: =SUM(K2:K13) -> 1696 | L14: =K14/$F14 -> 0.20779221 | M14: =SUM(M2:M13) -> 2492 | N14: =M14/$F14 -> 0.30531732 | O14: =SUM(O2:O13) -> 2962 | P14: =O14/$F14 -> 0.36290125 | Q14: =SUM(Q2:Q13) -> 3399 | R14: =Q14/$F14 -> 0.41644205 | S14: =SUM(S2:S13) -> 3844 | T14: =S14/$F14 -> 0.470963 | U14: =SUM(U2:U13) -> 4248 | V14: =U14/$F14 -> 0.52046067 | W14: =SUM(W2:W13) -> 4485 | X14: =W14/$F14 -> 0.54949767 | Y14: =SUM(Y2:Y13) -> 4682 | Z14: =Y14/$F14 -> 0.57363391 | AA14: =SUM(AA2:AA13) -> 0 | AB14: =AA14/$F14 -> 0 | AC14: =SUM(AC2:AC13) -> 0 | AD14: =AC14/$F14 -> 0 | AE14: Total
A15: Date | B15: =Synthèse!$B$17 -> 46096 | AE15: Valeurs du tour précédent
A16: Election | B16: =Synthèse!$B$18 -> Municipales 1er tour
A17: Ville | B17: =Synthèse!$B$19 -> Cogolin
B29: Les cases grisées sont
B30: calculées automatiquement
B31: Ne pas éditer
G36: Tour actuel | U36: Tour précédent
F37: Heure | G37: Bureau 1 | H37: Bureau 2 | I37: Bureau 3 | J37: Bureau 4 | K37: Bureau 5 | L37: Bureau 6 | M37: Bureau 7 | N37: Bureau 8 | O37: Bureau 9 | P37: Bureau 10 | Q37: Bureau 11 | R37: Bureau 12 | S37: Total | T37: Heure | U37: Bureau 1 | V37: Bureau 2 | W37: Bureau 3 | X37: Bureau 4 | Y37: Bureau 5 | Z37: Bureau 6 | AA37: Bureau 7 | AB37: Bureau 8 | AC37: Bureau 9 | AD37: Bureau 10 | AE37: Bureau 11 | AF37: Bureau 12 | AG37: Total
F38: 08h00 | G38: 0 | H38: 0 | I38: 0 | J38: 0 | K38: 0 | L38: 0 | M38: 0 | N38: 0 | O38: 0 | P38: 0 | Q38: 0 | R38: 0 | S38: 0 | T38: 08h00 | U38: 0 | V38: 0 | W38: 0 | X38: 0 | Y38: 0 | Z38: 0 | AA38: 0 | AB38: 0 | AC38: 0 | AD38: 0 | AE38: 0 | AF38: 0 | AG38: 0
F39: 09h00 | G39: {=IF( INDEX($H$2:$Z$14, COLUMN(A1), 2*ROW(A1)-1)>0, INDEX($H$2:$Z$14, COLUMN(A1), 2*ROW(A1)-1), NA() )} -> 0.059674503 | H39: {=IF( INDEX($H$2:$Z$14, COLUMN(B1), 2*ROW(B1)-1)>0, INDEX($H$2:$Z$14, COLUMN(B1), 2*ROW(B1)-1), NA() )} -> 0.060810811 | I39: {=IF( INDEX($H$2:$Z$14, COLUMN(C1), 2*ROW(C1)-1)>0, INDEX($H$2:$Z$14, COLUMN(C1), 2*ROW(C1)-1), NA() )} -> 0.056100982 | J39: {=IF( INDEX($H$2:$Z$14, COLUMN(D1), 2*ROW(D1)-1)>0, INDEX($H$2:$Z$14, COLUMN(D1), 2*ROW(D1)-1), NA() )} -> 0.048600884 | K39: {=IF( INDEX($H$2:$Z$14, COLUMN(E1), 2*ROW(E1)-1)>0, INDEX($H$2:$Z$14, COLUMN(E1), 2*ROW(E1)-1), NA() )} -> 0.05278174 | L39: {=IF( INDEX($H$2:$Z$14, COLUMN(F1), 2*ROW(F1)-1)>0, INDEX($H$2:$Z$14, COLUMN(F1), 2*ROW(F1)-1), NA() )} -> 0.042253521 | M39: {=IF( INDEX($H$2:$Z$14, COLUMN(G1), 2*ROW(G1)-1)>0, INDEX($H$2:$Z$14, COLUMN(G1), 2*ROW(G1)-1), NA() )} -> 0.027359781 | N39: {=IF( INDEX($H$2:$Z$14, COLUMN(H1), 2*ROW(H1)-1)>0, INDEX($H$2:$Z$14, COLUMN(H1), 2*ROW(H1)-1), NA() )} -> 0.055727554 | ... S39: {=IF( INDEX($H$2:$Z$14, COLUMN(M1), 2*ROW(M1)-1)>0, INDEX($H$2:$Z$14, COLUMN(M1), 2*ROW(M1)-1), NA() )} -> 0.048272482 | T39: 09h00 | U39: =AF2 -> 0 | V39: =AF3 -> 0 | W39: =AF4 -> 0 | X39: =AF5 -> 0 | Y39: =AF6 -> 0 | Z39: =AF7 -> 0 | AA39: =AF8 -> 0 | AB39: =AF9 -> 0 | AC39: =AF10 -> 0 | AD39: =AF11 -> 0 | AE39: =AF12 -> 0 | AF39: =AF13 -> 0 | AG39: =AF14 -> 0
F40: 10h00 | G40: {=IF( INDEX($H$2:$Z$14, COLUMN(A2), 2*ROW(A2)-1)>0, INDEX($H$2:$Z$14, COLUMN(A2), 2*ROW(A2)-1), NA() )} -> 0.14104882 | H40: {=IF( INDEX($H$2:$Z$14, COLUMN(B2), 2*ROW(B2)-1)>0, INDEX($H$2:$Z$14, COLUMN(B2), 2*ROW(B2)-1), NA() )} -> 0.10810811 | I40: {=IF( INDEX($H$2:$Z$14, COLUMN(C2), 2*ROW(C2)-1)>0, INDEX($H$2:$Z$14, COLUMN(C2), 2*ROW(C2)-1), NA() )} -> 0.1542777 | J40: {=IF( INDEX($H$2:$Z$14, COLUMN(D2), 2*ROW(D2)-1)>0, INDEX($H$2:$Z$14, COLUMN(D2), 2*ROW(D2)-1), NA() )} -> 0.10014728 | K40: {=IF( INDEX($H$2:$Z$14, COLUMN(E2), 2*ROW(E2)-1)>0, INDEX($H$2:$Z$14, COLUMN(E2), 2*ROW(E2)-1), NA() )} -> 0.13266762 | L40: {=IF( INDEX($H$2:$Z$14, COLUMN(F2), 2*ROW(F2)-1)>0, INDEX($H$2:$Z$14, COLUMN(F2), 2*ROW(F2)-1), NA() )} -> 0.12535211 | M40: {=IF( INDEX($H$2:$Z$14, COLUMN(G2), 2*ROW(G2)-1)>0, INDEX($H$2:$Z$14, COLUMN(G2), 2*ROW(G2)-1), NA() )} -> 0.10259918 | N40: {=IF( INDEX($H$2:$Z$14, COLUMN(H2), 2*ROW(H2)-1)>0, INDEX($H$2:$Z$14, COLUMN(H2), 2*ROW(H2)-1), NA() )} -> 0.11145511 | ... S40: {=IF( INDEX($H$2:$Z$14, COLUMN(M2), 2*ROW(M2)-1)>0, INDEX($H$2:$Z$14, COLUMN(M2), 2*ROW(M2)-1), NA() )} -> 0.11504533 | T40: 10h00 | U40: =AG2 -> 0 | V40: =AG3 -> 0 | W40: =AG4 -> 0 | X40: =AG5 -> 0 | Y40: =AG6 -> 0 | Z40: =AG7 -> 0 | AA40: =AG8 -> 0 | AB40: =AG9 -> 0 | AC40: =AG10 -> 0 | AD40: =AG11 -> 0 | AE40: =AG12 -> 0 | AF40: =AG13 -> 0 | AG40: =AG14 -> 0
F41: 11h00 | G41: {=IF( INDEX($H$2:$Z$14, COLUMN(A3), 2*ROW(A3)-1)>0, INDEX($H$2:$Z$14, COLUMN(A3), 2*ROW(A3)-1), NA() )} -> 0.23508137 | H41: {=IF( INDEX($H$2:$Z$14, COLUMN(B3), 2*ROW(B3)-1)>0, INDEX($H$2:$Z$14, COLUMN(B3), 2*ROW(B3)-1), NA() )} -> 0.18918919 | I41: {=IF( INDEX($H$2:$Z$14, COLUMN(C3), 2*ROW(C3)-1)>0, INDEX($H$2:$Z$14, COLUMN(C3), 2*ROW(C3)-1), NA() )} -> 0.26647966 | J41: {=IF( INDEX($H$2:$Z$14, COLUMN(D3), 2*ROW(D3)-1)>0, INDEX($H$2:$Z$14, COLUMN(D3), 2*ROW(D3)-1), NA() )} -> 0.20324006 | K41: {=IF( INDEX($H$2:$Z$14, COLUMN(E3), 2*ROW(E3)-1)>0, INDEX($H$2:$Z$14, COLUMN(E3), 2*ROW(E3)-1), NA() )} -> 0.22824536 | L41: {=IF( INDEX($H$2:$Z$14, COLUMN(F3), 2*ROW(F3)-1)>0, INDEX($H$2:$Z$14, COLUMN(F3), 2*ROW(F3)-1), NA() )} -> 0.1971831 | M41: {=IF( INDEX($H$2:$Z$14, COLUMN(G3), 2*ROW(G3)-1)>0, INDEX($H$2:$Z$14, COLUMN(G3), 2*ROW(G3)-1), NA() )} -> 0.20519836 | N41: {=IF( INDEX($H$2:$Z$14, COLUMN(H3), 2*ROW(H3)-1)>0, INDEX($H$2:$Z$14, COLUMN(H3), 2*ROW(H3)-1), NA() )} -> 0.23065015 | ... S41: {=IF( INDEX($H$2:$Z$14, COLUMN(M3), 2*ROW(M3)-1)>0, INDEX($H$2:$Z$14, COLUMN(M3), 2*ROW(M3)-1), NA() )} -> 0.20779221 | T41: 11h00 | U41: =AH2 -> 0 | V41: =AH3 -> 0 | W41: =AH4 -> 0 | X41: =AH5 -> 0 | Y41: =AH6 -> 0 | Z41: =AH7 -> 0 | AA41: =AH8 -> 0 | AB41: =AH9 -> 0 | AC41: =AH10 -> 0 | AD41: =AH11 -> 0 | AE41: =AH12 -> 0 | AF41: =AH13 -> 0 | AG41: =AH14 -> 0
F42: 12h00 | G42: {=IF( INDEX($H$2:$Z$14, COLUMN(A4), 2*ROW(A4)-1)>0, INDEX($H$2:$Z$14, COLUMN(A4), 2*ROW(A4)-1), NA() )} -> 0.3363472 | H42: {=IF( INDEX($H$2:$Z$14, COLUMN(B4), 2*ROW(B4)-1)>0, INDEX($H$2:$Z$14, COLUMN(B4), 2*ROW(B4)-1), NA() )} -> 0.31081081 | I42: {=IF( INDEX($H$2:$Z$14, COLUMN(C4), 2*ROW(C4)-1)>0, INDEX($H$2:$Z$14, COLUMN(C4), 2*ROW(C4)-1), NA() )} -> 0.37868163 | J42: {=IF( INDEX($H$2:$Z$14, COLUMN(D4), 2*ROW(D4)-1)>0, INDEX($H$2:$Z$14, COLUMN(D4), 2*ROW(D4)-1), NA() )} -> 0.27687776 | K42: {=IF( INDEX($H$2:$Z$14, COLUMN(E4), 2*ROW(E4)-1)>0, INDEX($H$2:$Z$14, COLUMN(E4), 2*ROW(E4)-1), NA() )} -> 0.34236805 | L42: {=IF( INDEX($H$2:$Z$14, COLUMN(F4), 2*ROW(F4)-1)>0, INDEX($H$2:$Z$14, COLUMN(F4), 2*ROW(F4)-1), NA() )} -> 0.26760563 | M42: {=IF( INDEX($H$2:$Z$14, COLUMN(G4), 2*ROW(G4)-1)>0, INDEX($H$2:$Z$14, COLUMN(G4), 2*ROW(G4)-1), NA() )} -> 0.33105335 | N42: {=IF( INDEX($H$2:$Z$14, COLUMN(H4), 2*ROW(H4)-1)>0, INDEX($H$2:$Z$14, COLUMN(H4), 2*ROW(H4)-1), NA() )} -> 0.32972136 | ... S42: {=IF( INDEX($H$2:$Z$14, COLUMN(M4), 2*ROW(M4)-1)>0, INDEX($H$2:$Z$14, COLUMN(M4), 2*ROW(M4)-1), NA() )} -> 0.30531732 | T42: 12h00 | U42: =AI2 -> 0 | V42: =AI3 -> 0 | W42: =AI4 -> 0 | X42: =AI5 -> 0 | Y42: =AI6 -> 0 | Z42: =AI7 -> 0 | AA42: =AI8 -> 0 | AB42: =AI9 -> 0 | AC42: =AI10 -> 0 | AD42: =AI11 -> 0 | AE42: =AI12 -> 0 | AF42: =AI13 -> 0 | AG42: =AI14 -> 0
F43: 13h00 | G43: {=IF( INDEX($H$2:$Z$14, COLUMN(A5), 2*ROW(A5)-1)>0, INDEX($H$2:$Z$14, COLUMN(A5), 2*ROW(A5)-1), NA() )} -> 0.37793852 | H43: {=IF( INDEX($H$2:$Z$14, COLUMN(B5), 2*ROW(B5)-1)>0, INDEX($H$2:$Z$14, COLUMN(B5), 2*ROW(B5)-1), NA() )} -> 0.36216216 | I43: {=IF( INDEX($H$2:$Z$14, COLUMN(C5), 2*ROW(C5)-1)>0, INDEX($H$2:$Z$14, COLUMN(C5), 2*ROW(C5)-1), NA() )} -> 0.43478261 | J43: {=IF( INDEX($H$2:$Z$14, COLUMN(D5), 2*ROW(D5)-1)>0, INDEX($H$2:$Z$14, COLUMN(D5), 2*ROW(D5)-1), NA() )} -> 0.33284242 | K43: {=IF( INDEX($H$2:$Z$14, COLUMN(E5), 2*ROW(E5)-1)>0, INDEX($H$2:$Z$14, COLUMN(E5), 2*ROW(E5)-1), NA() )} -> 0.41369472 | L43: {=IF( INDEX($H$2:$Z$14, COLUMN(F5), 2*ROW(F5)-1)>0, INDEX($H$2:$Z$14, COLUMN(F5), 2*ROW(F5)-1), NA() )} -> 0.33380282 | M43: {=IF( INDEX($H$2:$Z$14, COLUMN(G5), 2*ROW(G5)-1)>0, INDEX($H$2:$Z$14, COLUMN(G5), 2*ROW(G5)-1), NA() )} -> 0.38850889 | N43: {=IF( INDEX($H$2:$Z$14, COLUMN(H5), 2*ROW(H5)-1)>0, INDEX($H$2:$Z$14, COLUMN(H5), 2*ROW(H5)-1), NA() )} -> 0.40247678 | ... S43: {=IF( INDEX($H$2:$Z$14, COLUMN(M5), 2*ROW(M5)-1)>0, INDEX($H$2:$Z$14, COLUMN(M5), 2*ROW(M5)-1), NA() )} -> 0.36290125 | T43: 13h00 | U43: =AJ2 -> 0 | V43: =AJ3 -> 0 | W43: =AJ4 -> 0 | X43: =AJ5 -> 0 | Y43: =AJ6 -> 0 | Z43: =AJ7 -> 0 | AA43: =AJ8 -> 0 | AB43: =AJ9 -> 0 | AC43: =AJ10 -> 0 | AD43: =AJ11 -> 0 | AE43: =AJ12 -> 0 | AF43: =AJ13 -> 0 | AG43: =AJ14 -> 0
F44: 14h00 | G44: {=IF( INDEX($H$2:$Z$14, COLUMN(A6), 2*ROW(A6)-1)>0, INDEX($H$2:$Z$14, COLUMN(A6), 2*ROW(A6)-1), NA() )} -> 0.42495479 | H44: {=IF( INDEX($H$2:$Z$14, COLUMN(B6), 2*ROW(B6)-1)>0, INDEX($H$2:$Z$14, COLUMN(B6), 2*ROW(B6)-1), NA() )} -> 0.41891892 | I44: {=IF( INDEX($H$2:$Z$14, COLUMN(C6), 2*ROW(C6)-1)>0, INDEX($H$2:$Z$14, COLUMN(C6), 2*ROW(C6)-1), NA() )} -> 0.50490884 | J44: {=IF( INDEX($H$2:$Z$14, COLUMN(D6), 2*ROW(D6)-1)>0, INDEX($H$2:$Z$14, COLUMN(D6), 2*ROW(D6)-1), NA() )} -> 0.39175258 | K44: {=IF( INDEX($H$2:$Z$14, COLUMN(E6), 2*ROW(E6)-1)>0, INDEX($H$2:$Z$14, COLUMN(E6), 2*ROW(E6)-1), NA() )} -> 0.4636234 | L44: {=IF( INDEX($H$2:$Z$14, COLUMN(F6), 2*ROW(F6)-1)>0, INDEX($H$2:$Z$14, COLUMN(F6), 2*ROW(F6)-1), NA() )} -> 0.38732394 | M44: {=IF( INDEX($H$2:$Z$14, COLUMN(G6), 2*ROW(G6)-1)>0, INDEX($H$2:$Z$14, COLUMN(G6), 2*ROW(G6)-1), NA() )} -> 0.42407661 | N44: {=IF( INDEX($H$2:$Z$14, COLUMN(H6), 2*ROW(H6)-1)>0, INDEX($H$2:$Z$14, COLUMN(H6), 2*ROW(H6)-1), NA() )} -> 0.46439628 | ... S44: {=IF( INDEX($H$2:$Z$14, COLUMN(M6), 2*ROW(M6)-1)>0, INDEX($H$2:$Z$14, COLUMN(M6), 2*ROW(M6)-1), NA() )} -> 0.41644205 | T44: 14h00 | U44: =AK2 -> 0 | V44: =AK3 -> 0 | W44: =AK4 -> 0 | X44: =AK5 -> 0 | Y44: =AK6 -> 0 | Z44: =AK7 -> 0 | AA44: =AK8 -> 0 | AB44: =AK9 -> 0 | AC44: =AK10 -> 0 | AD44: =AK11 -> 0 | AE44: =AK12 -> 0 | AF44: =AK13 -> 0 | AG44: =AK14 -> 0
F45: 15h00 | G45: {=IF( INDEX($H$2:$Z$14, COLUMN(A7), 2*ROW(A7)-1)>0, INDEX($H$2:$Z$14, COLUMN(A7), 2*ROW(A7)-1), NA() )} -> 0.46292948 | H45: {=IF( INDEX($H$2:$Z$14, COLUMN(B7), 2*ROW(B7)-1)>0, INDEX($H$2:$Z$14, COLUMN(B7), 2*ROW(B7)-1), NA() )} -> 0.48648649 | I45: {=IF( INDEX($H$2:$Z$14, COLUMN(C7), 2*ROW(C7)-1)>0, INDEX($H$2:$Z$14, COLUMN(C7), 2*ROW(C7)-1), NA() )} -> 0.57503506 | J45: {=IF( INDEX($H$2:$Z$14, COLUMN(D7), 2*ROW(D7)-1)>0, INDEX($H$2:$Z$14, COLUMN(D7), 2*ROW(D7)-1), NA() )} -> 0.45066274 | K45: {=IF( INDEX($H$2:$Z$14, COLUMN(E7), 2*ROW(E7)-1)>0, INDEX($H$2:$Z$14, COLUMN(E7), 2*ROW(E7)-1), NA() )} -> 0.53495007 | L45: {=IF( INDEX($H$2:$Z$14, COLUMN(F7), 2*ROW(F7)-1)>0, INDEX($H$2:$Z$14, COLUMN(F7), 2*ROW(F7)-1), NA() )} -> 0.42957746 | M45: {=IF( INDEX($H$2:$Z$14, COLUMN(G7), 2*ROW(G7)-1)>0, INDEX($H$2:$Z$14, COLUMN(G7), 2*ROW(G7)-1), NA() )} -> 0.48426813 | N45: {=IF( INDEX($H$2:$Z$14, COLUMN(H7), 2*ROW(H7)-1)>0, INDEX($H$2:$Z$14, COLUMN(H7), 2*ROW(H7)-1), NA() )} -> 0.50309598 | ... S45: {=IF( INDEX($H$2:$Z$14, COLUMN(M7), 2*ROW(M7)-1)>0, INDEX($H$2:$Z$14, COLUMN(M7), 2*ROW(M7)-1), NA() )} -> 0.470963 | T45: 15h00 | U45: =AL2 -> 0 | V45: =AL3 -> 0 | W45: =AL4 -> 0 | X45: =AL5 -> 0 | Y45: =AL6 -> 0 | Z45: =AL7 -> 0 | AA45: =AL8 -> 0 | AB45: =AL9 -> 0 | AC45: =AL10 -> 0 | AD45: =AL11 -> 0 | AE45: =AL12 -> 0 | AF45: =AL13 -> 0 | AG45: =AL14 -> 0
F46: 16h00 | G46: {=IF( INDEX($H$2:$Z$14, COLUMN(A8), 2*ROW(A8)-1)>0, INDEX($H$2:$Z$14, COLUMN(A8), 2*ROW(A8)-1), NA() )} -> 0.50994575 | H46: {=IF( INDEX($H$2:$Z$14, COLUMN(B8), 2*ROW(B8)-1)>0, INDEX($H$2:$Z$14, COLUMN(B8), 2*ROW(B8)-1), NA() )} -> 0.52702703 | I46: {=IF( INDEX($H$2:$Z$14, COLUMN(C8), 2*ROW(C8)-1)>0, INDEX($H$2:$Z$14, COLUMN(C8), 2*ROW(C8)-1), NA() )} -> 0.6171108 | J46: {=IF( INDEX($H$2:$Z$14, COLUMN(D8), 2*ROW(D8)-1)>0, INDEX($H$2:$Z$14, COLUMN(D8), 2*ROW(D8)-1), NA() )} -> 0.49484536 | K46: {=IF( INDEX($H$2:$Z$14, COLUMN(E8), 2*ROW(E8)-1)>0, INDEX($H$2:$Z$14, COLUMN(E8), 2*ROW(E8)-1), NA() )} -> 0.59914408 | L46: {=IF( INDEX($H$2:$Z$14, COLUMN(F8), 2*ROW(F8)-1)>0, INDEX($H$2:$Z$14, COLUMN(F8), 2*ROW(F8)-1), NA() )} -> 0.47323944 | M46: {=IF( INDEX($H$2:$Z$14, COLUMN(G8), 2*ROW(G8)-1)>0, INDEX($H$2:$Z$14, COLUMN(G8), 2*ROW(G8)-1), NA() )} -> 0.5499316 | N46: {=IF( INDEX($H$2:$Z$14, COLUMN(H8), 2*ROW(H8)-1)>0, INDEX($H$2:$Z$14, COLUMN(H8), 2*ROW(H8)-1), NA() )} -> 0.54179567 | ... S46: {=IF( INDEX($H$2:$Z$14, COLUMN(M8), 2*ROW(M8)-1)>0, INDEX($H$2:$Z$14, COLUMN(M8), 2*ROW(M8)-1), NA() )} -> 0.52046067 | T46: 16h00 | U46: =AM2 -> 0 | V46: =AM3 -> 0 | W46: =AM4 -> 0 | X46: =AM5 -> 0 | Y46: =AM6 -> 0 | Z46: =AM7 -> 0 | AA46: =AM8 -> 0 | AB46: =AM9 -> 0 | AC46: =AM10 -> 0 | AD46: =AM11 -> 0 | AE46: =AM12 -> 0 | AF46: =AM13 -> 0 | AG46: =AM14 -> 0
F47: 17h00 | G47: {=IF( INDEX($H$2:$Z$14, COLUMN(A9), 2*ROW(A9)-1)>0, INDEX($H$2:$Z$14, COLUMN(A9), 2*ROW(A9)-1), NA() )} -> 0.54792043 | H47: {=IF( INDEX($H$2:$Z$14, COLUMN(B9), 2*ROW(B9)-1)>0, INDEX($H$2:$Z$14, COLUMN(B9), 2*ROW(B9)-1), NA() )} -> 0.56081081 | I47: {=IF( INDEX($H$2:$Z$14, COLUMN(C9), 2*ROW(C9)-1)>0, INDEX($H$2:$Z$14, COLUMN(C9), 2*ROW(C9)-1), NA() )} -> 0.65918654 | J47: {=IF( INDEX($H$2:$Z$14, COLUMN(D9), 2*ROW(D9)-1)>0, INDEX($H$2:$Z$14, COLUMN(D9), 2*ROW(D9)-1), NA() )} -> 0.51693667 | K47: {=IF( INDEX($H$2:$Z$14, COLUMN(E9), 2*ROW(E9)-1)>0, INDEX($H$2:$Z$14, COLUMN(E9), 2*ROW(E9)-1), NA() )} -> 0.62054208 | L47: {=IF( INDEX($H$2:$Z$14, COLUMN(F9), 2*ROW(F9)-1)>0, INDEX($H$2:$Z$14, COLUMN(F9), 2*ROW(F9)-1), NA() )} -> 0.5 | M47: {=IF( INDEX($H$2:$Z$14, COLUMN(G9), 2*ROW(G9)-1)>0, INDEX($H$2:$Z$14, COLUMN(G9), 2*ROW(G9)-1), NA() )} -> 0.5745554 | N47: {=IF( INDEX($H$2:$Z$14, COLUMN(H9), 2*ROW(H9)-1)>0, INDEX($H$2:$Z$14, COLUMN(H9), 2*ROW(H9)-1), NA() )} -> 0.55882353 | ... S47: {=IF( INDEX($H$2:$Z$14, COLUMN(M9), 2*ROW(M9)-1)>0, INDEX($H$2:$Z$14, COLUMN(M9), 2*ROW(M9)-1), NA() )} -> 0.54949767 | T47: 17h00 | U47: =AN2 -> 0 | V47: =AN3 -> 0 | W47: =AN4 -> 0 | X47: =AN5 -> 0 | Y47: =AN6 -> 0 | Z47: =AN7 -> 0 | AA47: =AN8 -> 0 | AB47: =AN9 -> 0 | AC47: =AN10 -> 0 | AD47: =AN11 -> 0 | AE47: =AN12 -> 0 | AF47: =AN13 -> 0 | AG47: =AN14 -> 0
F48: 18h00 | G48: {=IF( INDEX($H$2:$Z$14, COLUMN(A10), 2*ROW(A10)-1)>0, INDEX($H$2:$Z$14, COLUMN(A10), 2*ROW(A10)-1), NA() )} -> 0.5840868 | H48: {=IF( INDEX($H$2:$Z$14, COLUMN(B10), 2*ROW(B10)-1)>0, INDEX($H$2:$Z$14, COLUMN(B10), 2*ROW(B10)-1), NA() )} -> 0.59864865 | I48: {=IF( INDEX($H$2:$Z$14, COLUMN(C10), 2*ROW(C10)-1)>0, INDEX($H$2:$Z$14, COLUMN(C10), 2*ROW(C10)-1), NA() )} -> 0.67882188 | J48: {=IF( INDEX($H$2:$Z$14, COLUMN(D10), 2*ROW(D10)-1)>0, INDEX($H$2:$Z$14, COLUMN(D10), 2*ROW(D10)-1), NA() )} -> 0.53460972 | K48: {=IF( INDEX($H$2:$Z$14, COLUMN(E10), 2*ROW(E10)-1)>0, INDEX($H$2:$Z$14, COLUMN(E10), 2*ROW(E10)-1), NA() )} -> 0.64479315 | L48: {=IF( INDEX($H$2:$Z$14, COLUMN(F10), 2*ROW(F10)-1)>0, INDEX($H$2:$Z$14, COLUMN(F10), 2*ROW(F10)-1), NA() )} -> 0.51690141 | M48: {=IF( INDEX($H$2:$Z$14, COLUMN(G10), 2*ROW(G10)-1)>0, INDEX($H$2:$Z$14, COLUMN(G10), 2*ROW(G10)-1), NA() )} -> 0.6005472 | N48: {=IF( INDEX($H$2:$Z$14, COLUMN(H10), 2*ROW(H10)-1)>0, INDEX($H$2:$Z$14, COLUMN(H10), 2*ROW(H10)-1), NA() )} -> 0.58668731 | ... S48: {=IF( INDEX($H$2:$Z$14, COLUMN(M10), 2*ROW(M10)-1)>0, INDEX($H$2:$Z$14, COLUMN(M10), 2*ROW(M10)-1), NA() )} -> 0.57363391 | T48: 18h00 | U48: =AO2 -> 0 | V48: =AO3 -> 0 | W48: =AO4 -> 0 | X48: =AO5 -> 0 | Y48: =AO6 -> 0 | Z48: =AO7 -> 0 | AA48: =AO8 -> 0 | AB48: =AO9 -> 0 | AC48: =AO10 -> 0 | AD48: =AO11 -> 0 | AE48: =AO12 -> 0 | AF48: =AO13 -> 0 | AG48: =AO14 -> 0
F49: 19h00 | G49: {=IF( INDEX($H$2:$Z$14, COLUMN(A11), 2*ROW(A11)-1)>0, INDEX($H$2:$Z$14, COLUMN(A11), 2*ROW(A11)-1), NA() )} -> #REF! | H49: {=IF( INDEX($H$2:$Z$14, COLUMN(B11), 2*ROW(B11)-1)>0, INDEX($H$2:$Z$14, COLUMN(B11), 2*ROW(B11)-1), NA() )} -> #REF! | I49: {=IF( INDEX($H$2:$Z$14, COLUMN(C11), 2*ROW(C11)-1)>0, INDEX($H$2:$Z$14, COLUMN(C11), 2*ROW(C11)-1), NA() )} -> #REF! | J49: {=IF( INDEX($H$2:$Z$14, COLUMN(D11), 2*ROW(D11)-1)>0, INDEX($H$2:$Z$14, COLUMN(D11), 2*ROW(D11)-1), NA() )} -> #REF! | K49: {=IF( INDEX($H$2:$Z$14, COLUMN(E11), 2*ROW(E11)-1)>0, INDEX($H$2:$Z$14, COLUMN(E11), 2*ROW(E11)-1), NA() )} -> #REF! | L49: {=IF( INDEX($H$2:$Z$14, COLUMN(F11), 2*ROW(F11)-1)>0, INDEX($H$2:$Z$14, COLUMN(F11), 2*ROW(F11)-1), NA() )} -> #REF! | M49: {=IF( INDEX($H$2:$Z$14, COLUMN(G11), 2*ROW(G11)-1)>0, INDEX($H$2:$Z$14, COLUMN(G11), 2*ROW(G11)-1), NA() )} -> #REF! | N49: {=IF( INDEX($H$2:$Z$14, COLUMN(H11), 2*ROW(H11)-1)>0, INDEX($H$2:$Z$14, COLUMN(H11), 2*ROW(H11)-1), NA() )} -> #REF! | ... S49: {=IF( INDEX($H$2:$Z$14, COLUMN(M11), 2*ROW(M11)-1)>0, INDEX($H$2:$Z$14, COLUMN(M11), 2*ROW(M11)-1), NA() )} -> #REF! | T49: 19h00 | U49: =AP2 -> 0 | V49: =AP3 -> 0 | W49: =AP4 -> 0 | X49: =AP5 -> 0 | Y49: =AP6 -> 0 | Z49: =AP7 -> 0 | AA49: =AP8 -> 0 | AB49: =AP9 -> 0 | AC49: =AP10 -> 0 | AD49: =AP11 -> 0 | AE49: =AP12 -> 0 | AF49: =AP13 -> 0 | AG49: =AP14 -> 0
F50: 20h00 | G50: {=IF( INDEX($H$2:$Z$14, COLUMN(A12), 2*ROW(A12)-1)>0, INDEX($H$2:$Z$14, COLUMN(A12), 2*ROW(A12)-1), NA() )} -> #REF! | H50: {=IF( INDEX($H$2:$Z$14, COLUMN(B12), 2*ROW(B12)-1)>0, INDEX($H$2:$Z$14, COLUMN(B12), 2*ROW(B12)-1), NA() )} -> #REF! | I50: {=IF( INDEX($H$2:$Z$14, COLUMN(C12), 2*ROW(C12)-1)>0, INDEX($H$2:$Z$14, COLUMN(C12), 2*ROW(C12)-1), NA() )} -> #REF! | J50: {=IF( INDEX($H$2:$Z$14, COLUMN(D12), 2*ROW(D12)-1)>0, INDEX($H$2:$Z$14, COLUMN(D12), 2*ROW(D12)-1), NA() )} -> #REF! | K50: {=IF( INDEX($H$2:$Z$14, COLUMN(E12), 2*ROW(E12)-1)>0, INDEX($H$2:$Z$14, COLUMN(E12), 2*ROW(E12)-1), NA() )} -> #REF! | L50: {=IF( INDEX($H$2:$Z$14, COLUMN(F12), 2*ROW(F12)-1)>0, INDEX($H$2:$Z$14, COLUMN(F12), 2*ROW(F12)-1), NA() )} -> #REF! | M50: {=IF( INDEX($H$2:$Z$14, COLUMN(G12), 2*ROW(G12)-1)>0, INDEX($H$2:$Z$14, COLUMN(G12), 2*ROW(G12)-1), NA() )} -> #REF! | N50: {=IF( INDEX($H$2:$Z$14, COLUMN(H12), 2*ROW(H12)-1)>0, INDEX($H$2:$Z$14, COLUMN(H12), 2*ROW(H12)-1), NA() )} -> #REF! | ... S50: {=IF( INDEX($H$2:$Z$14, COLUMN(M12), 2*ROW(M12)-1)>0, INDEX($H$2:$Z$14, COLUMN(M12), 2*ROW(M12)-1), NA() )} -> #REF! | T50: 20h00 | U50: =AQ2 -> 0 | V50: =AQ3 -> 0 | W50: =AQ4 -> 0 | X50: =AQ5 -> 0 | Y50: =AQ6 -> 0 | Z50: =AQ7 -> 0 | AA50: =AQ8 -> 0 | AB50: =AQ9 -> 0 | AC50: =AQ10 -> 0 | AD50: =AQ11 -> 0 | AE50: =AQ12 -> 0 | AF50: =AQ13 -> 0 | AG50: =AQ14 -> 0
G52: Tour actuel
F53: Heure | G53: Bureau 1 | H53: Bureau 2 | I53: Bureau 3 | J53: Bureau 4 | K53: Bureau 5 | L53: Bureau 6 | M53: Bureau 7 | N53: Bureau 8 | O53: Bureau 9 | P53: Bureau 10 | Q53: Bureau 11 | R53: Bureau 12 | S53: Total
F54: 8h-9h | G54: =INDIRECT("'Bureau 1'!" & ADDRESS(ROW()-50,Synthèse!$G$40+14,4)) -> 33 | H54: =INDIRECT("'Bureau 2'!" & ADDRESS(ROW()-50,Synthèse!$G$40+14,4)) -> 45 | I54: =INDIRECT("'Bureau 3'!" & ADDRESS(ROW()-50,Synthèse!$G$40+14,4)) -> 40 | J54: =INDIRECT("'Bureau 4'!" & ADDRESS(ROW()-50,Synthèse!$G$40+14,4)) -> 33 | K54: =INDIRECT("'Bureau 5'!" & ADDRESS(ROW()-50,Synthèse!$G$40+14,4)) -> 37 | L54: =INDIRECT("'Bureau 6'!" & ADDRESS(ROW()-50,Synthèse!$G$40+14,4)) -> 30 | M54: =INDIRECT("'Bureau 7'!" & ADDRESS(ROW()-50,Synthèse!$G$40+14,4)) -> 20 | N54: =INDIRECT("'Bureau 8'!" & ADDRESS(ROW()-50,Synthèse!$G$40+14,4)) -> 36 | O54: =INDIRECT("'Bureau 9'!" & ADDRESS(ROW()-50,Synthèse!$G$40+14,4)) -> 22 | P54: =INDIRECT("'Bureau 10'!" & ADDRESS(ROW()-50,Synthèse!$G$40+14,4)) -> 27 | Q54: =INDIRECT("'Bureau 11'!" & ADDRESS(ROW()-50,Synthèse!$G$40+14,4)) -> 47 | R54: =INDIRECT("'Bureau 12'!" & ADDRESS(ROW()-50,Synthèse!$G$40+14,4)) -> 24 | S54: =SUMIF(G54:R54, "<>#N/A") -> 394
F55: 9h-10h | G55: =INDIRECT("'Bureau 1'!" & ADDRESS(ROW()-50,Synthèse!$G$40+14,4)) -> 45 | H55: =INDIRECT("'Bureau 2'!" & ADDRESS(ROW()-50,Synthèse!$G$40+14,4)) -> 35 | I55: =INDIRECT("'Bureau 3'!" & ADDRESS(ROW()-50,Synthèse!$G$40+14,4)) -> 70 | J55: =INDIRECT("'Bureau 4'!" & ADDRESS(ROW()-50,Synthèse!$G$40+14,4)) -> 35 | K55: =INDIRECT("'Bureau 5'!" & ADDRESS(ROW()-50,Synthèse!$G$40+14,4)) -> 56 | L55: =INDIRECT("'Bureau 6'!" & ADDRESS(ROW()-50,Synthèse!$G$40+14,4)) -> 59 | M55: =INDIRECT("'Bureau 7'!" & ADDRESS(ROW()-50,Synthèse!$G$40+14,4)) -> 55 | N55: =INDIRECT("'Bureau 8'!" & ADDRESS(ROW()-50,Synthèse!$G$40+14,4)) -> 36 | O55: =INDIRECT("'Bureau 9'!" & ADDRESS(ROW()-50,Synthèse!$G$40+14,4)) -> 37 | P55: =INDIRECT("'Bureau 10'!" & ADDRESS(ROW()-50,Synthèse!$G$40+14,4)) -> 43 | Q55: =INDIRECT("'Bureau 11'!" & ADDRESS(ROW()-50,Synthèse!$G$40+14,4)) -> 49 | R55: =INDIRECT("'Bureau 12'!" & ADDRESS(ROW()-50,Synthèse!$G$40+14,4)) -> 25 | S55: =SUMIF(G55:R55, "<>#N/A") -> 545
F56: 10h-11h | G56: =INDIRECT("'Bureau 1'!" & ADDRESS(ROW()-50,Synthèse!$G$40+14,4)) -> 52 | H56: =INDIRECT("'Bureau 2'!" & ADDRESS(ROW()-50,Synthèse!$G$40+14,4)) -> 60 | I56: =INDIRECT("'Bureau 3'!" & ADDRESS(ROW()-50,Synthèse!$G$40+14,4)) -> 80 | J56: =INDIRECT("'Bureau 4'!" & ADDRESS(ROW()-50,Synthèse!$G$40+14,4)) -> 70 | K56: =INDIRECT("'Bureau 5'!" & ADDRESS(ROW()-50,Synthèse!$G$40+14,4)) -> 67 | L56: =INDIRECT("'Bureau 6'!" & ADDRESS(ROW()-50,Synthèse!$G$40+14,4)) -> 51 | M56: =INDIRECT("'Bureau 7'!" & ADDRESS(ROW()-50,Synthèse!$G$40+14,4)) -> 75 | N56: =INDIRECT("'Bureau 8'!" & ADDRESS(ROW()-50,Synthèse!$G$40+14,4)) -> 77 | O56: =INDIRECT("'Bureau 9'!" & ADDRESS(ROW()-50,Synthèse!$G$40+14,4)) -> 46 | P56: =INDIRECT("'Bureau 10'!" & ADDRESS(ROW()-50,Synthèse!$G$40+14,4)) -> 70 | Q56: =INDIRECT("'Bureau 11'!" & ADDRESS(ROW()-50,Synthèse!$G$40+14,4)) -> 62 | R56: =INDIRECT("'Bureau 12'!" & ADDRESS(ROW()-50,Synthèse!$G$40+14,4)) -> 47 | S56: =SUMIF(G56:R56, "<>#N/A") -> 757
...

Sheet Projection
H2: 1 | I2: 2 | J2: 3 | K2: 4 | L2: 5 | M2: 6 | N2: 7
E3: Bureaux | G3: Inscrits | H3: =Synthèse!L$2 -> Mme Christiane LARDAT | I3: =Synthèse!M$2 -> M. Francis LAPRADE | J3: =Synthèse!N$2 -> M. Pierre-Yves TIERCE | K3: =Synthèse!O$2 -> M. Philippe VALLET | L3: =Synthèse!P$2 -> Mme Isabelle FARNET RISSO | M3: =Synthèse!Q$2 -> Mme Véronique LANSADE | N3: =Synthèse!R$2 -> M. Pascal CORDÉ | O3: Blancs | P3: Nuls | Q3: Total dépouillé | Z3: Bureaux | AB3: Inscrits | AC3: Votants
B4: Date | C4: =Synthèse!$B$17 -> 46096 | E4: 1 | F4: {=INDIRECT("'Synthèse'!$B" & ROW()-1)} -> Ecole Chabaud | G4: =Synthèse!C3 -> 553 | H4: =Synthèse!L3 -> 31 | I4: =Synthèse!M3 -> 6 | J4: =Synthèse!N3 -> 112 | K4: =Synthèse!O3 -> 36 | L4: =Synthèse!P3 -> 94 | M4: =Synthèse!Q3 -> 10 | N4: =Synthèse!R3 -> 22 | O4: =Synthèse!G3 -> 8 | P4: =Synthèse!H3 -> 4 | Q4: {=SUM(IFERROR(H4:P4,0))} -> 323 | Z4: 1 | AA4: =Synthèse!$B3 -> Ecole Chabaud | AB4: =Synthèse!$C3 -> 553 | AC4: =Synthèse!$E3 -> 323 | AD4: =$AC4/$AB4 -> 0.5840868 | AE4: =$AC4/$AB4 -> 0.5840868 | AH4: Date | AI4: =Synthèse!$B$17 -> 46096
B5: Election | C5: =Synthèse!$B$18 -> Municipales 1er tour | E5: 2 | F5: {=INDIRECT("'Synthèse'!$B" & ROW()-1)} -> Gymnase B | G5: =Synthèse!C4 -> 740 | H5: =Synthèse!L4 -> 29 | I5: =Synthèse!M4 -> 19 | J5: =Synthèse!N4 -> 129 | K5: =Synthèse!O4 -> 78 | L5: =Synthèse!P4 -> 137 | M5: =Synthèse!Q4 -> 20 | N5: =Synthèse!R4 -> 10 | O5: =Synthèse!G4 -> 9 | P5: =Synthèse!H4 -> 12 | Q5: {=SUM(IFERROR(H5:P5,0))} -> 443 | Z5: 2 | AA5: =Synthèse!$B4 -> Gymnase B | AB5: =Synthèse!$C4 -> 740 | AC5: =Synthèse!$E4 -> 443 | AD5: =$AC5/$AB5 -> 0.59864865 | AE5: =$AC5/$AB5 -> 0.59864865 | AH5: Election | AI5: =Synthèse!$B$18 -> Municipales 1er tour
B6: Ville | C6: =Synthèse!$B$19 -> Cogolin | E6: 3 | F6: {=INDIRECT("'Synthèse'!$B" & ROW()-1)} -> Gymnase B | G6: =Synthèse!C5 -> 713 | H6: =Synthèse!L5 -> 37 | I6: =Synthèse!M5 -> 9 | J6: =Synthèse!N5 -> 137 | K6: =Synthèse!O5 -> 76 | L6: =Synthèse!P5 -> 188 | M6: =Synthèse!Q5 -> 10 | N6: =Synthèse!R5 -> 8 | O6: =Synthèse!G5 -> 11 | P6: =Synthèse!H5 -> 8 | Q6: {=SUM(IFERROR(H6:P6,0))} -> 484 | Z6: 3 | AA6: =Synthèse!$B5 -> Gymnase B | AB6: =Synthèse!$C5 -> 713 | AC6: =Synthèse!$E5 -> 484 | AD6: =$AC6/$AB6 -> 0.67882188 | AE6: =$AC6/$AB6 -> 0.67882188 | AH6: Ville | AI6: =Synthèse!$B$19 -> Cogolin
E7: 4 | F7: {=INDIRECT("'Synthèse'!$B" & ROW()-1)} -> Gymnase B | G7: =Synthèse!C6 -> 679 | H7: =Synthèse!L6 -> 28 | I7: =Synthèse!M6 -> 15 | J7: =Synthèse!N6 -> 81 | K7: =Synthèse!O6 -> 61 | L7: =Synthèse!P6 -> 135 | M7: =Synthèse!Q6 -> 15 | N7: =Synthèse!R6 -> 14 | O7: =Synthèse!G6 -> 4 | P7: =Synthèse!H6 -> 10 | Q7: {=SUM(IFERROR(H7:P7,0))} -> 363 | Z7: 4 | AA7: =Synthèse!$B6 -> Gymnase B | AB7: =Synthèse!$C6 -> 679 | AC7: =Synthèse!$E6 -> 363 | AD7: =$AC7/$AB7 -> 0.53460972 | AE7: =$AC7/$AB7 -> 0.53460972
