Workbook
Name CalculSieges: Sièges!$E$1:$O$3
Name exTable3: #REF!
Name PfmCC: Sièges!$G$20
Name PfmCM: Sièges!$G$19
Name PmCC: Sièges!$F$20
Name PmCM: Sièges!$F$19
Name Table1: 'Bureau 1'!$D$49:$H$59
Name Table1: 'Bureau 10'!$D$49:$H$59
Name Table1: 'Bureau 11'!$D$49:$H$59
Name Table1: 'Bureau 12'!$D$49:$H$59
Name Table1: 'Bureau 2'!$D$49:$H$59
Name Table1: 'Bureau 3'!$D$49:$H$59
Name Table1: 'Bureau 4'!$D$49:$H$59
Name Table1: 'Bureau 5'!$D$49:$H$59
Name Table1: 'Bureau 6'!$D$49:$H$59
Name Table1: 'Bureau 7'!$D$49:$H$59
Name Table1: 'Bureau 8'!$D$49:$H$59
Name Table1: 'Bureau 9'!$D$49:$H$59
Name Table1: 'Feuille décompte'!$A$6:$E$15
Name Table1: #REF!
Name Table1bis: 'Feuille décompte'!$A$24:$E$28
Name Table2: 'Bureau 1'!$D$67:$H$72
Name Table2: 'Bureau 10'!$D$67:$H$72
Name Table2: 'Bureau 11'!$D$67:$H$72
Name Table2: 'Bureau 12'!$D$67:$H$72
Name Table2: 'Bureau 2'!$D$67:$H$72
Name Table2: 'Bureau 3'!$D$67:$H$72
Name Table2: 'Bureau 4'!$D$67:$H$72
Name Table2: 'Bureau 5'!$D$67:$H$72
Name Table2: 'Bureau 6'!$D$67:$H$72
Name Table2: 'Bureau 7'!$D$67:$H$72
Name Table2: 'Bureau 8'!$D$67:$H$72
Name Table2: 'Bureau 9'!$D$67:$H$72
Name Table2: 'Feuille décompte'!#REF!
Name Table2: #REF!
Name Table3: 'Bureau 1'!$D$78:$H$80
Name Table3: 'Bureau 10'!$D$78:$H$80
Name Table3: 'Bureau 11'!$D$78:$H$80
Name Table3: 'Bureau 12'!$D$78:$H$80
Name Table3: 'Bureau 2'!$D$78:$H$80
Name Table3: 'Bureau 3'!$D$78:$H$80
Name Table3: 'Bureau 4'!$D$78:$H$80
Name Table3: 'Bureau 5'!$D$78:$H$80
Name Table3: 'Bureau 6'!$D$78:$H$80
Name Table3: 'Bureau 7'!$D$78:$H$80
Name Table3: 'Bureau 8'!$D$78:$H$80
Name Table3: 'Bureau 9'!$D$78:$H$80
Name Table3: 'Feuille décompte'!#REF!
Name Table3: #REF!
Name TableauAges: Sièges!$Y$3:$AD$38
Name TableDepouillement1: #REF!
Name TableDepouillement1bis: #REF!
Name VoixEligibles: Sièges!$F$14:$F$15

Sheet Synthèse
L1: 1 | M1: 2 | N1: Vérification
A2: N° | B2: Nom | C2: Inscrits | D2: Emargements | E2: Votants | F2: Abstention | G2: Nuls | H2: Blancs | I2: Exprimés | J2: Participation | K2: Abstention (%) | L2: M. Pierre-Yves TIERCE | M2: Mme Isabelle FARNET RISSO | N2: Total exprimé
A3: 1 | B3: Ecole Chabaud | C3: 554 | D3: {=INDIRECT("'Bureau " & ROW()-2 & "'!$B$9")} -> 316 | E3: {=INDIRECT("'Bureau " & ROW()-2 & "'!$B$8")} -> 316 | F3: =C3-E3 -> 238 | G3: =INDEX(INDIRECT("'Bureau "&(ROW()-2)&"'!13:13"),1,MATCH("Nuls",INDIRECT("'Bureau "&(ROW()-2)&"'!2:2"),0)) -> 8 | H3: =INDEX(INDIRECT("'Bureau "&(ROW()-2)&"'!13:13"),1,MATCH("Blancs",INDIRECT("'Bureau "&(ROW()-2)&"'!2:2"),0)) -> 4 | I3: =E3-H3-G3 -> 304 | J3: =E3/C3 -> 0.57039711 | K3: =F3/C3 -> 0.42960289 | L3: {=INDIRECT("'Bureau " & ROW()-2 & "'!" & ADDRESS(13,COLUMN()-7,4))} -> 148 | M3: {=INDIRECT("'Bureau " & ROW()-2 & "'!" & ADDRESS(13,COLUMN()-7,4))} -> 156 | N3: {=SUM(IFERROR(L3:M3,0))} -> 304
A4: 2 | B4: Gymnase B | C4: 740 | D4: {=INDIRECT("'Bureau " & ROW()-2 & "'!$B$9")} -> 433 | E4: {=INDIRECT("'Bureau " & ROW()-2 & "'!$B$8")} -> 433 | F4: =C4-E4 -> 307 | G4: =INDEX(INDIRECT("'Bureau "&(ROW()-2)&"'!13:13"),1,MATCH("Nuls",INDIRECT("'Bureau "&(ROW()-2)&"'!2:2"),0)) -> 10 | H4: =INDEX(INDIRECT("'Bureau "&(ROW()-2)&"'!13:13"),1,MATCH("Blancs",INDIRECT("'Bureau "&(ROW()-2)&"'!2:2"),0)) -> 9 | I4: =E4-H4-G4 -> 414 | J4: =E4/C4 -> 0.58513514 | K4: =F4/C4 -> 0.41486486 | L4: {=INDIRECT("'Bureau " & ROW()-2 & "'!" & ADDRESS(13,COLUMN()-7,4))} -> 197 | M4: {=INDIRECT("'Bureau " & ROW()-2 & "'!" & ADDRESS(13,COLUMN()-7,4))} -> 217 | N4: {=SUM(IFERROR(L4:M4,0))} -> 414
A5: 3 | B5: Gymnase B | C5: 714 | D5: {=INDIRECT("'Bureau " & ROW()-2 & "'!$B$9")} -> 480 | E5: {=INDIRECT("'Bureau " & ROW()-2 & "'!$B$8")} -> 480 | F5: =C5-E5 -> 234 | G5: =INDEX(INDIRECT("'Bureau "&(ROW()-2)&"'!13:13"),1,MATCH("Nuls",INDIRECT("'Bureau "&(ROW()-2)&"'!2:2"),0)) -> 3 | H5: =INDEX(INDIRECT("'Bureau "&(ROW()-2)&"'!13:13"),1,MATCH("Blancs",INDIRECT("'Bureau "&(ROW()-2)&"'!2:2"),0)) -> 6 | I5: =E5-H5-G5 -> 471 | J5: =E5/C5 -> 0.67226891 | K5: =F5/C5 -> 0.32773109 | L5: {=INDIRECT("'Bureau " & ROW()-2 & "'!" & ADDRESS(13,COLUMN()-7,4))} -> 206 | M5: {=INDIRECT("'Bureau " & ROW()-2 & "'!" & ADDRESS(13,COLUMN()-7,4))} -> 265 | N5: {=SUM(IFERROR(L5:M5,0))} -> 471
A6: 4 | B6: Gymnase B | C6: 679 | D6: {=INDIRECT("'Bureau " & ROW()-2 & "'!$B$9")} -> 382 | E6: {=INDIRECT("'Bureau " & ROW()-2 & "'!$B$8")} -> 382 | F6: =C6-E6 -> 297 | G6: =INDEX(INDIRECT("'Bureau "&(ROW()-2)&"'!13:13"),1,MATCH("Nuls",INDIRECT("'Bureau "&(ROW()-2)&"'!2:2"),0)) -> 5 | H6: =INDEX(INDIRECT("'Bureau "&(ROW()-2)&"'!13:13"),1,MATCH("Blancs",INDIRECT("'Bureau "&(ROW()-2)&"'!2:2"),0)) -> 8 | I6: =E6-H6-G6 -> 369 | J6: =E6/C6 -> 0.56259205 | K6: =F6/C6 -> 0.43740795 | L6: {=INDIRECT("'Bureau " & ROW()-2 & "'!" & ADDRESS(13,COLUMN()-7,4))} -> 147 | M6: {=INDIRECT("'Bureau " & ROW()-2 & "'!" & ADDRESS(13,COLUMN()-7,4))} -> 222 | N6: {=SUM(IFERROR(L6:M6,0))} -> 369
A7: 5 | B7: COSEC | C7: 701 | D7: {=INDIRECT("'Bureau " & ROW()-2 & "'!$B$9")} -> 475 | E7: {=INDIRECT("'Bureau " & ROW()-2 & "'!$B$8")} -> 475 | F7: =C7-E7 -> 226 | G7: =INDEX(INDIRECT("'Bureau "&(ROW()-2)&"'!13:13"),1,MATCH("Nuls",INDIRECT("'Bureau "&(ROW()-2)&"'!2:2"),0)) -> 10 | H7: =INDEX(INDIRECT("'Bureau "&(ROW()-2)&"'!13:13"),1,MATCH("Blancs",INDIRECT("'Bureau "&(ROW()-2)&"'!2:2"),0)) -> 10 | I7: =E7-H7-G7 -> 455 | J7: =E7/C7 -> 0.67760342 | K7: =F7/C7 -> 0.32239658 | L7: {=INDIRECT("'Bureau " & ROW()-2 & "'!" & ADDRESS(13,COLUMN()-7,4))} -> 204 | M7: {=INDIRECT("'Bureau " & ROW()-2 & "'!" & ADDRESS(13,COLUMN()-7,4))} -> 251 | N7: {=SUM(IFERROR(L7:M7,0))} -> 455
A8: 6 | B8: COSEC | C8: 710 | D8: {=INDIRECT("'Bureau " & ROW()-2 & "'!$B$9")} -> 380 | E8: {=INDIRECT("'Bureau " & ROW()-2 & "'!$B$8")} -> 380 | F8: =C8-E8 -> 330 | G8: =INDEX(INDIRECT("'Bureau "&(ROW()-2)&"'!13:13"),1,MATCH("Nuls",INDIRECT("'Bureau "&(ROW()-2)&"'!2:2"),0)) -> 2 | H8: =INDEX(INDIRECT("'Bureau "&(ROW()-2)&"'!13:13"),1,MATCH("Blancs",INDIRECT("'Bureau "&(ROW()-2)&"'!2:2"),0)) -> 12 | I8: =E8-H8-G8 -> 366 | J8: =E8/C8 -> 0.53521127 | K8: =F8/C8 -> 0.46478873 | L8: {=INDIRECT("'Bureau " & ROW()-2 & "'!" & ADDRESS(13,COLUMN()-7,4))} -> 161 | M8: {=INDIRECT("'Bureau " & ROW()-2 & "'!" & ADDRESS(13,COLUMN()-7,4))} -> 205 | N8: {=SUM(IFERROR(L8:M8,0))} -> 366
A9: 7 | B9: COSEC | C9: 731 | D9: {=INDIRECT("'Bureau " & ROW()-2 & "'!$B$9")} -> 430 | E9: {=INDIRECT("'Bureau " & ROW()-2 & "'!$B$8")} -> 430 | F9: =C9-E9 -> 301 | G9: =INDEX(INDIRECT("'Bureau "&(ROW()-2)&"'!13:13"),1,MATCH("Nuls",INDIRECT("'Bureau "&(ROW()-2)&"'!2:2"),0)) -> 4 | H9: =INDEX(INDIRECT("'Bureau "&(ROW()-2)&"'!13:13"),1,MATCH("Blancs",INDIRECT("'Bureau "&(ROW()-2)&"'!2:2"),0)) -> 11 | I9: =E9-H9-G9 -> 415 | J9: =E9/C9 -> 0.58823529 | K9: =F9/C9 -> 0.41176471 | L9: {=INDIRECT("'Bureau " & ROW()-2 & "'!" & ADDRESS(13,COLUMN()-7,4))} -> 172 | M9: {=INDIRECT("'Bureau " & ROW()-2 & "'!" & ADDRESS(13,COLUMN()-7,4))} -> 243 | N9: {=SUM(IFERROR(L9:M9,0))} -> 415
A10: 8 | B10: COSEC | C10: 645 | D10: {=INDIRECT("'Bureau " & ROW()-2 & "'!$B$9")} -> 362 | E10: {=INDIRECT("'Bureau " & ROW()-2 & "'!$B$8")} -> 362 | F10: =C10-E10 -> 283 | G10: =INDEX(INDIRECT("'Bureau "&(ROW()-2)&"'!13:13"),1,MATCH("Nuls",INDIRECT("'Bureau "&(ROW()-2)&"'!2:2"),0)) -> 4 | H10: =INDEX(INDIRECT("'Bureau "&(ROW()-2)&"'!13:13"),1,MATCH("Blancs",INDIRECT("'Bureau "&(ROW()-2)&"'!2:2"),0)) -> 9 | I10: =E10-H10-G10 -> 349 | J10: =E10/C10 -> 0.56124031 | K10: =F10/C10 -> 0.43875969 | L10: {=INDIRECT("'Bureau " & ROW()-2 & "'!" & ADDRESS(13,COLUMN()-7,4))} -> 149 | M10: {=INDIRECT("'Bureau " & ROW()-2 & "'!" & ADDRESS(13,COLUMN()-7,4))} -> 200 | N10: {=SUM(IFERROR(L10:M10,0))} -> 349
A11: 9 | B11: CMM | C11: 710 | D11: {=INDIRECT("'Bureau " & ROW()-2 & "'!$B$9")} -> 331 | E11: {=INDIRECT("'Bureau " & ROW()-2 & "'!$B$8")} -> 331 | F11: =C11-E11 -> 379 | G11: =INDEX(INDIRECT("'Bureau "&(ROW()-2)&"'!13:13"),1,MATCH("Nuls",INDIRECT("'Bureau "&(ROW()-2)&"'!2:2"),0)) -> 11 | H11: =INDEX(INDIRECT("'Bureau "&(ROW()-2)&"'!13:13"),1,MATCH("Blancs",INDIRECT("'Bureau "&(ROW()-2)&"'!2:2"),0)) -> 6 | I11: =E11-H11-G11 -> 314 | J11: =E11/C11 -> 0.46619718 | K11: =F11/C11 -> 0.53380282 | L11: {=INDIRECT("'Bureau " & ROW()-2 & "'!" & ADDRESS(13,COLUMN()-7,4))} -> 144 | M11: {=INDIRECT("'Bureau " & ROW()-2 & "'!" & ADDRESS(13,COLUMN()-7,4))} -> 170 | N11: {=SUM(IFERROR(L11:M11,0))} -> 314
A12: 10 | B12: CMM | C12: 609 | D12: {=INDIRECT("'Bureau " & ROW()-2 & "'!$B$9")} -> 357 | E12: {=INDIRECT("'Bureau " & ROW()-2 & "'!$B$8")} -> 357 | F12: =C12-E12 -> 252 | G12: =INDEX(INDIRECT("'Bureau "&(ROW()-2)&"'!13:13"),1,MATCH("Nuls",INDIRECT("'Bureau "&(ROW()-2)&"'!2:2"),0)) -> 7 | H12: =INDEX(INDIRECT("'Bureau "&(ROW()-2)&"'!13:13"),1,MATCH("Blancs",INDIRECT("'Bureau "&(ROW()-2)&"'!2:2"),0)) -> 7 | I12: =E12-H12-G12 -> 343 | J12: =E12/C12 -> 0.5862069 | K12: =F12/C12 -> 0.4137931 | L12: {=INDIRECT("'Bureau " & ROW()-2 & "'!" & ADDRESS(13,COLUMN()-7,4))} -> 175 | M12: {=INDIRECT("'Bureau " & ROW()-2 & "'!" & ADDRESS(13,COLUMN()-7,4))} -> 168 | N12: {=SUM(IFERROR(L12:M12,0))} -> 343
A13: 11 | B13: CMM | C13: 691 | D13: {=INDIRECT("'Bureau " & ROW()-2 & "'!$B$9")} -> 405 | E13: {=INDIRECT("'Bureau " & ROW()-2 & "'!$B$8")} -> 405 | F13: =C13-E13 -> 286 | G13: =INDEX(INDIRECT("'Bureau "&(ROW()-2)&"'!13:13"),1,MATCH("Nuls",INDIRECT("'Bureau "&(ROW()-2)&"'!2:2"),0)) -> 8 | H13: =INDEX(INDIRECT("'Bureau "&(ROW()-2)&"'!13:13"),1,MATCH("Blancs",INDIRECT("'Bureau "&(ROW()-2)&"'!2:2"),0)) -> 13 | I13: =E13-H13-G13 -> 384 | J13: =E13/C13 -> 0.58610709 | K13: =F13/C13 -> 0.41389291 | L13: {=INDIRECT("'Bureau " & ROW()-2 & "'!" & ADDRESS(13,COLUMN()-7,4))} -> 210 | M13: {=INDIRECT("'Bureau " & ROW()-2 & "'!" & ADDRESS(13,COLUMN()-7,4))} -> 174 | N13: {=SUM(IFERROR(L13:M13,0))} -> 384
A14: 12 | B14: Base nautique | C14: 681 | D14: {=INDIRECT("'Bureau " & ROW()-2 & "'!$B$9")} -> 300 | E14: {=INDIRECT("'Bureau " & ROW()-2 & "'!$B$8")} -> 300 | F14: =C14-E14 -> 381 | G14: =INDEX(INDIRECT("'Bureau "&(ROW()-2)&"'!13:13"),1,MATCH("Nuls",INDIRECT("'Bureau "&(ROW()-2)&"'!2:2"),0)) -> 6 | H14: =INDEX(INDIRECT("'Bureau "&(ROW()-2)&"'!13:13"),1,MATCH("Blancs",INDIRECT("'Bureau "&(ROW()-2)&"'!2:2"),0)) -> 6 | I14: =E14-H14-G14 -> 288 | J14: =E14/C14 -> 0.44052863 | K14: =F14/C14 -> 0.55947137 | L14: {=INDIRECT("'Bureau " & ROW()-2 & "'!" & ADDRESS(13,COLUMN()-7,4))} -> 154 | M14: {=INDIRECT("'Bureau " & ROW()-2 & "'!" & ADDRESS(13,COLUMN()-7,4))} -> 134 | N14: {=SUM(IFERROR(L14:M14,0))} -> 288
B15: TOTAL | C15: {=SUM(IFERROR(C3:C14,0))} -> 8165 | D15: {=SUM(IFERROR(D3:D14,0))} -> 4651 | E15: {=SUM(IFERROR(E3:E14,0))} -> 4651 | F15: {=SUM(IFERROR(F3:F14,0))} -> 3514 | G15: {=SUM(IFERROR(G3:G14,0))} -> 78 | H15: {=SUM(IFERROR(H3:H14,0))} -> 101 | I15: {=SUM(IFERROR(I3:I14,0))} -> 4472 | J15: =E15 -> 4651 | K15: {=SUM(IFERROR(F3:F14,0))} -> 3514 | L15: {=SUM(IFERROR(L3:L14,0))} -> 2067 | M15: {=SUM(IFERROR(M3:M14,0))} -> 2405 | N15: {=SUM(IFERROR(N3:N14,0))} -> 4472
B16: % | D16: =D15/$C15 -> 0.56962645 | E16: =E15/$C15 -> 0.56962645 | F16: =F15/$C15 -> 0.43037355 | G16: =IFERROR(G15/$E15,0) -> 0.016770587 | H16: =IFERROR(H15/$E15,0) -> 0.02171576 | I16: =I15/$C15 -> 0.54770361 | J16: =J15/$C15 -> 0.56962645 | K16: =K15/$C15 -> 0.43037355 | L16: =IFERROR(L15/$I15,0) -> 0.4622093 | M16: =IFERROR(M15/$I15,0) -> 0.5377907 | N16: =IFERROR(N15/$I15,0) -> 1 | O16: % exprimés
A17: Date | B17: 46103 | D17: % d'inscrits | G17: % de votants | I17: % d'inscrits | L17: =L15/$C$15 -> 0.2531537 | M17: =M15/$C$15 -> 0.29454991 | N17: =N15/$C$15 -> 0.54770361 | O17: % d'inscrits
A18: Election | B18: Municipale
A19: Tour | B19: 2
A20: Ville | B20: Cogolin
F35: Seuil 0 | G35: 0.5
F36: Seuil 1
F37: Seuil 2
F38: Seuil 3 | G38: top 1
F40: Nb Candidats | G40: =MATCH("Total exprimé",2:2,0)-12 -> 2
F41: Nb Bureaux | G41: =MATCH("TOTAL",B:B,0)-3 -> 12

Sheet Participation horaire
A1: Bureaux | C1: Votants | F1: Inscrits | G1: 09h00 | I1: 10h00 | K1: 11h00 | M1: 12h00 | O1: 13h00 | Q1: 14h00 | S1: 15h00 | U1: 16h00 | W1: 17h00 | Y1: 18h00 | AA1: 19h00 | AC1: 20h00 | AE1: Bureaux | AF1: 09h00 | AG1: 10h00 | AH1: 11h00 | AI1: 12h00 | AJ1: 13h00 | AK1: 14h00 | AL1: 15h00 | AM1: 16h00 | AN1: 17h00 | AO1: 18h00 | AP1: 19h00 | AQ1: 20h00
A2: 1 | B2: =Synthèse!B3 -> Ecole Chabaud | C2: =MAX(G2,I2,K2,M2,O2,Q2,S2,U2,W2,Y2,AA2,AC2) -> 316 | D2: =C2/$F2 -> 0.57039711 | E2: =D2 -> 0.57039711 | F2: =Synthèse!C3 -> 554 | G2: =INDIRECT("'Bureau " & ROW()-1 & "'!" & ADDRESS(4,Synthèse!$G$40+10,4)) -> 33 | H2: =G2/$F2 -> 0.059566787 | I2: =INDIRECT("'Bureau " & ROW()-1 & "'!" & ADDRESS(5,Synthèse!$G$40+10,4)) -> 72 | J2: =I2/$F2 -> 0.1299639 | K2: =INDIRECT("'Bureau " & ROW()-1 & "'!" & ADDRESS(6,Synthèse!$G$40+10,4)) -> 123 | L2: =K2/$F2 -> 0.22202166 | M2: =INDIRECT("'Bureau " & ROW()-1 & "'!" & ADDRESS(7,Synthèse!$G$40+10,4)) -> 180 | N2: =M2/$F2 -> 0.32490975 | O2: =INDIRECT("'Bureau " & ROW()-1 & "'!" & ADDRESS(8,Synthèse!$G$40+10,4)) -> 212 | P2: =O2/$F2 -> 0.38267148 | Q2: =INDIRECT("'Bureau " & ROW()-1 & "'!" & ADDRESS(9,Synthèse!$G$40+10,4)) -> 232 | R2: =Q2/$F2 -> 0.41877256 | S2: =INDIRECT("'Bureau " & ROW()-1 & "'!" & ADDRESS(10,Synthèse!$G$40+10,4)) -> 255 | T2: =S2/$F2 -> 0.46028881 | U2: =INDIRECT("'Bureau " & ROW()-1 & "'!" & ADDRESS(11,Synthèse!$G$40+10,4)) -> 279 | V2: =U2/$F2 -> 0.50361011 | W2: =INDIRECT("'Bureau " & ROW()-1 & "'!" & ADDRESS(12,Synthèse!$G$40+10,4)) -> 302 | X2: =W2/$F2 -> 0.54512635 | Y2: =INDIRECT("'Bureau " & ROW()-1 & "'!" & ADDRESS(13,Synthèse!$G$40+10,4)) -> 316 | Z2: =Y2/$F2 -> 0.57039711 | AA2: =INDIRECT("'Bureau " & ROW()-1 & "'!" & ADDRESS(14,Synthèse!$G$40+10,4)) -> 0 | AB2: =AA2/$F2 -> 0 | AC2: =INDIRECT("'Bureau " & ROW()-1 & "'!" & ADDRESS(15,Synthèse!$G$40+10,4)) -> 0 | AD2: =AC2/$F2 -> 0 | AE2: 1 | AF2: 0.059674503 | AG2: 0.14104882 | AH2: 0.23508137 | AI2: 0.3363472 | AJ2: 0.37793852 | AK2: 0.42495479 | AL2: 0.46292948 | AM2: 0.50994575 | AN2: 0.54792043 | AO2: 0.5840868 | AP2: 0 | AQ2: 0
A3: 2 | B3: =Synthèse!B4 -> Gymnase B | C3: =MAX(G3,I3,K3,M3,O3,Q3,S3,U3,W3,Y3,AA3,AC3) -> 433 | D3: =C3/$F3 -> 0.58513514 | E3: =D3 -> 0.58513514 | F3: =Synthèse!C4 -> 740 | G3: =INDIRECT("'Bureau " & ROW()-1 & "'!" & ADDRESS(4,Synthèse!$G$40+10,4)) -> 50 | H3: =G3/$F3 -> 0.067567568 | I3: =INDIRECT("'Bureau " & ROW()-1 & "'!" & ADDRESS(5,Synthèse!$G$40+10,4)) -> 90 | J3: =I3/$F3 -> 0.12162162 | K3: =INDIRECT("'Bureau " & ROW()-1 & "'!" & ADDRESS(6,Synthèse!$G$40+10,4)) -> 170 | L3: =K3/$F3 -> 0.22972973 | M3: =INDIRECT("'Bureau " & ROW()-1 & "'!" & ADDRESS(7,Synthèse!$G$40+10,4)) -> 230 | N3: =M3/$F3 -> 0.31081081 | O3: =INDIRECT("'Bureau " & ROW()-1 & "'!" & ADDRESS(8,Synthèse!$G$40+10,4)) -> 288 | P3: =O3/$F3 -> 0.38918919 | Q3: =INDIRECT("'Bureau " & ROW()-1 & "'!" & ADDRESS(9,Synthèse!$G$40+10,4)) -> 314 | R3: =Q3/$F3 -> 0.42432432 | S3: =INDIRECT("'Bureau " & ROW()-1 & "'!" & ADDRESS(10,Synthèse!$G$40+10,4)) -> 340 | T3: =S3/$F3 -> 0.45945946 | U3: =INDIRECT("'Bureau " & ROW()-1 & "'!" & ADDRESS(11,Synthèse!$G$40+10,4)) -> 370 | V3: =U3/$F3 -> 0.5 | W3: =INDIRECT("'Bureau " & ROW()-1 & "'!" & ADDRESS(12,Synthèse!$G$40+10,4)) -> 402 | X3: =W3/$F3 -> 0.54324324 | Y3: =INDIRECT("'Bureau " & ROW()-1 & "'!" & ADDRESS(13,Synthèse!$G$40+10,4)) -> 433 | Z3: =Y3/$F3 -> 0.58513514 | AA3: =INDIRECT("'Bureau " & ROW()-1 & "'!" & ADDRESS(14,Synthèse!$G$40+10,4)) -> 0 | AB3: =AA3/$F3 -> 0 | AC3: =INDIRECT("'Bureau " & ROW()-1 & "'!" & ADDRESS(15,Synthèse!$G$40+10,4)) -> 0 | AD3: =AC3/$F3 -> 0 | AE3: 2 | AF3: 0.060810811 | AG3: 0.10810811 | AH3: 0.18918919 | AI3: 0.31081081 | AJ3: 0.38918919 | AK3: 0.41891892 | AL3: 0.48648649 | AM3: 0.52702703 | AN3: 0.56081081 | AO3: 0.59864865 | AP3: 0 | AQ3: 0
A4: 3 | B4: =Synthèse!B5 -> Gymnase B | C4: =MAX(G4,I4,K4,M4,O4,Q4,S4,U4,W4,Y4,AA4,AC4) -> 480 | D4: =C4/$F4 -> 0.67226891 | E4: =D4 -> 0.67226891 | F4: =Synthèse!C5 -> 714 | G4: =INDIRECT("'Bureau " & ROW()-1 & "'!" & ADDRESS(4,Synthèse!$G$40+10,4)) -> 50 | H4: =G4/$F4 -> 0.070028011 | I4: =INDIRECT("'Bureau " & ROW()-1 & "'!" & ADDRESS(5,Synthèse!$G$40+10,4)) -> 100 | J4: =I4/$F4 -> 0.14005602 | K4: =INDIRECT("'Bureau " & ROW()-1 & "'!" & ADDRESS(6,Synthèse!$G$40+10,4)) -> 180 | L4: =K4/$F4 -> 0.25210084 | M4: =INDIRECT("'Bureau " & ROW()-1 & "'!" & ADDRESS(7,Synthèse!$G$40+10,4)) -> 260 | N4: =M4/$F4 -> 0.36414566 | O4: =INDIRECT("'Bureau " & ROW()-1 & "'!" & ADDRESS(8,Synthèse!$G$40+10,4)) -> 310 | P4: =O4/$F4 -> 0.43417367 | Q4: =INDIRECT("'Bureau " & ROW()-1 & "'!" & ADDRESS(9,Synthèse!$G$40+10,4)) -> 330 | R4: =Q4/$F4 -> 0.46218487 | S4: =INDIRECT("'Bureau " & ROW()-1 & "'!" & ADDRESS(10,Synthèse!$G$40+10,4)) -> 370 | T4: =S4/$F4 -> 0.51820728 | U4: =INDIRECT("'Bureau " & ROW()-1 & "'!" & ADDRESS(11,Synthèse!$G$40+10,4)) -> 420 | V4: =U4/$F4 -> 0.58823529 | W4: =INDIRECT("'Bureau " & ROW()-1 & "'!" & ADDRESS(12,Synthèse!$G$40+10,4)) -> 460 | X4: =W4/$F4 -> 0.6442577 | Y4: =INDIRECT("'Bureau " & ROW()-1 & "'!" & ADDRESS(13,Synthèse!$G$40+10,4)) -> 480 | Z4: =Y4/$F4 -> 0.67226891 | AA4: =INDIRECT("'Bureau " & ROW()-1 & "'!" & ADDRESS(14,Synthèse!$G$40+10,4)) -> 0 | AB4: =AA4/$F4 -> 0 | AC4: =INDIRECT("'Bureau " & ROW()-1 & "'!" & ADDRESS(15,Synthèse!$G$40+10,4)) -> 0 | AD4: =AC4/$F4 -> 0 | AE4: 3 | AF4: 0.056100982 | AG4: 0.1542777 | AH4: 0.26647966 | AI4: 0.37868163 | AJ4: 0.43478261 | AK4: 0.50490884 | AL4: 0.57503506 | AM4: 0.6171108 | AN4: 0.65918654 | AO4: 0.67882188 | AP4: 0 | AQ4: 0
A5: 4 | B5: =Synthèse!B6 -> Gymnase B | C5: =MAX(G5,I5,K5,M5,O5,Q5,S5,U5,W5,Y5,AA5,AC5) -> 382 | D5: =C5/$F5 -> 0.56259205 | E5: =D5 -> 0.56259205 | F5: =Synthèse!C6 -> 679 | G5: =INDIRECT("'Bureau " & ROW()-1 & "'!" & ADDRESS(4,Synthèse!$G$40+10,4)) -> 44 | H5: =G5/$F5 -> 0.064801178 | I5: =INDIRECT("'Bureau " & ROW()-1 & "'!" & ADDRESS(5,Synthèse!$G$40+10,4)) -> 110 | J5: =I5/$F5 -> 0.16200295 | K5: =INDIRECT("'Bureau " & ROW()-1 & "'!" & ADDRESS(6,Synthèse!$G$40+10,4)) -> 183 | L5: =K5/$F5 -> 0.26951399 | M5: =INDIRECT("'Bureau " & ROW()-1 & "'!" & ADDRESS(7,Synthèse!$G$40+10,4)) -> 220 | N5: =M5/$F5 -> 0.32400589 | O5: =INDIRECT("'Bureau " & ROW()-1 & "'!" & ADDRESS(8,Synthèse!$G$40+10,4)) -> 260 | P5: =O5/$F5 -> 0.38291605 | Q5: =INDIRECT("'Bureau " & ROW()-1 & "'!" & ADDRESS(9,Synthèse!$G$40+10,4)) -> 295 | R5: =Q5/$F5 -> 0.43446244 | S5: =INDIRECT("'Bureau " & ROW()-1 & "'!" & ADDRESS(10,Synthèse!$G$40+10,4)) -> 327 | T5: =S5/$F5 -> 0.48159057 | U5: =INDIRECT("'Bureau " & ROW()-1 & "'!" & ADDRESS(11,Synthèse!$G$40+10,4)) -> 344 | V5: =U5/$F5 -> 0.50662739 | W5: =INDIRECT("'Bureau " & ROW()-1 & "'!" & ADDRESS(12,Synthèse!$G$40+10,4)) -> 367 | X5: =W5/$F5 -> 0.54050074 | Y5: =INDIRECT("'Bureau " & ROW()-1 & "'!" & ADDRESS(13,Synthèse!$G$40+10,4)) -> 382 | Z5: =Y5/$F5 -> 0.56259205 | AA5: =INDIRECT("'Bureau " & ROW()-1 & "'!" & ADDRESS(14,Synthèse!$G$40+10,4)) -> 0 | AB5: =AA5/$F5 -> 0 | AC5: =INDIRECT("'Bureau " & ROW()-1 & "'!" & ADDRESS(15,Synthèse!$G$40+10,4)) -> 0 | AD5: =AC5/$F5 -> 0 | AE5: 4 | AF5: 0.048600884 | AG5: 0.10014728 | AH5: 0.20324006 | AI5: 0.27687776 | AJ5: 0.33284242 | AK5: 0.39175258 | AL5: 0.45066274 | AM5: 0.49484536 | AN5: 0.51693667 | AO5: 0.53460972 | AP5: 0 | AQ5: 0
A6: 5 | B6: =Synthèse!B7 -> COSEC | C6: =MAX(G6,I6,K6,M6,O6,Q6,S6,U6,W6,Y6,AA6,AC6) -> 475 | D6: =C6/$F6 -> 0.67760342 | E6: =D6 -> 0.67760342 | F6: =Synthèse!C7 -> 701 | G6: =INDIRECT("'Bureau " & ROW()-1 & "'!" & ADDRESS(4,Synthèse!$G$40+10,4)) -> 45 | H6: =G6/$F6 -> 0.064194009 | I6: =INDIRECT("'Bureau " & ROW()-1 & "'!" & ADDRESS(5,Synthèse!$G$40+10,4)) -> 110 | J6: =I6/$F6 -> 0.15691869 | K6: =INDIRECT("'Bureau " & ROW()-1 & "'!" & ADDRESS(6,Synthèse!$G$40+10,4)) -> 200 | L6: =K6/$F6 -> 0.2853067 | M6: =INDIRECT("'Bureau " & ROW()-1 & "'!" & ADDRESS(7,Synthèse!$G$40+10,4)) -> 271 | N6: =M6/$F6 -> 0.38659058 | O6: =INDIRECT("'Bureau " & ROW()-1 & "'!" & ADDRESS(8,Synthèse!$G$40+10,4)) -> 331 | P6: =O6/$F6 -> 0.4721826 | Q6: =INDIRECT("'Bureau " & ROW()-1 & "'!" & ADDRESS(9,Synthèse!$G$40+10,4)) -> 355 | R6: =Q6/$F6 -> 0.5064194 | S6: =INDIRECT("'Bureau " & ROW()-1 & "'!" & ADDRESS(10,Synthèse!$G$40+10,4)) -> 390 | T6: =S6/$F6 -> 0.55634807 | U6: =INDIRECT("'Bureau " & ROW()-1 & "'!" & ADDRESS(11,Synthèse!$G$40+10,4)) -> 420 | V6: =U6/$F6 -> 0.59914408 | W6: =INDIRECT("'Bureau " & ROW()-1 & "'!" & ADDRESS(12,Synthèse!$G$40+10,4)) -> 447 | X6: =W6/$F6 -> 0.63766049 | Y6: =INDIRECT("'Bureau " & ROW()-1 & "'!" & ADDRESS(13,Synthèse!$G$40+10,4)) -> 475 | Z6: =Y6/$F6 -> 0.67760342 | AA6: =INDIRECT("'Bureau " & ROW()-1 & "'!" & ADDRESS(14,Synthèse!$G$40+10,4)) -> 0 | AB6: =AA6/$F6 -> 0 | AC6: =INDIRECT("'Bureau " & ROW()-1 & "'!" & ADDRESS(15,Synthèse!$G$40+10,4)) -> 0 | AD6: =AC6/$F6 -> 0 | AE6: 5 | AF6: 0.05278174 | AG6: 0.13266762 | AH6: 0.22824536 | AI6: 0.34236805 | AJ6: 0.41369472 | AK6: 0.4636234 | AL6: 0.53495007 | AM6: 0.59914408 | AN6: 0.62054208 | AO6: 0.64479315 | AP6: 0 | AQ6: 0
A7: 6 | B7: =Synthèse!B8 -> COSEC | C7: =MAX(G7,I7,K7,M7,O7,Q7,S7,U7,W7,Y7,AA7,AC7) -> 380 | D7: =C7/$F7 -> 0.53521127 | E7: =D7 -> 0.53521127 | F7: =Synthèse!C8 -> 710 | G7: =INDIRECT("'Bureau " & ROW()-1 & "'!" & ADDRESS(4,Synthèse!$G$40+10,4)) -> 48 | H7: =G7/$F7 -> 0.067605634 | I7: =INDIRECT("'Bureau " & ROW()-1 & "'!" & ADDRESS(5,Synthèse!$G$40+10,4)) -> 100 | J7: =I7/$F7 -> 0.14084507 | K7: =INDIRECT("'Bureau " & ROW()-1 & "'!" & ADDRESS(6,Synthèse!$G$40+10,4)) -> 156 | L7: =K7/$F7 -> 0.21971831 | M7: =INDIRECT("'Bureau " & ROW()-1 & "'!" & ADDRESS(7,Synthèse!$G$40+10,4)) -> 213 | N7: =M7/$F7 -> 0.3 | O7: =INDIRECT("'Bureau " & ROW()-1 & "'!" & ADDRESS(8,Synthèse!$G$40+10,4)) -> 258 | P7: =O7/$F7 -> 0.36338028 | Q7: =INDIRECT("'Bureau " & ROW()-1 & "'!" & ADDRESS(9,Synthèse!$G$40+10,4)) -> 284 | R7: =Q7/$F7 -> 0.4 | S7: =INDIRECT("'Bureau " & ROW()-1 & "'!" & ADDRESS(10,Synthèse!$G$40+10,4)) -> 320 | T7: =S7/$F7 -> 0.45070423 | U7: =INDIRECT("'Bureau " & ROW()-1 & "'!" & ADDRESS(11,Synthèse!$G$40+10,4)) -> 340 | V7: =U7/$F7 -> 0.47887324 | W7: =INDIRECT("'Bureau " & ROW()-1 & "'!" & ADDRESS(12,Synthèse!$G$40+10,4)) -> 362 | X7: =W7/$F7 -> 0.50985915 | Y7: =INDIRECT("'Bureau " & ROW()-1 & "'!" & ADDRESS(13,Synthèse!$G$40+10,4)) -> 380 | Z7: =Y7/$F7 -> 0.53521127 | AA7: =INDIRECT("'Bureau " & ROW()-1 & "'!" & ADDRESS(14,Synthèse!$G$40+10,4)) -> 0 | AB7: =AA7/$F7 -> 0 | AC7: =INDIRECT("'Bureau " & ROW()-1 & "'!" & ADDRESS(15,Synthèse!$G$40+10,4)) -> 0 | AD7: =AC7/$F7 -> 0 | AE7: 6 | AF7: 0.042253521 | AG7: 0.11971831 | AH7: 0.1971831 | AI7: 0.26760563 | AJ7: 0.33380282 | AK7: 0.38732394 | AL7: 0.42957746 | AM7: 0.47323944 | AN7: 0.5 | AO7: 0.51690141 | AP7: 0 | AQ7: 0
A8: 7 | B8: =Synthèse!B9 -> COSEC | C8: =MAX(G8,I8,K8,M8,O8,Q8,S8,U8,W8,Y8,AA8,AC8) -> 430 | D8: =C8/$F8 -> 0.58823529 | E8: =D8 -> 0.58823529 | F8: =Synthèse!C9 -> 731 | G8: =INDIRECT("'Bureau " & ROW()-1 & "'!" & ADDRESS(4,Synthèse!$G$40+10,4)) -> 30 | H8: =G8/$F8 -> 0.041039672 | I8: =INDIRECT("'Bureau " & ROW()-1 & "'!" & ADDRESS(5,Synthèse!$G$40+10,4)) -> 90 | J8: =I8/$F8 -> 0.12311902 | K8: =INDIRECT("'Bureau " & ROW()-1 & "'!" & ADDRESS(6,Synthèse!$G$40+10,4)) -> 160 | L8: =K8/$F8 -> 0.21887825 | M8: =INDIRECT("'Bureau " & ROW()-1 & "'!" & ADDRESS(7,Synthèse!$G$40+10,4)) -> 230 | N8: =M8/$F8 -> 0.31463748 | O8: =INDIRECT("'Bureau " & ROW()-1 & "'!" & ADDRESS(8,Synthèse!$G$40+10,4)) -> 280 | P8: =O8/$F8 -> 0.38303694 | Q8: =INDIRECT("'Bureau " & ROW()-1 & "'!" & ADDRESS(9,Synthèse!$G$40+10,4)) -> 310 | R8: =Q8/$F8 -> 0.42407661 | S8: =INDIRECT("'Bureau " & ROW()-1 & "'!" & ADDRESS(10,Synthèse!$G$40+10,4)) -> 330 | T8: =S8/$F8 -> 0.45143639 | U8: =INDIRECT("'Bureau " & ROW()-1 & "'!" & ADDRESS(11,Synthèse!$G$40+10,4)) -> 375 | V8: =U8/$F8 -> 0.5129959 | W8: =INDIRECT("'Bureau " & ROW()-1 & "'!" & ADDRESS(12,Synthèse!$G$40+10,4)) -> 410 | X8: =W8/$F8 -> 0.56087551 | Y8: =INDIRECT("'Bureau " & ROW()-1 & "'!" & ADDRESS(13,Synthèse!$G$40+10,4)) -> 430 | Z8: =Y8/$F8 -> 0.58823529 | AA8: =INDIRECT("'Bureau " & ROW()-1 & "'!" & ADDRESS(14,Synthèse!$G$40+10,4)) -> 0 | AB8: =AA8/$F8 -> 0 | AC8: =INDIRECT("'Bureau " & ROW()-1 & "'!" & ADDRESS(15,Synthèse!$G$40+10,4)) -> 0 | AD8: =AC8/$F8 -> 0 | AE8: 7 | AF8: 0.027359781 | AG8: 0.10259918 | AH8: 0.20519836 | AI8: 0.33105335 | AJ8: 0.38850889 | AK8: 0.42407661 | AL8: 0.48426813 | AM8: 0.5499316 | AN8: 0.5745554 | AO8: 0.6005472 | AP8: 0 | AQ8: 0
A9: 8 | B9: =Synthèse!B10 -> COSEC | C9: =MAX(G9,I9,K9,M9,O9,Q9,S9,U9,W9,Y9,AA9,AC9) -> 362 | D9: =C9/$F9 -> 0.56124031 | E9: =D9 -> 0.56124031 | F9: =Synthèse!C10 -> 645 | G9: =INDIRECT("'Bureau " & ROW()-1 & "'!" & ADDRESS(4,Synthèse!$G$40+10,4)) -> 40 | H9: =G9/$F9 -> 0.062015504 | I9: =INDIRECT("'Bureau " & ROW()-1 & "'!" & ADDRESS(5,Synthèse!$G$40+10,4)) -> 92 | J9: =I9/$F9 -> 0.14263566 | K9: =INDIRECT("'Bureau " & ROW()-1 & "'!" & ADDRESS(6,Synthèse!$G$40+10,4)) -> 146 | L9: =K9/$F9 -> 0.22635659 | M9: =INDIRECT("'Bureau " & ROW()-1 & "'!" & ADDRESS(7,Synthèse!$G$40+10,4)) -> 212 | N9: =M9/$F9 -> 0.32868217 | O9: =INDIRECT("'Bureau " & ROW()-1 & "'!" & ADDRESS(8,Synthèse!$G$40+10,4)) -> 267 | P9: =O9/$F9 -> 0.41395349 | Q9: =INDIRECT("'Bureau " & ROW()-1 & "'!" & ADDRESS(9,Synthèse!$G$40+10,4)) -> 294 | R9: =Q9/$F9 -> 0.45581395 | S9: =INDIRECT("'Bureau " & ROW()-1 & "'!" & ADDRESS(10,Synthèse!$G$40+10,4)) -> 317 | T9: =S9/$F9 -> 0.49147287 | U9: =INDIRECT("'Bureau " & ROW()-1 & "'!" & ADDRESS(11,Synthèse!$G$40+10,4)) -> 330 | V9: =U9/$F9 -> 0.51162791 | W9: =INDIRECT("'Bureau " & ROW()-1 & "'!" & ADDRESS(12,Synthèse!$G$40+10,4)) -> 356 | X9: =W9/$F9 -> 0.55193798 | Y9: =INDIRECT("'Bureau " & ROW()-1 & "'!" & ADDRESS(13,Synthèse!$G$40+10,4)) -> 362 | Z9: =Y9/$F9 -> 0.56124031 | AA9: =INDIRECT("'Bureau " & ROW()-1 & "'!" & ADDRESS(14,Synthèse!$G$40+10,4)) -> 0 | AB9: =AA9/$F9 -> 0 | AC9: =INDIRECT("'Bureau " & ROW()-1 & "'!" & ADDRESS(15,Synthèse!$G$40+10,4)) -> 0 | AD9: =AC9/$F9 -> 0 | AE9: 8 | AF9: 0.055727554 | AG9: 0.11145511 | AH9: 0.23065015 | AI9: 0.32972136 | AJ9: 0.40247678 | AK9: 0.46439628 | AL9: 0.50309598 | AM9: 0.54179567 | AN9: 0.55882353 | AO9: 0.58668731 | AP9: 0 | AQ9: 0
A10: 9 | B10: =Synthèse!B11 -> CMM | C10: =MAX(G10,I10,K10,M10,O10,Q10,S10,U10,W10,Y10,AA10,AC10) -> 331 | D10: =C10/$F10 -> 0.46619718 | E10: =D10 -> 0.46619718 | F10: =Synthèse!C11 -> 710 | G10: =INDIRECT("'Bureau " & ROW()-1 & "'!" & ADDRESS(4,Synthèse!$G$40+10,4)) -> 35 | H10: =G10/$F10 -> 0.049295775 | I10: =INDIRECT("'Bureau " & ROW()-1 & "'!" & ADDRESS(5,Synthèse!$G$40+10,4)) -> 70 | J10: =I10/$F10 -> 0.098591549 | K10: =INDIRECT("'Bureau " & ROW()-1 & "'!" & ADDRESS(6,Synthèse!$G$40+10,4)) -> 127 | L10: =K10/$F10 -> 0.17887324 | M10: =INDIRECT("'Bureau " & ROW()-1 & "'!" & ADDRESS(7,Synthèse!$G$40+10,4)) -> 180 | N10: =M10/$F10 -> 0.25352113 | O10: =INDIRECT("'Bureau " & ROW()-1 & "'!" & ADDRESS(8,Synthèse!$G$40+10,4)) -> 213 | P10: =O10/$F10 -> 0.3 | Q10: =INDIRECT("'Bureau " & ROW()-1 & "'!" & ADDRESS(9,Synthèse!$G$40+10,4)) -> 240 | R10: =Q10/$F10 -> 0.33802817 | S10: =INDIRECT("'Bureau " & ROW()-1 & "'!" & ADDRESS(10,Synthèse!$G$40+10,4)) -> 264 | T10: =S10/$F10 -> 0.37183099 | U10: =INDIRECT("'Bureau " & ROW()-1 & "'!" & ADDRESS(11,Synthèse!$G$40+10,4)) -> 294 | V10: =U10/$F10 -> 0.41408451 | W10: =INDIRECT("'Bureau " & ROW()-1 & "'!" & ADDRESS(12,Synthèse!$G$40+10,4)) -> 320 | X10: =W10/$F10 -> 0.45070423 | Y10: =INDIRECT("'Bureau " & ROW()-1 & "'!" & ADDRESS(13,Synthèse!$G$40+10,4)) -> 331 | Z10: =Y10/$F10 -> 0.46619718 | AA10: =INDIRECT("'Bureau " & ROW()-1 & "'!" & ADDRESS(14,Synthèse!$G$40+10,4)) -> 0 | AB10: =AA10/$F10 -> 0 | AC10: =INDIRECT("'Bureau " & ROW()-1 & "'!" & ADDRESS(15,Synthèse!$G$40+10,4)) -> 0 | AD10: =AC10/$F10 -> 0 | AE10: 9 | AF10: 0.031029619 | AG10: 0.083215797 | AH10: 0.14809591 | AI10: 0.23272214 | AJ10: 0.27080395 | AK10: 0.32440056 | AL10: 0.38081805 | AM10: 0.41325811 | AN10: 0.44005642 | AO10: 0.4696756 | AP10: 0 | AQ10: 0
A11: 10 | B11: =Synthèse!B12 -> CMM | C11: =MAX(G11,I11,K11,M11,O11,Q11,S11,U11,W11,Y11,AA11,AC11) -> 357 | D11: =C11/$F11 -> 0.5862069 | E11: =D11 -> 0.5862069 | F11: =Synthèse!C12 -> 609 | G11: =INDIRECT("'Bureau " & ROW()-1 & "'!" & ADDRESS(4,Synthèse!$G$40+10,4)) -> 30 | H11: =G11/$F11 -> 0.049261084 | I11: =INDIRECT("'Bureau " & ROW()-1 & "'!" & ADDRESS(5,Synthèse!$G$40+10,4)) -> 84 | J11: =I11/$F11 -> 0.13793103 | K11: =INDIRECT("'Bureau " & ROW()-1 & "'!" & ADDRESS(6,Synthèse!$G$40+10,4)) -> 150 | L11: =K11/$F11 -> 0.24630542 | M11: =INDIRECT("'Bureau " & ROW()-1 & "'!" & ADDRESS(7,Synthèse!$G$40+10,4)) -> 220 | N11: =M11/$F11 -> 0.36124795 | O11: =INDIRECT("'Bureau " & ROW()-1 & "'!" & ADDRESS(8,Synthèse!$G$40+10,4)) -> 270 | P11: =O11/$F11 -> 0.44334975 | Q11: =INDIRECT("'Bureau " & ROW()-1 & "'!" & ADDRESS(9,Synthèse!$G$40+10,4)) -> 282 | R11: =Q11/$F11 -> 0.46305419 | S11: =INDIRECT("'Bureau " & ROW()-1 & "'!" & ADDRESS(10,Synthèse!$G$40+10,4)) -> 305 | T11: =S11/$F11 -> 0.50082102 | U11: =INDIRECT("'Bureau " & ROW()-1 & "'!" & ADDRESS(11,Synthèse!$G$40+10,4)) -> 325 | V11: =U11/$F11 -> 0.53366174 | W11: =INDIRECT("'Bureau " & ROW()-1 & "'!" & ADDRESS(12,Synthèse!$G$40+10,4)) -> 345 | X11: =W11/$F11 -> 0.56650246 | Y11: =INDIRECT("'Bureau " & ROW()-1 & "'!" & ADDRESS(13,Synthèse!$G$40+10,4)) -> 357 | Z11: =Y11/$F11 -> 0.5862069 | AA11: =INDIRECT("'Bureau " & ROW()-1 & "'!" & ADDRESS(14,Synthèse!$G$40+10,4)) -> 0 | AB11: =AA11/$F11 -> 0 | AC11: =INDIRECT("'Bureau " & ROW()-1 & "'!" & ADDRESS(15,Synthèse!$G$40+10,4)) -> 0 | AD11: =AC11/$F11 -> 0 | AE11: 10 | AF11: 0.044334975 | AG11: 0.11494253 | AH11: 0.22988506 | AI11: 0.34482759 | AJ11: 0.39408867 | AK11: 0.44663383 | AL11: 0.49261084 | AM11: 0.54187192 | AN11: 0.56486043 | AO11: 0.5862069 | AP11: 0 | AQ11: 0
A12: 11 | B12: =Synthèse!B13 -> CMM | C12: =MAX(G12,I12,K12,M12,O12,Q12,S12,U12,W12,Y12,AA12,AC12) -> 405 | D12: =C12/$F12 -> 0.58610709 | E12: =D12 -> 0.58610709 | F12: =Synthèse!C13 -> 691 | G12: =INDIRECT("'Bureau " & ROW()-1 & "'!" & ADDRESS(4,Synthèse!$G$40+10,4)) -> 43 | H12: =G12/$F12 -> 0.062228654 | I12: =INDIRECT("'Bureau " & ROW()-1 & "'!" & ADDRESS(5,Synthèse!$G$40+10,4)) -> 93 | J12: =I12/$F12 -> 0.13458755 | K12: =INDIRECT("'Bureau " & ROW()-1 & "'!" & ADDRESS(6,Synthèse!$G$40+10,4)) -> 156 | L12: =K12/$F12 -> 0.22575977 | M12: =INDIRECT("'Bureau " & ROW()-1 & "'!" & ADDRESS(7,Synthèse!$G$40+10,4)) -> 226 | N12: =M12/$F12 -> 0.32706223 | O12: =INDIRECT("'Bureau " & ROW()-1 & "'!" & ADDRESS(8,Synthèse!$G$40+10,4)) -> 260 | P12: =O12/$F12 -> 0.37626628 | Q12: =INDIRECT("'Bureau " & ROW()-1 & "'!" & ADDRESS(9,Synthèse!$G$40+10,4)) -> 298 | R12: =Q12/$F12 -> 0.43125904 | S12: =INDIRECT("'Bureau " & ROW()-1 & "'!" & ADDRESS(10,Synthèse!$G$40+10,4)) -> 332 | T12: =S12/$F12 -> 0.4804631 | U12: =INDIRECT("'Bureau " & ROW()-1 & "'!" & ADDRESS(11,Synthèse!$G$40+10,4)) -> 363 | V12: =U12/$F12 -> 0.52532562 | W12: =INDIRECT("'Bureau " & ROW()-1 & "'!" & ADDRESS(12,Synthèse!$G$40+10,4)) -> 387 | X12: =W12/$F12 -> 0.56005789 | Y12: =INDIRECT("'Bureau " & ROW()-1 & "'!" & ADDRESS(13,Synthèse!$G$40+10,4)) -> 405 | Z12: =Y12/$F12 -> 0.58610709 | AA12: =INDIRECT("'Bureau " & ROW()-1 & "'!" & ADDRESS(14,Synthèse!$G$40+10,4)) -> 0 | AB12: =AA12/$F12 -> 0 | AC12: =INDIRECT("'Bureau " & ROW()-1 & "'!" & ADDRESS(15,Synthèse!$G$40+10,4)) -> 0 | AD12: =AC12/$F12 -> 0 | AE12: 11 | AF12: 0.068017366 | AG12: 0.13892909 | AH12: 0.22865412 | AI12: 0.31114327 | AJ12: 0.38205499 | AK12: 0.43270622 | AL12: 0.4804631 | AM12: 0.552822 | AN12: 0.57597685 | AO12: 0.60202605 | AP12: 0 | AQ12: 0
A13: 12 | B13: =Synthèse!B14 -> Base nautique | C13: =MAX(G13,I13,K13,M13,O13,Q13,S13,U13,W13,Y13,AA13,AC13) -> 300 | D13: =C13/$F13 -> 0.44052863 | E13: =D13 -> 0.44052863 | F13: =Synthèse!C14 -> 681 | G13: =INDIRECT("'Bureau " & ROW()-1 & "'!" & ADDRESS(4,Synthèse!$G$40+10,4)) -> 10 | H13: =G13/$F13 -> 0.014684288 | I13: =INDIRECT("'Bureau " & ROW()-1 & "'!" & ADDRESS(5,Synthèse!$G$40+10,4)) -> 45 | J13: =I13/$F13 -> 0.066079295 | K13: =INDIRECT("'Bureau " & ROW()-1 & "'!" & ADDRESS(6,Synthèse!$G$40+10,4)) -> 98 | L13: =K13/$F13 -> 0.14390602 | M13: =INDIRECT("'Bureau " & ROW()-1 & "'!" & ADDRESS(7,Synthèse!$G$40+10,4)) -> 158 | N13: =M13/$F13 -> 0.23201175 | O13: =INDIRECT("'Bureau " & ROW()-1 & "'!" & ADDRESS(8,Synthèse!$G$40+10,4)) -> 194 | P13: =O13/$F13 -> 0.28487518 | Q13: =INDIRECT("'Bureau " & ROW()-1 & "'!" & ADDRESS(9,Synthèse!$G$40+10,4)) -> 210 | R13: =Q13/$F13 -> 0.30837004 | S13: =INDIRECT("'Bureau " & ROW()-1 & "'!" & ADDRESS(10,Synthèse!$G$40+10,4)) -> 239 | T13: =S13/$F13 -> 0.35095448 | U13: =INDIRECT("'Bureau " & ROW()-1 & "'!" & ADDRESS(11,Synthèse!$G$40+10,4)) -> 260 | V13: =U13/$F13 -> 0.38179148 | W13: =INDIRECT("'Bureau " & ROW()-1 & "'!" & ADDRESS(12,Synthèse!$G$40+10,4)) -> 287 | X13: =W13/$F13 -> 0.42143906 | Y13: =INDIRECT("'Bureau " & ROW()-1 & "'!" & ADDRESS(13,Synthèse!$G$40+10,4)) -> 300 | Z13: =Y13/$F13 -> 0.44052863 | AA13: =INDIRECT("'Bureau " & ROW()-1 & "'!" & ADDRESS(14,Synthèse!$G$40+10,4)) -> 0 | AB13: =AA13/$F13 -> 0 | AC13: =INDIRECT("'Bureau " & ROW()-1 & "'!" & ADDRESS(15,Synthèse!$G$40+10,4)) -> 0 | AD13: =AC13/$F13 -> 0 | AE13: 12 | AF13: 0.035294118 | AG13: 0.072058824 | AH13: 0.14117647 | AI13: 0.21029412 | AJ13: 0.26764706 | AK13: 0.31911765 | AL13: 0.36911765 | AM13: 0.42205882 | AN13: 0.47205882 | AO13: 0.47941176 | AP13: 0 | AQ13: 0
A14: TOTAL | C14: =SUM(C2:C13) -> 4651 | D14: =C14/$F14 -> 0.56962645 | E14: =D14 -> 0.56962645 | F14: =SUM(F2:F13) -> 8165 | G14: =SUM(G2:G13) -> 458 | H14: =G14/$F14 -> 0.05609308 | I14: =SUM(I2:I13) -> 1056 | J14: =I14/$F14 -> 0.12933252 | K14: =SUM(K2:K13) -> 1849 | L14: =K14/$F14 -> 0.22645438 | M14: =SUM(M2:M13) -> 2600 | N14: =M14/$F14 -> 0.31843233 | O14: =SUM(O2:O13) -> 3143 | P14: =O14/$F14 -> 0.3849357 | Q14: =SUM(Q2:Q13) -> 3444 | R14: =Q14/$F14 -> 0.42180037 | S14: =SUM(S2:S13) -> 3789 | T14: =S14/$F14 -> 0.46405389 | U14: =SUM(U2:U13) -> 4120 | V14: =U14/$F14 -> 0.50459277 | W14: =SUM(W2:W13) -> 4445 | X14: =W14/$F14 -> 0.54439682 | Y14: =SUM(Y2:Y13) -> 4651 | Z14: =Y14/$F14 -> 0.56962645 | AA14: =SUM(AA2:AA13) -> 0 | AB14: =AA14/$F14 -> 0 | AC14: =SUM(AC2:AC13) -> 0 | AD14: =AC14/$F14 -> 0 | AE14: Total | AF14: 0.048272482 | AG14: 0.11455526 | AH14: 0.20779221 | AI14: 0.30531732 | AJ14: 0.36535163 | AK14: 0.41644205 | AL14: 0.470963 | AM14: 0.52046067 | AN14: 0.54949767 | AO14: 0.57363391 | AP14: 0 | AQ14: 0
A15: =Synthèse!$A$17 -> Date | B15: =Synthèse!$B$17 -> 46103 | AE15: Valeurs du tour précédent
A16: =Synthèse!$A$18 -> Election | B16: =Synthèse!$B$18 -> Municipale
A17: =Synthèse!$A$19 -> Tour | B17: =Synthèse!$B$19 -> 2
A18: =Synthèse!$A$20 -> Ville | B18: =Synthèse!$B$20 -> Cogolin
B29: Les cases grisées sont
B30: calculées automatiquement
B31: Ne pas éditer
G36: Tour actuel | U36: Tour précédent
F37: Heure | G37: Bureau 1 | H37: Bureau 2 | I37: Bureau 3 | J37: Bureau 4 | K37: Bureau 5 | L37: Bureau 6 | M37: Bureau 7 | N37: Bureau 8 | O37: Bureau 9 | P37: Bureau 10 | Q37: Bureau 11 | R37: Bureau 12 | S37: Total | T37: Heure | U37: Bureau 1 | V37: Bureau 2 | W37: Bureau 3 | X37: Bureau 4 | Y37: Bureau 5 | Z37: Bureau 6 | AA37: Bureau 7 | AB37: Bureau 8 | AC37: Bureau 9 | AD37: Bureau 10 | AE37: Bureau 11 | AF37: Bureau 12 | AG37: Total
F38: 08h00 | G38: 0 | H38: 0 | I38: 0 | J38: 0 | K38: 0 | L38: 0 | M38: 0 | N38: 0 | O38: 0 | P38: 0 | Q38: 0 | R38: 0 | S38: 0 | T38: 08h00 | U38: 0 | V38: 0 | W38: 0 | X38: 0 | Y38: 0 | Z38: 0 | AA38: 0 | AB38: 0 | AC38: 0 | AD38: 0 | AE38: 0 | AF38: 0 | AG38: 0
F39: 09h00 | G39: {=IF( INDEX($H$2:$Z$14, COLUMN(A1), 2*ROW(A1)-1)>0, INDEX($H$2:$Z$14, COLUMN(A1), 2*ROW(A1)-1), NA() )} -> 0.059566787 | H39: {=IF( INDEX($H$2:$Z$14, COLUMN(B1), 2*ROW(B1)-1)>0, INDEX($H$2:$Z$14, COLUMN(B1), 2*ROW(B1)-1), NA() )} -> 0.067567568 | I39: {=IF( INDEX($H$2:$Z$14, COLUMN(C1), 2*ROW(C1)-1)>0, INDEX($H$2:$Z$14, COLUMN(C1), 2*ROW(C1)-1), NA() )} -> 0.070028011 | J39: {=IF( INDEX($H$2:$Z$14, COLUMN(D1), 2*ROW(D1)-1)>0, INDEX($H$2:$Z$14, COLUMN(D1), 2*ROW(D1)-1), NA() )} -> 0.064801178 | K39: {=IF( INDEX($H$2:$Z$14, COLUMN(E1), 2*ROW(E1)-1)>0, INDEX($H$2:$Z$14, COLUMN(E1), 2*ROW(E1)-1), NA() )} -> 0.064194009 | L39: {=IF( INDEX($H$2:$Z$14, COLUMN(F1), 2*ROW(F1)-1)>0, INDEX($H$2:$Z$14, COLUMN(F1), 2*ROW(F1)-1), NA() )} -> 0.067605634 | M39: {=IF( INDEX($H$2:$Z$14, COLUMN(G1), 2*ROW(G1)-1)>0, INDEX($H$2:$Z$14, COLUMN(G1), 2*ROW(G1)-1), NA() )} -> 0.041039672 | N39: {=IF( INDEX($H$2:$Z$14, COLUMN(H1), 2*ROW(H1)-1)>0, INDEX($H$2:$Z$14, COLUMN(H1), 2*ROW(H1)-1), NA() )} -> 0.062015504 | ... S39: {=IF( INDEX($H$2:$Z$14, COLUMN(M1), 2*ROW(M1)-1)>0, INDEX($H$2:$Z$14, COLUMN(M1), 2*ROW(M1)-1), NA() )} -> 0.05609308 | T39: 09h00 | U39: =AF2 -> 0.059674503 | V39: =AF3 -> 0.060810811 | W39: =AF4 -> 0.056100982 | X39: =AF5 -> 0.048600884 | Y39: =AF6 -> 0.05278174 | Z39: =AF7 -> 0.042253521 | AA39: =AF8 -> 0.027359781 | AB39: =AF9 -> 0.055727554 | AC39: =AF10 -> 0.031029619 | AD39: =AF11 -> 0.044334975 | AE39: =AF12 -> 0.068017366 | AF39: =AF13 -> 0.035294118 | AG39: =AF14 -> 0.048272482
F40: 10h00 | G40: {=IF( INDEX($H$2:$Z$14, COLUMN(A2), 2*ROW(A2)-1)>0, INDEX($H$2:$Z$14, COLUMN(A2), 2*ROW(A2)-1), NA() )} -> 0.1299639 | H40: {=IF( INDEX($H$2:$Z$14, COLUMN(B2), 2*ROW(B2)-1)>0, INDEX($H$2:$Z$14, COLUMN(B2), 2*ROW(B2)-1), NA() )} -> 0.12162162 | I40: {=IF( INDEX($H$2:$Z$14, COLUMN(C2), 2*ROW(C2)-1)>0, INDEX($H$2:$Z$14, COLUMN(C2), 2*ROW(C2)-1), NA() )} -> 0.14005602 | J40: {=IF( INDEX($H$2:$Z$14, COLUMN(D2), 2*ROW(D2)-1)>0, INDEX($H$2:$Z$14, COLUMN(D2), 2*ROW(D2)-1), NA() )} -> 0.16200295 | K40: {=IF( INDEX($H$2:$Z$14, COLUMN(E2), 2*ROW(E2)-1)>0, INDEX($H$2:$Z$14, COLUMN(E2), 2*ROW(E2)-1), NA() )} -> 0.15691869 | L40: {=IF( INDEX($H$2:$Z$14, COLUMN(F2), 2*ROW(F2)-1)>0, INDEX($H$2:$Z$14, COLUMN(F2), 2*ROW(F2)-1), NA() )} -> 0.14084507 | M40: {=IF( INDEX($H$2:$Z$14, COLUMN(G2), 2*ROW(G2)-1)>0, INDEX($H$2:$Z$14, COLUMN(G2), 2*ROW(G2)-1), NA() )} -> 0.12311902 | N40: {=IF( INDEX($H$2:$Z$14, COLUMN(H2), 2*ROW(H2)-1)>0, INDEX($H$2:$Z$14, COLUMN(H2), 2*ROW(H2)-1), NA() )} -> 0.14263566 | ... S40: {=IF( INDEX($H$2:$Z$14, COLUMN(M2), 2*ROW(M2)-1)>0, INDEX($H$2:$Z$14, COLUMN(M2), 2*ROW(M2)-1), NA() )} -> 0.12933252 | T40: 10h00 | U40: =AG2 -> 0.14104882 | V40: =AG3 -> 0.10810811 | W40: =AG4 -> 0.1542777 | X40: =AG5 -> 0.10014728 | Y40: =AG6 -> 0.13266762 | Z40: =AG7 -> 0.11971831 | AA40: =AG8 -> 0.10259918 | AB40: =AG9 -> 0.11145511 | AC40: =AG10 -> 0.083215797 | AD40: =AG11 -> 0.11494253 | AE40: =AG12 -> 0.13892909 | AF40: =AG13 -> 0.072058824 | AG40: =AG14 -> 0.11455526
F41: 11h00 | G41: {=IF( INDEX($H$2:$Z$14, COLUMN(A3), 2*ROW(A3)-1)>0, INDEX($H$2:$Z$14, COLUMN(A3), 2*ROW(A3)-1), NA() )} -> 0.22202166 | H41: {=IF( INDEX($H$2:$Z$14, COLUMN(B3), 2*ROW(B3)-1)>0, INDEX($H$2:$Z$14, COLUMN(B3), 2*ROW(B3)-1), NA() )} -> 0.22972973 | I41: {=IF( INDEX($H$2:$Z$14, COLUMN(C3), 2*ROW(C3)-1)>0, INDEX($H$2:$Z$14, COLUMN(C3), 2*ROW(C3)-1), NA() )} -> 0.25210084 | J41: {=IF( INDEX($H$2:$Z$14, COLUMN(D3), 2*ROW(D3)-1)>0, INDEX($H$2:$Z$14, COLUMN(D3), 2*ROW(D3)-1), NA() )} -> 0.26951399 | K41: {=IF( INDEX($H$2:$Z$14, COLUMN(E3), 2*ROW(E3)-1)>0, INDEX($H$2:$Z$14, COLUMN(E3), 2*ROW(E3)-1), NA() )} -> 0.2853067 | L41: {=IF( INDEX($H$2:$Z$14, COLUMN(F3), 2*ROW(F3)-1)>0, INDEX($H$2:$Z$14, COLUMN(F3), 2*ROW(F3)-1), NA() )} -> 0.21971831 | M41: {=IF( INDEX($H$2:$Z$14, COLUMN(G3), 2*ROW(G3)-1)>0, INDEX($H$2:$Z$14, COLUMN(G3), 2*ROW(G3)-1), NA() )} -> 0.21887825 | N41: {=IF( INDEX($H$2:$Z$14, COLUMN(H3), 2*ROW(H3)-1)>0, INDEX($H$2:$Z$14, COLUMN(H3), 2*ROW(H3)-1), NA() )} -> 0.22635659 | ... S41: {=IF( INDEX($H$2:$Z$14, COLUMN(M3), 2*ROW(M3)-1)>0, INDEX($H$2:$Z$14, COLUMN(M3), 2*ROW(M3)-1), NA() )} -> 0.22645438 | T41: 11h00 | U41: =AH2 -> 0.23508137 | V41: =AH3 -> 0.18918919 | W41: =AH4 -> 0.26647966 | X41: =AH5 -> 0.20324006 | Y41: =AH6 -> 0.22824536 | Z41: =AH7 -> 0.1971831 | AA41: =AH8 -> 0.20519836 | AB41: =AH9 -> 0.23065015 | AC41: =AH10 -> 0.14809591 | AD41: =AH11 -> 0.22988506 | AE41: =AH12 -> 0.22865412 | AF41: =AH13 -> 0.14117647 | AG41: =AH14 -> 0.20779221
F42: 12h00 | G42: {=IF( INDEX($H$2:$Z$14, COLUMN(A4), 2*ROW(A4)-1)>0, INDEX($H$2:$Z$14, COLUMN(A4), 2*ROW(A4)-1), NA() )} -> 0.32490975 | H42: {=IF( INDEX($H$2:$Z$14, COLUMN(B4), 2*ROW(B4)-1)>0, INDEX($H$2:$Z$14, COLUMN(B4), 2*ROW(B4)-1), NA() )} -> 0.31081081 | I42: {=IF( INDEX($H$2:$Z$14, COLUMN(C4), 2*ROW(C4)-1)>0, INDEX($H$2:$Z$14, COLUMN(C4), 2*ROW(C4)-1), NA() )} -> 0.36414566 | J42: {=IF( INDEX($H$2:$Z$14, COLUMN(D4), 2*ROW(D4)-1)>0, INDEX($H$2:$Z$14, COLUMN(D4), 2*ROW(D4)-1), NA() )} -> 0.32400589 | K42: {=IF( INDEX($H$2:$Z$14, COLUMN(E4), 2*ROW(E4)-1)>0, INDEX($H$2:$Z$14, COLUMN(E4), 2*ROW(E4)-1), NA() )} -> 0.38659058 | L42: {=IF( INDEX($H$2:$Z$14, COLUMN(F4), 2*ROW(F4)-1)>0, INDEX($H$2:$Z$14, COLUMN(F4), 2*ROW(F4)-1), NA() )} -> 0.3 | M42: {=IF( INDEX($H$2:$Z$14, COLUMN(G4), 2*ROW(G4)-1)>0, INDEX($H$2:$Z$14, COLUMN(G4), 2*ROW(G4)-1), NA() )} -> 0.31463748 | N42: {=IF( INDEX($H$2:$Z$14, COLUMN(H4), 2*ROW(H4)-1)>0, INDEX($H$2:$Z$14, COLUMN(H4), 2*ROW(H4)-1), NA() )} -> 0.32868217 | ... S42: {=IF( INDEX($H$2:$Z$14, COLUMN(M4), 2*ROW(M4)-1)>0, INDEX($H$2:$Z$14, COLUMN(M4), 2*ROW(M4)-1), NA() )} -> 0.31843233 | T42: 12h00 | U42: =AI2 -> 0.3363472 | V42: =AI3 -> 0.31081081 | W42: =AI4 -> 0.37868163 | X42: =AI5 -> 0.27687776 | Y42: =AI6 -> 0.34236805 | Z42: =AI7 -> 0.26760563 | AA42: =AI8 -> 0.33105335 | AB42: =AI9 -> 0.32972136 | AC42: =AI10 -> 0.23272214 | AD42: =AI11 -> 0.34482759 | AE42: =AI12 -> 0.31114327 | AF42: =AI13 -> 0.21029412 | AG42: =AI14 -> 0.30531732
F43: 13h00 | G43: {=IF( INDEX($H$2:$Z$14, COLUMN(A5), 2*ROW(A5)-1)>0, INDEX($H$2:$Z$14, COLUMN(A5), 2*ROW(A5)-1), NA() )} -> 0.38267148 | H43: {=IF( INDEX($H$2:$Z$14, COLUMN(B5), 2*ROW(B5)-1)>0, INDEX($H$2:$Z$14, COLUMN(B5), 2*ROW(B5)-1), NA() )} -> 0.38918919 | I43: {=IF( INDEX($H$2:$Z$14, COLUMN(C5), 2*ROW(C5)-1)>0, INDEX($H$2:$Z$14, COLUMN(C5), 2*ROW(C5)-1), NA() )} -> 0.43417367 | J43: {=IF( INDEX($H$2:$Z$14, COLUMN(D5), 2*ROW(D5)-1)>0, INDEX($H$2:$Z$14, COLUMN(D5), 2*ROW(D5)-1), NA() )} -> 0.38291605 | K43: {=IF( INDEX($H$2:$Z$14, COLUMN(E5), 2*ROW(E5)-1)>0, INDEX($H$2:$Z$14, COLUMN(E5), 2*ROW(E5)-1), NA() )} -> 0.4721826 | L43: {=IF( INDEX($H$2:$Z$14, COLUMN(F5), 2*ROW(F5)-1)>0, INDEX($H$2:$Z$14, COLUMN(F5), 2*ROW(F5)-1), NA() )} -> 0.36338028 | M43: {=IF( INDEX($H$2:$Z$14, COLUMN(G5), 2*ROW(G5)-1)>0, INDEX($H$2:$Z$14, COLUMN(G5), 2*ROW(G5)-1), NA() )} -> 0.38303694 | N43: {=IF( INDEX($H$2:$Z$14, COLUMN(H5), 2*ROW(H5)-1)>0, INDEX($H$2:$Z$14, COLUMN(H5), 2*ROW(H5)-1), NA() )} -> 0.41395349 | ... S43: {=IF( INDEX($H$2:$Z$14, COLUMN(M5), 2*ROW(M5)-1)>0, INDEX($H$2:$Z$14, COLUMN(M5), 2*ROW(M5)-1), NA() )} -> 0.3849357 | T43: 13h00 | U43: =AJ2 -> 0.37793852 | V43: =AJ3 -> 0.38918919 | W43: =AJ4 -> 0.43478261 | X43: =AJ5 -> 0.33284242 | Y43: =AJ6 -> 0.41369472 | Z43: =AJ7 -> 0.33380282 | AA43: =AJ8 -> 0.38850889 | AB43: =AJ9 -> 0.40247678 | AC43: =AJ10 -> 0.27080395 | AD43: =AJ11 -> 0.39408867 | AE43: =AJ12 -> 0.38205499 | AF43: =AJ13 -> 0.26764706 | AG43: =AJ14 -> 0.36535163
F44: 14h00 | G44: {=IF( INDEX($H$2:$Z$14, COLUMN(A6), 2*ROW(A6)-1)>0, INDEX($H$2:$Z$14, COLUMN(A6), 2*ROW(A6)-1), NA() )} -> 0.41877256 | H44: {=IF( INDEX($H$2:$Z$14, COLUMN(B6), 2*ROW(B6)-1)>0, INDEX($H$2:$Z$14, COLUMN(B6), 2*ROW(B6)-1), NA() )} -> 0.42432432 | I44: {=IF( INDEX($H$2:$Z$14, COLUMN(C6), 2*ROW(C6)-1)>0, INDEX($H$2:$Z$14, COLUMN(C6), 2*ROW(C6)-1), NA() )} -> 0.46218487 | J44: {=IF( INDEX($H$2:$Z$14, COLUMN(D6), 2*ROW(D6)-1)>0, INDEX($H$2:$Z$14, COLUMN(D6), 2*ROW(D6)-1), NA() )} -> 0.43446244 | K44: {=IF( INDEX($H$2:$Z$14, COLUMN(E6), 2*ROW(E6)-1)>0, INDEX($H$2:$Z$14, COLUMN(E6), 2*ROW(E6)-1), NA() )} -> 0.5064194 | L44: {=IF( INDEX($H$2:$Z$14, COLUMN(F6), 2*ROW(F6)-1)>0, INDEX($H$2:$Z$14, COLUMN(F6), 2*ROW(F6)-1), NA() )} -> 0.4 | M44: {=IF( INDEX($H$2:$Z$14, COLUMN(G6), 2*ROW(G6)-1)>0, INDEX($H$2:$Z$14, COLUMN(G6), 2*ROW(G6)-1), NA() )} -> 0.42407661 | N44: {=IF( INDEX($H$2:$Z$14, COLUMN(H6), 2*ROW(H6)-1)>0, INDEX($H$2:$Z$14, COLUMN(H6), 2*ROW(H6)-1), NA() )} -> 0.45581395 | ... S44: {=IF( INDEX($H$2:$Z$14, COLUMN(M6), 2*ROW(M6)-1)>0, INDEX($H$2:$Z$14, COLUMN(M6), 2*ROW(M6)-1), NA() )} -> 0.42180037 | T44: 14h00 | U44: =AK2 -> 0.42495479 | V44: =AK3 -> 0.41891892 | W44: =AK4 -> 0.50490884 | X44: =AK5 -> 0.39175258 | Y44: =AK6 -> 0.4636234 | Z44: =AK7 -> 0.38732394 | AA44: =AK8 -> 0.42407661 | AB44: =AK9 -> 0.46439628 | AC44: =AK10 -> 0.32440056 | AD44: =AK11 -> 0.44663383 | AE44: =AK12 -> 0.43270622 | AF44: =AK13 -> 0.31911765 | AG44: =AK14 -> 0.41644205
F45: 15h00 | G45: {=IF( INDEX($H$2:$Z$14, COLUMN(A7), 2*ROW(A7)-1)>0, INDEX($H$2:$Z$14, COLUMN(A7), 2*ROW(A7)-1), NA() )} -> 0.46028881 | H45: {=IF( INDEX($H$2:$Z$14, COLUMN(B7), 2*ROW(B7)-1)>0, INDEX($H$2:$Z$14, COLUMN(B7), 2*ROW(B7)-1), NA() )} -> 0.45945946 | I45: {=IF( INDEX($H$2:$Z$14, COLUMN(C7), 2*ROW(C7)-1)>0, INDEX($H$2:$Z$14, COLUMN(C7), 2*ROW(C7)-1), NA() )} -> 0.51820728 | J45: {=IF( INDEX($H$2:$Z$14, COLUMN(D7), 2*ROW(D7)-1)>0, INDEX($H$2:$Z$14, COLUMN(D7), 2*ROW(D7)-1), NA() )} -> 0.48159057 | K45: {=IF( INDEX($H$2:$Z$14, COLUMN(E7), 2*ROW(E7)-1)>0, INDEX($H$2:$Z$14, COLUMN(E7), 2*ROW(E7)-1), NA() )} -> 0.55634807 | L45: {=IF( INDEX($H$2:$Z$14, COLUMN(F7), 2*ROW(F7)-1)>0, INDEX($H$2:$Z$14, COLUMN(F7), 2*ROW(F7)-1), NA() )} -> 0.45070423 | M45: {=IF( INDEX($H$2:$Z$14, COLUMN(G7), 2*ROW(G7)-1)>0, INDEX($H$2:$Z$14, COLUMN(G7), 2*ROW(G7)-1), NA() )} -> 0.45143639 | N45: {=IF( INDEX($H$2:$Z$14, COLUMN(H7), 2*ROW(H7)-1)>0, INDEX($H$2:$Z$14, COLUMN(H7), 2*ROW(H7)-1), NA() )} -> 0.49147287 | ... S45: {=IF( INDEX($H$2:$Z$14, COLUMN(M7), 2*ROW(M7)-1)>0, INDEX($H$2:$Z$14, COLUMN(M7), 2*ROW(M7)-1), NA() )} -> 0.46405389 | T45: 15h00 | U45: =AL2 -> 0.46292948 | V45: =AL3 -> 0.48648649 | W45: =AL4 -> 0.57503506 | X45: =AL5 -> 0.45066274 | Y45: =AL6 -> 0.53495007 | Z45: =AL7 -> 0.42957746 | AA45: =AL8 -> 0.48426813 | AB45: =AL9 -> 0.50309598 | AC45: =AL10 -> 0.38081805 | AD45: =AL11 -> 0.49261084 | AE45: =AL12 -> 0.4804631 | AF45: =AL13 -> 0.36911765 | AG45: =AL14 -> 0.470963
F46: 16h00 | G46: {=IF( INDEX($H$2:$Z$14, COLUMN(A8), 2*ROW(A8)-1)>0, INDEX($H$2:$Z$14, COLUMN(A8), 2*ROW(A8)-1), NA() )} -> 0.50361011 | H46: {=IF( INDEX($H$2:$Z$14, COLUMN(B8), 2*ROW(B8)-1)>0, INDEX($H$2:$Z$14, COLUMN(B8), 2*ROW(B8)-1), NA() )} -> 0.5 | I46: {=IF( INDEX($H$2:$Z$14, COLUMN(C8), 2*ROW(C8)-1)>0, INDEX($H$2:$Z$14, COLUMN(C8), 2*ROW(C8)-1), NA() )} -> 0.58823529 | J46: {=IF( INDEX($H$2:$Z$14, COLUMN(D8), 2*ROW(D8)-1)>0, INDEX($H$2:$Z$14, COLUMN(D8), 2*ROW(D8)-1), NA() )} -> 0.50662739 | K46: {=IF( INDEX($H$2:$Z$14, COLUMN(E8), 2*ROW(E8)-1)>0, INDEX($H$2:$Z$14, COLUMN(E8), 2*ROW(E8)-1), NA() )} -> 0.59914408 | L46: {=IF( INDEX($H$2:$Z$14, COLUMN(F8), 2*ROW(F8)-1)>0, INDEX($H$2:$Z$14, COLUMN(F8), 2*ROW(F8)-1), NA() )} -> 0.47887324 | M46: {=IF( INDEX($H$2:$Z$14, COLUMN(G8), 2*ROW(G8)-1)>0, INDEX($H$2:$Z$14, COLUMN(G8), 2*ROW(G8)-1), NA() )} -> 0.5129959 | N46: {=IF( INDEX($H$2:$Z$14, COLUMN(H8), 2*ROW(H8)-1)>0, INDEX($H$2:$Z$14, COLUMN(H8), 2*ROW(H8)-1), NA() )} -> 0.51162791 | ... S46: {=IF( INDEX($H$2:$Z$14, COLUMN(M8), 2*ROW(M8)-1)>0, INDEX($H$2:$Z$14, COLUMN(M8), 2*ROW(M8)-1), NA() )} -> 0.50459277 | T46: 16h00 | U46: =AM2 -> 0.50994575 | V46: =AM3 -> 0.52702703 | W46: =AM4 -> 0.6171108 | X46: =AM5 -> 0.49484536 | Y46: =AM6 -> 0.59914408 | Z46: =AM7 -> 0.47323944 | AA46: =AM8 -> 0.5499316 | AB46: =AM9 -> 0.54179567 | AC46: =AM10 -> 0.41325811 | AD46: =AM11 -> 0.54187192 | AE46: =AM12 -> 0.552822 | AF46: =AM13 -> 0.42205882 | AG46: =AM14 -> 0.52046067
F47: 17h00 | G47: {=IF( INDEX($H$2:$Z$14, COLUMN(A9), 2*ROW(A9)-1)>0, INDEX($H$2:$Z$14, COLUMN(A9), 2*ROW(A9)-1), NA() )} -> 0.54512635 | H47: {=IF( INDEX($H$2:$Z$14, COLUMN(B9), 2*ROW(B9)-1)>0, INDEX($H$2:$Z$14, COLUMN(B9), 2*ROW(B9)-1), NA() )} -> 0.54324324 | I47: {=IF( INDEX($H$2:$Z$14, COLUMN(C9), 2*ROW(C9)-1)>0, INDEX($H$2:$Z$14, COLUMN(C9), 2*ROW(C9)-1), NA() )} -> 0.6442577 | J47: {=IF( INDEX($H$2:$Z$14, COLUMN(D9), 2*ROW(D9)-1)>0, INDEX($H$2:$Z$14, COLUMN(D9), 2*ROW(D9)-1), NA() )} -> 0.54050074 | K47: {=IF( INDEX($H$2:$Z$14, COLUMN(E9), 2*ROW(E9)-1)>0, INDEX($H$2:$Z$14, COLUMN(E9), 2*ROW(E9)-1), NA() )} -> 0.63766049 | L47: {=IF( INDEX($H$2:$Z$14, COLUMN(F9), 2*ROW(F9)-1)>0, INDEX($H$2:$Z$14, COLUMN(F9), 2*ROW(F9)-1), NA() )} -> 0.50985915 | M47: {=IF( INDEX($H$2:$Z$14, COLUMN(G9), 2*ROW(G9)-1)>0, INDEX($H$2:$Z$14, COLUMN(G9), 2*ROW(G9)-1), NA() )} -> 0.56087551 | N47: {=IF( INDEX($H$2:$Z$14, COLUMN(H9), 2*ROW(H9)-1)>0, INDEX($H$2:$Z$14, COLUMN(H9), 2*ROW(H9)-1), NA() )} -> 0.55193798 | ... S47: {=IF( INDEX($H$2:$Z$14, COLUMN(M9), 2*ROW(M9)-1)>0, INDEX($H$2:$Z$14, COLUMN(M9), 2*ROW(M9)-1), NA() )} -> 0.54439682 | T47: 17h00 | U47: =AN2 -> 0.54792043 | V47: =AN3 -> 0.56081081 | W47: =AN4 -> 0.65918654 | X47: =AN5 -> 0.51693667 | Y47: =AN6 -> 0.62054208 | Z47: =AN7 -> 0.5 | AA47: =AN8 -> 0.5745554 | AB47: =AN9 -> 0.55882353 | AC47: =AN10 -> 0.44005642 | AD47: =AN11 -> 0.56486043 | AE47: =AN12 -> 0.57597685 | AF47: =AN13 -> 0.47205882 | AG47: =AN14 -> 0.54949767
F48: 18h00 | G48: {=IF( INDEX($H$2:$Z$14, COLUMN(A10), 2*ROW(A10)-1)>0, INDEX($H$2:$Z$14, COLUMN(A10), 2*ROW(A10)-1), NA() )} -> 0.57039711 | H48: {=IF( INDEX($H$2:$Z$14, COLUMN(B10), 2*ROW(B10)-1)>0, INDEX($H$2:$Z$14, COLUMN(B10), 2*ROW(B10)-1), NA() )} -> 0.58513514 | I48: {=IF( INDEX($H$2:$Z$14, COLUMN(C10), 2*ROW(C10)-1)>0, INDEX($H$2:$Z$14, COLUMN(C10), 2*ROW(C10)-1), NA() )} -> 0.67226891 | J48: {=IF( INDEX($H$2:$Z$14, COLUMN(D10), 2*ROW(D10)-1)>0, INDEX($H$2:$Z$14, COLUMN(D10), 2*ROW(D10)-1), NA() )} -> 0.56259205 | K48: {=IF( INDEX($H$2:$Z$14, COLUMN(E10), 2*ROW(E10)-1)>0, INDEX($H$2:$Z$14, COLUMN(E10), 2*ROW(E10)-1), NA() )} -> 0.67760342 | L48: {=IF( INDEX($H$2:$Z$14, COLUMN(F10), 2*ROW(F10)-1)>0, INDEX($H$2:$Z$14, COLUMN(F10), 2*ROW(F10)-1), NA() )} -> 0.53521127 | M48: {=IF( INDEX($H$2:$Z$14, COLUMN(G10), 2*ROW(G10)-1)>0, INDEX($H$2:$Z$14, COLUMN(G10), 2*ROW(G10)-1), NA() )} -> 0.58823529 | N48: {=IF( INDEX($H$2:$Z$14, COLUMN(H10), 2*ROW(H10)-1)>0, INDEX($H$2:$Z$14, COLUMN(H10), 2*ROW(H10)-1), NA() )} -> 0.56124031 | ... S48: {=IF( INDEX($H$2:$Z$14, COLUMN(M10), 2*ROW(M10)-1)>0, INDEX($H$2:$Z$14, COLUMN(M10), 2*ROW(M10)-1), NA() )} -> 0.56962645 | T48: 18h00 | U48: =AO2 -> 0.5840868 | V48: =AO3 -> 0.59864865 | W48: =AO4 -> 0.67882188 | X48: =AO5 -> 0.53460972 | Y48: =AO6 -> 0.64479315 | Z48: =AO7 -> 0.51690141 | AA48: =AO8 -> 0.6005472 | AB48: =AO9 -> 0.58668731 | AC48: =AO10 -> 0.4696756 | AD48: =AO11 -> 0.5862069 | AE48: =AO12 -> 0.60202605 | AF48: =AO13 -> 0.47941176 | AG48: =AO14 -> 0.57363391
F49: 19h00 | G49: {=IF( INDEX($H$2:$Z$14, COLUMN(A11), 2*ROW(A11)-1)>0, INDEX($H$2:$Z$14, COLUMN(A11), 2*ROW(A11)-1), NA() )} -> #REF! | H49: {=IF( INDEX($H$2:$Z$14, COLUMN(B11), 2*ROW(B11)-1)>0, INDEX($H$2:$Z$14, COLUMN(B11), 2*ROW(B11)-1), NA() )} -> #REF! | I49: {=IF( INDEX($H$2:$Z$14, COLUMN(C11), 2*ROW(C11)-1)>0, INDEX($H$2:$Z$14, COLUMN(C11), 2*ROW(C11)-1), NA() )} -> #REF! | J49: {=IF( INDEX($H$2:$Z$14, COLUMN(D11), 2*ROW(D11)-1)>0, INDEX($H$2:$Z$14, COLUMN(D11), 2*ROW(D11)-1), NA() )} -> #REF! | K49: {=IF( INDEX($H$2:$Z$14, COLUMN(E11), 2*ROW(E11)-1)>0, INDEX($H$2:$Z$14, COLUMN(E11), 2*ROW(E11)-1), NA() )} -> #REF! | L49: {=IF( INDEX($H$2:$Z$14, COLUMN(F11), 2*ROW(F11)-1)>0, INDEX($H$2:$Z$14, COLUMN(F11), 2*ROW(F11)-1), NA() )} -> #REF! | M49: {=IF( INDEX($H$2:$Z$14, COLUMN(G11), 2*ROW(G11)-1)>0, INDEX($H$2:$Z$14, COLUMN(G11), 2*ROW(G11)-1), NA() )} -> #REF! | N49: {=IF( INDEX($H$2:$Z$14, COLUMN(H11), 2*ROW(H11)-1)>0, INDEX($H$2:$Z$14, COLUMN(H11), 2*ROW(H11)-1), NA() )} -> #REF! | ... S49: {=IF( INDEX($H$2:$Z$14, COLUMN(M11), 2*ROW(M11)-1)>0, INDEX($H$2:$Z$14, COLUMN(M11), 2*ROW(M11)-1), NA() )} -> #REF! | T49: 19h00 | U49: =AP2 -> 0 | V49: =AP3 -> 0 | W49: =AP4 -> 0 | X49: =AP5 -> 0 | Y49: =AP6 -> 0 | Z49: =AP7 -> 0 | AA49: =AP8 -> 0 | AB49: =AP9 -> 0 | AC49: =AP10 -> 0 | AD49: =AP11 -> 0 | AE49: =AP12 -> 0 | AF49: =AP13 -> 0 | AG49: =AP14 -> 0
F50: 20h00 | G50: {=IF( INDEX($H$2:$Z$14, COLUMN(A12), 2*ROW(A12)-1)>0, INDEX($H$2:$Z$14, COLUMN(A12), 2*ROW(A12)-1), NA() )} -> #REF! | H50: {=IF( INDEX($H$2:$Z$14, COLUMN(B12), 2*ROW(B12)-1)>0, INDEX($H$2:$Z$14, COLUMN(B12), 2*ROW(B12)-1), NA() )} -> #REF! | I50: {=IF( INDEX($H$2:$Z$14, COLUMN(C12), 2*ROW(C12)-1)>0, INDEX($H$2:$Z$14, COLUMN(C12), 2*ROW(C12)-1), NA() )} -> #REF! | J50: {=IF( INDEX($H$2:$Z$14, COLUMN(D12), 2*ROW(D12)-1)>0, INDEX($H$2:$Z$14, COLUMN(D12), 2*ROW(D12)-1), NA() )} -> #REF! | K50: {=IF( INDEX($H$2:$Z$14, COLUMN(E12), 2*ROW(E12)-1)>0, INDEX($H$2:$Z$14, COLUMN(E12), 2*ROW(E12)-1), NA() )} -> #REF! | L50: {=IF( INDEX($H$2:$Z$14, COLUMN(F12), 2*ROW(F12)-1)>0, INDEX($H$2:$Z$14, COLUMN(F12), 2*ROW(F12)-1), NA() )} -> #REF! | M50: {=IF( INDEX($H$2:$Z$14, COLUMN(G12), 2*ROW(G12)-1)>0, INDEX($H$2:$Z$14, COLUMN(G12), 2*ROW(G12)-1), NA() )} -> #REF! | N50: {=IF( INDEX($H$2:$Z$14, COLUMN(H12), 2*ROW(H12)-1)>0, INDEX($H$2:$Z$14, COLUMN(H12), 2*ROW(H12)-1), NA() )} -> #REF! | ... S50: {=IF( INDEX($H$2:$Z$14, COLUMN(M12), 2*ROW(M12)-1)>0, INDEX($H$2:$Z$14, COLUMN(M12), 2*ROW(M12)-1), NA() )} -> #REF! | T50: 20h00 | U50: =AQ2 -> 0 | V50: =AQ3 -> 0 | W50: =AQ4 -> 0 | X50: =AQ5 -> 0 | Y50: =AQ6 -> 0 | Z50: =AQ7 -> 0 | AA50: =AQ8 -> 0 | AB50: =AQ9 -> 0 | AC50: =AQ10 -> 0 | AD50: =AQ11 -> 0 | AE50: =AQ12 -> 0 | AF50: =AQ13 -> 0 | AG50: =AQ14 -> 0
G52: Tour actuel | U52: Tour précédent
F53: Heure | G53: Bureau 1 | H53: Bureau 2 | I53: Bureau 3 | J53: Bureau 4 | K53: Bureau 5 | L53: Bureau 6 | M53: Bureau 7 | N53: Bureau 8 | O53: Bureau 9 | P53: Bureau 10 | Q53: Bureau 11 | R53: Bureau 12 | S53: Total | T53: Heure | U53: Bureau 1 | V53: Bureau 2 | W53: Bureau 3 | X53: Bureau 4 | Y53: Bureau 5 | Z53: Bureau 6 | AA53: Bureau 7 | AB53: Bureau 8 | AC53: Bureau 9 | AD53: Bureau 10 | AE53: Bureau 11 | AF53: Bureau 12 | AG53: Total
F54: 8h-9h | G54: =INDIRECT("'Bureau 1'!" & ADDRESS(ROW()-50,Synthèse!$G$40+14,4)) -> 33 | H54: =INDIRECT("'Bureau 2'!" & ADDRESS(ROW()-50,Synthèse!$G$40+14,4)) -> 50 | I54: =INDIRECT("'Bureau 3'!" & ADDRESS(ROW()-50,Synthèse!$G$40+14,4)) -> 50 | J54: =INDIRECT("'Bureau 4'!" & ADDRESS(ROW()-50,Synthèse!$G$40+14,4)) -> 44 | K54: =INDIRECT("'Bureau 5'!" & ADDRESS(ROW()-50,Synthèse!$G$40+14,4)) -> 45 | L54: =INDIRECT("'Bureau 6'!" & ADDRESS(ROW()-50,Synthèse!$G$40+14,4)) -> 48 | M54: =INDIRECT("'Bureau 7'!" & ADDRESS(ROW()-50,Synthèse!$G$40+14,4)) -> 30 | N54: =INDIRECT("'Bureau 8'!" & ADDRESS(ROW()-50,Synthèse!$G$40+14,4)) -> 40 | O54: =INDIRECT("'Bureau 9'!" & ADDRESS(ROW()-50,Synthèse!$G$40+14,4)) -> 35 | P54: =INDIRECT("'Bureau 10'!" & ADDRESS(ROW()-50,Synthèse!$G$40+14,4)) -> 30 | Q54: =INDIRECT("'Bureau 11'!" & ADDRESS(ROW()-50,Synthèse!$G$40+14,4)) -> 43 | R54: =INDIRECT("'Bureau 12'!" & ADDRESS(ROW()-50,Synthèse!$G$40+14,4)) -> 10 | S54: =SUMIF(G54:R54, "<>#N/A") -> 458 | T54: 8h-9h | U54: 33 | V54: 45 | W54: 40 | X54: 33 | Y54: 37 | Z54: 30 | AA54: 20 | AB54: 36 | AC54: 22 | AD54: 27 | AE54: 47 | AF54: 24 | AG54: 394
F55: 9h-10h | G55: =INDIRECT("'Bureau 1'!" & ADDRESS(ROW()-50,Synthèse!$G$40+14,4)) -> 39 | H55: =INDIRECT("'Bureau 2'!" & ADDRESS(ROW()-50,Synthèse!$G$40+14,4)) -> 40 | I55: =INDIRECT("'Bureau 3'!" & ADDRESS(ROW()-50,Synthèse!$G$40+14,4)) -> 50 | J55: =INDIRECT("'Bureau 4'!" & ADDRESS(ROW()-50,Synthèse!$G$40+14,4)) -> 66 | K55: =INDIRECT("'Bureau 5'!" & ADDRESS(ROW()-50,Synthèse!$G$40+14,4)) -> 65 | L55: =INDIRECT("'Bureau 6'!" & ADDRESS(ROW()-50,Synthèse!$G$40+14,4)) -> 52 | M55: =INDIRECT("'Bureau 7'!" & ADDRESS(ROW()-50,Synthèse!$G$40+14,4)) -> 60 | N55: =INDIRECT("'Bureau 8'!" & ADDRESS(ROW()-50,Synthèse!$G$40+14,4)) -> 52 | O55: =INDIRECT("'Bureau 9'!" & ADDRESS(ROW()-50,Synthèse!$G$40+14,4)) -> 35 | P55: =INDIRECT("'Bureau 10'!" & ADDRESS(ROW()-50,Synthèse!$G$40+14,4)) -> 54 | Q55: =INDIRECT("'Bureau 11'!" & ADDRESS(ROW()-50,Synthèse!$G$40+14,4)) -> 50 | R55: =INDIRECT("'Bureau 12'!" & ADDRESS(ROW()-50,Synthèse!$G$40+14,4)) -> 35 | S55: =SUMIF(G55:R55, "<>#N/A") -> 598 | T55: 9h-10h | U55: 45 | V55: 35 | W55: 70 | X55: 35 | Y55: 56 | Z55: 59 | AA55: 55 | AB55: 36 | AC55: 37 | AD55: 43 | AE55: 49 | AF55: 25 | AG55: 545
...

Sheet Bureau 1
A1: =Synthèse!$A$17 -> Date | B1: =Synthèse!$B$17 -> 46103 | E1: Résultats relatifs aux centaines dépouillées | I1: Vérification
A2: =Synthèse!$A$18 -> Election | B2: =Synthèse!$B$18 -> Municipale | D2: Enveloppe de centaine | E2: =Synthèse!L2 -> M. Pierre-Yves TIERCE | F2: =Synthèse!M2 -> Mme Isabelle FARNET RISSO | G2: Nuls | H2: Blancs | I2: Sous-totaux centaines | K2: Heure | L2: Votants cumulés | M2: Votants % | O2: Période horaire | P2: Votants sur la période
A3: =Synthèse!$A$19 -> Tour | B3: =Synthèse!$B$19 -> 2 | D3: {=IF(ROW(1:1)<=$E$24, (ROW(1:1)), "")} -> 1 | E3: 44 | F3: 52 | G3: 1 | H3: 3 | I3: =SUM(E3:H3) -> 100 | K3: 08h00 | L3: 0 | M3: =L3/$B$7 -> 0
A4: =Synthèse!$A$20 -> Ville | B4: =Synthèse!$B$20 -> Cogolin | D4: {=IF(ROW(2:2)<=$E$24, (ROW(2:2)), "")} -> 2 | E4: 54 | F4: 43 | G4: 4 | H4: {=IF(ISNUMBER($D4), IFERROR( IF($D4 = MIN(INDEX(Table1,,1)), INDEX(Table1,MATCH($D4,INDEX(Table1,,1),0),COLUMN()-3), INDEX(Table1,MATCH($D4,INDEX(Table1,,1),0),COLUMN()-3)-INDEX(Table1,MATCH($D4,INDEX(Table1,,1),0)-1,COLUMN()-3) ), IFERROR( IF($D4 = MIN(INDEX(Table2,,1)), INDEX(Table2,MATCH($D4,INDEX(Table2,,1),0),COLUMN()-3), INDEX(Table2,MATCH($D4,INDEX(Table2,,1),0),COLUMN()-3)-INDEX(Table2,MATCH($D4,INDEX(Table2,,1),0)-1,COLUMN()-3) ), IFERROR( IF($D4 = MIN(INDEX(Table3,,1)), INDEX(Table3,MATCH($D4,INDEX(Table3,,1),0),COLUMN()-3), INDEX(Table3,MATCH($D4,INDEX(Table3,,1),0),COLUMN()-3)-INDEX(Table3,MATCH($D4,INDEX(Table3,,1),0)-1,COLUMN()-3) ), 0 ) ) ), 0)} -> 0 | I4: =SUM(E4:H4) -> 101 | K4: 09h00 | L4: 33 | M4: =IF(OR(L4=0, L4=""), NA(), L4/$B$7) -> 0.059566787 | O4: 8h-9h | P4: =IF(L4<>0,L4-L3,NA()) -> 33
A5: Bureau n° | B5: 1 | D5: {=IF(ROW(3:3)<=$E$24, (ROW(3:3)), "")} -> 3 | E5: 45 | F5: 51 | G5: 3 | H5: 1 | I5: =SUM(E5:H5) -> 100 | K5: 10h00 | L5: 72 | M5: =IF(OR(L5=0, L5=""), NA(), L5/$B$7) -> 0.1299639 | O5: 9h-10h | P5: =IF(L5<>0,L5-L4,NA()) -> 39
A6: Nom | B6: =INDEX(Synthèse!B:B,B5+2) -> Ecole Chabaud | D6: {=IF(ROW(4:4)<=$E$24, (ROW(4:4)), "")} -> 4 | E6: 5 | F6: 10 | G6: {=IF(ISNUMBER($D6), IFERROR( IF($D6 = MIN(INDEX(Table1,,1)), INDEX(Table1,MATCH($D6,INDEX(Table1,,1),0),COLUMN()-3), INDEX(Table1,MATCH($D6,INDEX(Table1,,1),0),COLUMN()-3)-INDEX(Table1,MATCH($D6,INDEX(Table1,,1),0)-1,COLUMN()-3) ), IFERROR( IF($D6 = MIN(INDEX(Table2,,1)), INDEX(Table2,MATCH($D6,INDEX(Table2,,1),0),COLUMN()-3), INDEX(Table2,MATCH($D6,INDEX(Table2,,1),0),COLUMN()-3)-INDEX(Table2,MATCH($D6,INDEX(Table2,,1),0)-1,COLUMN()-3) ), IFERROR( IF($D6 = MIN(INDEX(Table3,,1)), INDEX(Table3,MATCH($D6,INDEX(Table3,,1),0),COLUMN()-3), INDEX(Table3,MATCH($D6,INDEX(Table3,,1),0),COLUMN()-3)-INDEX(Table3,MATCH($D6,INDEX(Table3,,1),0)-1,COLUMN()-3) ), 0 ) ) ), 0)} -> 0 | H6: {=IF(ISNUMBER($D6), IFERROR( IF($D6 = MIN(INDEX(Table1,,1)), INDEX(Table1,MATCH($D6,INDEX(Table1,,1),0),COLUMN()-3), INDEX(Table1,MATCH($D6,INDEX(Table1,,1),0),COLUMN()-3)-INDEX(Table1,MATCH($D6,INDEX(Table1,,1),0)-1,COLUMN()-3) ), IFERROR( IF($D6 = MIN(INDEX(Table2,,1)), INDEX(Table2,MATCH($D6,INDEX(Table2,,1),0),COLUMN()-3), INDEX(Table2,MATCH($D6,INDEX(Table2,,1),0),COLUMN()-3)-INDEX(Table2,MATCH($D6,INDEX(Table2,,1),0)-1,COLUMN()-3) ), IFERROR( IF($D6 = MIN(INDEX(Table3,,1)), INDEX(Table3,MATCH($D6,INDEX(Table3,,1),0),COLUMN()-3), INDEX(Table3,MATCH($D6,INDEX(Table3,,1),0),COLUMN()-3)-INDEX(Table3,MATCH($D6,INDEX(Table3,,1),0)-1,COLUMN()-3) ), 0 ) ) ), 0)} -> 0 | I6: =SUM(E6:H6) -> 15 | K6: 11h00 | L6: 123 | M6: =IF(OR(L6=0, L6=""), NA(), L6/$B$7) -> 0.22202166 | O6: 10h-11h | P6: =IF(L6<>0,L6-L5,NA()) -> 51
